<?xml version="1.0" ?>
<!-- Generated using onshape-to-robot -->
<!-- Onshape document_id: 1f813eeba4ab32efffd87c1d -->
<robot name="track_left">
  <!-- Link body_left -->
  <link name="body_left">
    <inertial>
      <origin xyz="0.0238777 -0.00119624 -0.00412068" rpy="0 0 0"/>
      <mass value="0.6"/>
      <inertia ixx="0.000408384" ixy="6.93353e-06" ixz="3.09979e-05" iyy="0.000335218" iyz="-2.90084e-05" izz="0.000303698"/>
    </inertial>
    <!-- Part body_left -->
    <visual>
      <origin xyz="2.26711e-87 3.26265e-55 4.41854e-07" rpy="1.67587e-64 -0 3.14159"/>
      <geometry>
        <mesh filename="package://assets/body_left.stl"/>
      </geometry>
      <material name="body_left_material">
        <color rgba="0.647059 0.647059 0.647059 1"/>
      </material>
    </visual>
    <collision>
      <origin xyz="2.26711e-87 3.26265e-55 4.41854e-07" rpy="1.67587e-64 -0 3.14159"/>
      <geometry>
        <mesh filename="package://assets/body_left.stl"/>
      </geometry>
    </collision>
  </link>
  <!-- Link wheel -->
  <link name="wheel">
    <inertial>
      <origin xyz="1.92585e-20 -5.69643e-18 -0.0225" rpy="0 0 0"/>
      <mass value="0.1"/>
      <inertia ixx="2.26562e-05" ixy="0" ixz="0" iyy="2.26562e-05" iyz="5.3406e-69" izz="1.15625e-05"/>
    </inertial>
    <!-- Part wheel -->
    <visual>
      <origin xyz="0 -6.93889e-18 -0.045" rpy="-1.5708 -1.5708 0"/>
      <geometry>
        <mesh filename="package://assets/wheel.stl"/>
      </geometry>
      <material name="wheel_material">
        <color rgba="0.615686 0.811765 0.929412 1"/>
      </material>
    </visual>
    <collision>
      <origin xyz="0 -6.93889e-18 -0.045" rpy="-1.5708 -1.5708 0"/>
      <geometry>
        <mesh filename="package://assets/wheel.stl"/>
      </geometry>
    </collision>
  </link>
  <!-- Joint from body_left to wheel -->
  <joint name="wheel_1" type="continuous">
    <origin xyz="0 0.0484063 -0.0583795" rpy="-6.12323e-17 -1.5708 0"/>
    <parent link="body_left"/>
    <child link="wheel"/>
    <axis xyz="0 0 1"/>
    <limit effort="10" velocity="10"/>
  </joint>
  <!-- Link wheel_2 -->
  <link name="wheel_2">
    <inertial>
      <origin xyz="1.92585e-20 3.02108e-19 -0.0225" rpy="0 0 0"/>
      <mass value="0.1"/>
      <inertia ixx="2.26562e-05" ixy="0" ixz="0" iyy="2.26562e-05" iyz="5.3406e-69" izz="1.15625e-05"/>
    </inertial>
    <!-- Part wheel_2 -->
    <visual>
      <origin xyz="0 -9.40354e-19 -0.045" rpy="-1.5708 -1.5708 0"/>
      <geometry>
        <mesh filename="package://assets/wheel.stl"/>
      </geometry>
      <material name="wheel_2_material">
        <color rgba="0.615686 0.811765 0.929412 1"/>
      </material>
    </visual>
    <collision>
      <origin xyz="0 -9.40354e-19 -0.045" rpy="-1.5708 -1.5708 0"/>
      <geometry>
        <mesh filename="package://assets/wheel.stl"/>
      </geometry>
    </collision>
  </link>
  <!-- Joint from body_left to wheel_2 -->
  <joint name="wheel_2" type="continuous">
    <origin xyz="0 1.07779e-16 -0.0583795" rpy="-6.12323e-17 -1.5708 0"/>
    <parent link="body_left"/>
    <child link="wheel_2"/>
    <axis xyz="0 0 1"/>
    <limit effort="10" velocity="10"/>
  </joint>
  <!-- Link wheel_3 -->
  <link name="wheel_3">
    <inertial>
      <origin xyz="1.92585e-20 1.24246e-18 -0.0225" rpy="0 0 0"/>
      <mass value="0.1"/>
      <inertia ixx="2.26562e-05" ixy="0" ixz="0" iyy="2.26562e-05" iyz="5.3406e-69" izz="1.15625e-05"/>
    </inertial>
    <!-- Part wheel_3 -->
    <visual>
      <origin xyz="0 0 -0.045" rpy="-1.5708 -1.5708 0"/>
      <geometry>
        <mesh filename="package://assets/wheel.stl"/>
      </geometry>
      <material name="wheel_3_material">
        <color rgba="0.615686 0.811765 0.929412 1"/>
      </material>
    </visual>
    <collision>
      <origin xyz="0 0 -0.045" rpy="-1.5708 -1.5708 0"/>
      <geometry>
        <mesh filename="package://assets/wheel.stl"/>
      </geometry>
    </collision>
  </link>
  <!-- Joint from body_left to wheel_3 -->
  <joint name="wheel_3" type="continuous">
    <origin xyz="0 -0.0510313 -0.0583795" rpy="-6.12323e-17 -1.5708 0"/>
    <parent link="body_left"/>
    <child link="wheel_3"/>
    <axis xyz="0 0 1"/>
    <limit effort="10" velocity="10"/>
  </joint>
  <!-- Link wheel_4 -->
  <link name="wheel_4">
    <inertial>
      <origin xyz="1.92585e-20 1.24246e-18 -0.0225" rpy="0 0 0"/>
      <mass value="0.1"/>
      <inertia ixx="2.26562e-05" ixy="0" ixz="0" iyy="2.26562e-05" iyz="5.3406e-69" izz="1.15625e-05"/>
    </inertial>
    <!-- Part wheel_4 -->
    <visual>
      <origin xyz="0 0 -0.045" rpy="-1.5708 -1.5708 0"/>
      <geometry>
        <mesh filename="package://assets/wheel.stl"/>
      </geometry>
      <material name="wheel_4_material">
        <color rgba="0.615686 0.811765 0.929412 1"/>
      </material>
    </visual>
    <collision>
      <origin xyz="0 0 -0.045" rpy="-1.5708 -1.5708 0"/>
      <geometry>
        <mesh filename="package://assets/wheel.stl"/>
      </geometry>
    </collision>
  </link>
  <!-- Joint from body_left to wheel_4 -->
  <joint name="wheel_4" type="continuous">
    <origin xyz="0 -0.0766777 -0.0417374" rpy="-6.12323e-17 -1.5708 0"/>
    <parent link="body_left"/>
    <child link="wheel_4"/>
    <axis xyz="0 0 1"/>
    <limit effort="10" velocity="10"/>
  </joint>
</robot>
