<?xml version="1.0" ?>
<!-- Generated using onshape-to-robot -->
<!-- Onshape document_id: 1f813eeba4ab32efffd87c1d -->
<robot name="track">
  <!-- Link body -->
  <link name="body">
    <inertial>
      <origin xyz="-0.207239 -0.123927 0.00529817" rpy="0 0 0"/>
      <mass value="0.6"/>
      <inertia ixx="0.000414901" ixy="-6.8162e-06" ixz="-3.07156e-05" iyy="0.000336828" iyz="-2.94539e-05" izz="0.00030493"/>
    </inertial>
    <!-- Part body -->
    <visual>
      <origin xyz="-0.205538 -0.122711 -0.0648851" rpy="8.17568e-09 -4.94023e-07 3.14159"/>
      <geometry>
        <mesh filename="package://assets/body.stl"/>
      </geometry>
      <material name="body_material">
        <color rgba="0.647059 0.647059 0.647059 1"/>
      </material>
    </visual>
    <collision>
      <origin xyz="-0.205538 -0.122711 -0.0648851" rpy="8.17568e-09 -4.94023e-07 3.14159"/>
      <geometry>
        <mesh filename="package://assets/body.stl"/>
      </geometry>
    </collision>
  </link>
  <!-- Link leg -->
  <link name="leg">
    <inertial>
      <origin xyz="0.000123462 0.0511768 -0.0198492" rpy="0 0 0"/>
      <mass value="0.4"/>
      <inertia ixx="0.000738996" ixy="-2.56738e-08" ixz="7.44935e-09" iyy="0.000129288" iyz="3.08787e-06" izz="0.000840815"/>
    </inertial>
    <!-- Part leg -->
    <visual>
      <origin xyz="0 -1.04083e-17 -0.01" rpy="-1.5708 1.5708 0"/>
      <geometry>
        <mesh filename="package://assets/leg.stl"/>
      </geometry>
      <material name="leg_material">
        <color rgba="0.615686 0.811765 0.929412 1"/>
      </material>
    </visual>
    <collision>
      <origin xyz="0 -1.04083e-17 -0.01" rpy="-1.5708 1.5708 0"/>
      <geometry>
        <mesh filename="package://assets/leg.stl"/>
      </geometry>
    </collision>
  </link>
  <!-- Joint from body to leg -->
  <joint name="track" type="revolute">
    <origin xyz="-0.193038 -0.122711 0.00948947" rpy="1.5708 -8.17568e-09 -1.5708"/>
    <parent link="body"/>
    <child link="leg"/>
    <axis xyz="0 0 1"/>
    <limit effort="10" velocity="10" lower="-3.141592653589793" upper="3.141592653589793"/>
  </joint>
  <!-- Link wheel -->
  <link name="wheel">
    <inertial>
      <origin xyz="1.92585e-20 -5.69643e-18 -0.0225" rpy="0 0 0"/>
      <mass value="0.1"/>
      <inertia ixx="2.26562e-05" ixy="2.61901e-52" ixz="-5.75941e-28" iyy="2.26562e-05" iyz="-1.22423e-27" izz="1.15625e-05"/>
    </inertial>
    <!-- Part wheel -->
    <visual>
      <origin xyz="0 -6.93889e-18 -0.045" rpy="-1.5708 -1.5708 0"/>
      <geometry>
        <mesh filename="package://assets/wheel.stl"/>
      </geometry>
      <material name="wheel_material">
        <color rgba="0.615686 0.811765 0.929412 1"/>
      </material>
    </visual>
    <collision>
      <origin xyz="0 -6.93889e-18 -0.045" rpy="-1.5708 -1.5708 0"/>
      <geometry>
        <mesh filename="package://assets/wheel.stl"/>
      </geometry>
    </collision>
  </link>
  <!-- Joint from body to wheel -->
  <joint name="wheel_1" type="continuous">
    <origin xyz="-0.183038 -0.0743044 -0.0488901" rpy="1.5708 8.17568e-09 1.5708"/>
    <parent link="body"/>
    <child link="wheel"/>
    <axis xyz="0 0 1"/>
    <limit effort="10" velocity="10"/>
  </joint>
  <!-- Link wheel_2 -->
  <link name="wheel_2">
    <inertial>
      <origin xyz="1.92582e-20 1.24246e-18 -0.0225" rpy="0 0 0"/>
      <mass value="0.1"/>
      <inertia ixx="2.26562e-05" ixy="-1.62025e-50" ixz="2.59269e-28" iyy="2.26562e-05" iyz="-1.1746e-27" izz="1.15625e-05"/>
    </inertial>
    <!-- Part wheel_2 -->
    <visual>
      <origin xyz="0 0 -0.045" rpy="-1.5708 -1.5708 0"/>
      <geometry>
        <mesh filename="package://assets/wheel.stl"/>
      </geometry>
      <material name="wheel_2_material">
        <color rgba="0.615686 0.811765 0.929412 1"/>
      </material>
    </visual>
    <collision>
      <origin xyz="0 0 -0.045" rpy="-1.5708 -1.5708 0"/>
      <geometry>
        <mesh filename="package://assets/wheel.stl"/>
      </geometry>
    </collision>
  </link>
  <!-- Joint from body to wheel_2 -->
  <joint name="wheel_2" type="continuous">
    <origin xyz="-0.183038 -0.122711 -0.0488901" rpy="1.5708 0.0242209 1.5708"/>
    <parent link="body"/>
    <child link="wheel_2"/>
    <axis xyz="0 0 1"/>
    <limit effort="10" velocity="10"/>
  </joint>
  <!-- Link wheel_3 -->
  <link name="wheel_3">
    <inertial>
      <origin xyz="1.92578e-20 -5.69643e-18 -0.0225" rpy="0 0 0"/>
      <mass value="0.1"/>
      <inertia ixx="2.26562e-05" ixy="0" ixz="-3.82571e-28" iyy="2.26562e-05" iyz="2.39882e-27" izz="1.15625e-05"/>
    </inertial>
    <!-- Part wheel_3 -->
    <visual>
      <origin xyz="0 -6.93889e-18 -0.045" rpy="-1.5708 -1.5708 0"/>
      <geometry>
        <mesh filename="package://assets/wheel.stl"/>
      </geometry>
      <material name="wheel_3_material">
        <color rgba="0.615686 0.811765 0.929412 1"/>
      </material>
    </visual>
    <collision>
      <origin xyz="0 -6.93889e-18 -0.045" rpy="-1.5708 -1.5708 0"/>
      <geometry>
        <mesh filename="package://assets/wheel.stl"/>
      </geometry>
    </collision>
  </link>
  <!-- Joint from body to wheel_3 -->
  <joint name="wheel_3" type="continuous">
    <origin xyz="-0.183038 -0.173742 -0.0488901" rpy="1.5708 0.0242209 1.5708"/>
    <parent link="body"/>
    <child link="wheel_3"/>
    <axis xyz="0 0 1"/>
    <limit effort="10" velocity="10"/>
  </joint>
  <!-- Link wheel_4 -->
  <link name="wheel_4">
    <inertial>
      <origin xyz="1.9259e-20 1.24246e-18 -0.0225" rpy="0 0 0"/>
      <mass value="0.1"/>
      <inertia ixx="2.26562e-05" ixy="-7.49632e-29" ixz="1.74212e-28" iyy="2.26562e-05" iyz="1.22423e-27" izz="1.15625e-05"/>
    </inertial>
    <!-- Part wheel_4 -->
    <visual>
      <origin xyz="0 0 -0.045" rpy="-1.5708 -1.5708 0"/>
      <geometry>
        <mesh filename="package://assets/wheel.stl"/>
      </geometry>
      <material name="wheel_4_material">
        <color rgba="0.615686 0.811765 0.929412 1"/>
      </material>
    </visual>
    <collision>
      <origin xyz="0 0 -0.045" rpy="-1.5708 -1.5708 0"/>
      <geometry>
        <mesh filename="package://assets/wheel.stl"/>
      </geometry>
    </collision>
  </link>
  <!-- Joint from body to wheel_4 -->
  <joint name="wheel_4" type="continuous">
    <origin xyz="-0.183038 -0.199388 -0.0322479" rpy="1.5708 8.17568e-09 1.5708"/>
    <parent link="body"/>
    <child link="wheel_4"/>
    <axis xyz="0 0 1"/>
    <limit effort="10" velocity="10"/>
  </joint>
</robot>
