<?xml version="1.0" ?>
<!-- Generated using onshape-to-robot -->
<!-- Onshape document_id: 1f813eeba4ab32efffd87c1d -->
<robot name="track">
  <!-- Link body_left -->
  <link name="body_left">
    <inertial>
      <origin xyz="-0.143467 -0.0587173 -0.075791" rpy="0 0 0"/>
      <mass value="0.6"/>
      <inertia ixx="0.000414901" ixy="-6.81617e-06" ixz="-3.07156e-05" iyy="0.000336828" iyz="-2.94539e-05" izz="0.00030493"/>
    </inertial>
    <!-- Part body_left -->
    <visual>
      <origin xyz="-0.141766 -0.0575005 -0.145974" rpy="6.45781e-16 -1.33599e-16 3.14159"/>
      <geometry>
        <mesh filename="package://assets/body_left.stl"/>
      </geometry>
      <material name="body_left_material">
        <color rgba="0.647059 0.647059 0.647059 1"/>
      </material>
    </visual>
    <collision>
      <origin xyz="-0.141766 -0.0575005 -0.145974" rpy="6.45781e-16 -1.33599e-16 3.14159"/>
      <geometry>
        <mesh filename="package://assets/body_left.stl"/>
      </geometry>
    </collision>
  </link>
  <!-- Link wheel -->
  <link name="wheel">
    <inertial>
      <origin xyz="-1.71546e-18 1.24246e-18 -0.0225" rpy="0 0 0"/>
      <mass value="0.1"/>
      <inertia ixx="2.26562e-05" ixy="0" ixz="1.51091e-35" iyy="2.26562e-05" iyz="0" izz="1.15625e-05"/>
    </inertial>
    <!-- Part wheel -->
    <visual>
      <origin xyz="-1.73472e-18 0 -0.045" rpy="-1.5708 -1.5708 0"/>
      <geometry>
        <mesh filename="package://assets/wheel.stl"/>
      </geometry>
      <material name="wheel_material">
        <color rgba="0.615686 0.811765 0.929412 1"/>
      </material>
    </visual>
    <collision>
      <origin xyz="-1.73472e-18 0 -0.045" rpy="-1.5708 -1.5708 0"/>
      <geometry>
        <mesh filename="package://assets/wheel.stl"/>
      </geometry>
    </collision>
  </link>
  <!-- Joint from body_left to wheel -->
  <joint name="wheel_1_left" type="continuous">
    <origin xyz="-0.119266 -0.00909429 -0.129979" rpy="1.5708 6.42791e-09 1.5708"/>
    <parent link="body_left"/>
    <child link="wheel"/>
    <axis xyz="0 0 1"/>
    <limit effort="10" velocity="10"/>
  </joint>
  <!-- Link wheel_2 -->
  <link name="wheel_2">
    <inertial>
      <origin xyz="-6.91964e-18 1.24246e-18 -0.0225" rpy="0 0 0"/>
      <mass value="0.1"/>
      <inertia ixx="2.26562e-05" ixy="-7.86047e-23" ixz="2.89347e-36" iyy="2.26562e-05" iyz="0" izz="1.15625e-05"/>
    </inertial>
    <!-- Part wheel_2 -->
    <visual>
      <origin xyz="-6.93889e-18 0 -0.045" rpy="-1.5708 -1.5708 0"/>
      <geometry>
        <mesh filename="package://assets/wheel.stl"/>
      </geometry>
      <material name="wheel_2_material">
        <color rgba="0.615686 0.811765 0.929412 1"/>
      </material>
    </visual>
    <collision>
      <origin xyz="-6.93889e-18 0 -0.045" rpy="-1.5708 -1.5708 0"/>
      <geometry>
        <mesh filename="package://assets/wheel.stl"/>
      </geometry>
    </collision>
  </link>
  <!-- Joint from body_left to wheel_2 -->
  <joint name="wheel_2_left" type="continuous">
    <origin xyz="-0.119266 -0.0575005 -0.129979" rpy="1.5708 0.0242209 1.5708"/>
    <parent link="body_left"/>
    <child link="wheel_2"/>
    <axis xyz="0 0 1"/>
    <limit effort="10" velocity="10"/>
  </joint>
  <!-- Link wheel_3 -->
  <link name="wheel_3">
    <inertial>
      <origin xyz="1.3897e-17 -2.65131e-17 -0.0225" rpy="0 0 0"/>
      <mass value="0.1"/>
      <inertia ixx="2.26562e-05" ixy="7.86047e-23" ixz="1.38584e-35" iyy="2.26562e-05" iyz="4.43261e-53" izz="1.15625e-05"/>
    </inertial>
    <!-- Part wheel_3 -->
    <visual>
      <origin xyz="1.38778e-17 -2.77556e-17 -0.045" rpy="-1.5708 -1.5708 0"/>
      <geometry>
        <mesh filename="package://assets/wheel.stl"/>
      </geometry>
      <material name="wheel_3_material">
        <color rgba="0.615686 0.811765 0.929412 1"/>
      </material>
    </visual>
    <collision>
      <origin xyz="1.38778e-17 -2.77556e-17 -0.045" rpy="-1.5708 -1.5708 0"/>
      <geometry>
        <mesh filename="package://assets/wheel.stl"/>
      </geometry>
    </collision>
  </link>
  <!-- Joint from body_left to wheel_3 -->
  <joint name="wheel_3_left" type="continuous">
    <origin xyz="-0.119266 -0.108532 -0.129979" rpy="1.5708 0.0242209 1.5708"/>
    <parent link="body_left"/>
    <child link="wheel_3"/>
    <axis xyz="0 0 1"/>
    <limit effort="10" velocity="10"/>
  </joint>
  <!-- Link wheel_4 -->
  <link name="wheel_4">
    <inertial>
      <origin xyz="-2.77363e-17 1.24246e-18 -0.0225" rpy="0 0 0"/>
      <mass value="0.1"/>
      <inertia ixx="2.26562e-05" ixy="3.74816e-29" ixz="-2.71817e-36" iyy="2.26562e-05" iyz="-1.10507e-60" izz="1.15625e-05"/>
    </inertial>
    <!-- Part wheel_4 -->
    <visual>
      <origin xyz="-2.77556e-17 0 -0.045" rpy="-1.5708 -1.5708 0"/>
      <geometry>
        <mesh filename="package://assets/wheel.stl"/>
      </geometry>
      <material name="wheel_4_material">
        <color rgba="0.615686 0.811765 0.929412 1"/>
      </material>
    </visual>
    <collision>
      <origin xyz="-2.77556e-17 0 -0.045" rpy="-1.5708 -1.5708 0"/>
      <geometry>
        <mesh filename="package://assets/wheel.stl"/>
      </geometry>
    </collision>
  </link>
  <!-- Joint from body_left to wheel_4 -->
  <joint name="wheel_4_left" type="continuous">
    <origin xyz="-0.119266 -0.134178 -0.113337" rpy="1.5708 6.4279e-09 1.5708"/>
    <parent link="body_left"/>
    <child link="wheel_4"/>
    <axis xyz="0 0 1"/>
    <limit effort="10" velocity="10"/>
  </joint>
  <!-- Link leg -->
  <link name="leg">
    <inertial>
      <origin xyz="0.000123462 0.0511768 -0.03" rpy="0 0 0"/>
      <mass value="0.4"/>
      <inertia ixx="0.000780212" ixy="-2.56738e-08" ixz="1.2766e-18" iyy="0.000170503" iyz="-1.35131e-19" izz="0.000840815"/>
    </inertial>
    <!-- Part leg -->
    <visual>
      <origin xyz="-6.93889e-17 -2.77556e-17 -0.01" rpy="-1.5708 1.5708 0"/>
      <geometry>
        <mesh filename="package://assets/leg.stl"/>
      </geometry>
      <material name="leg_material">
        <color rgba="0.615686 0.811765 0.929412 1"/>
      </material>
    </visual>
    <collision>
      <origin xyz="-6.93889e-17 -2.77556e-17 -0.01" rpy="-1.5708 1.5708 0"/>
      <geometry>
        <mesh filename="package://assets/leg.stl"/>
      </geometry>
    </collision>
  </link>
  <!-- Link body_right -->
  <link name="body_right">
    <inertial>
      <origin xyz="0.00121674 -0.0041913 -0.0142012" rpy="0 0 0"/>
      <mass value="0.6"/>
      <inertia ixx="0.000336828" ixy="2.94539e-05" ixz="6.81617e-06" iyy="0.00030493" iyz="-3.07156e-05" izz="0.000414901"/>
    </inertial>
    <!-- Part body_right -->
    <visual>
      <origin xyz="0 -0.0743746 0.0325" rpy="-1.5708 -1.5708 0"/>
      <geometry>
        <mesh filename="package://assets/body_right.stl"/>
      </geometry>
      <material name="body_right_material">
        <color rgba="0.647059 0.647059 0.647059 1"/>
      </material>
    </visual>
    <collision>
      <origin xyz="0 -0.0743746 0.0325" rpy="-1.5708 -1.5708 0"/>
      <geometry>
        <mesh filename="package://assets/body_right.stl"/>
      </geometry>
    </collision>
  </link>
  <!-- Link wheel_5 -->
  <link name="wheel_5">
    <inertial>
      <origin xyz="1.92585e-20 -1.24246e-18 -0.0225" rpy="0 0 0"/>
      <mass value="0.1"/>
      <inertia ixx="2.26562e-05" ixy="0" ixz="1.70287e-35" iyy="2.26562e-05" iyz="0" izz="1.15625e-05"/>
    </inertial>
    <!-- Part wheel_5 -->
    <visual>
      <origin xyz="0 0 0" rpy="1.5708 1.5708 0"/>
      <geometry>
        <mesh filename="package://assets/wheel.stl"/>
      </geometry>
      <material name="wheel_5_material">
        <color rgba="0.615686 0.811765 0.929412 1"/>
      </material>
    </visual>
    <collision>
      <origin xyz="0 0 0" rpy="1.5708 1.5708 0"/>
      <geometry>
        <mesh filename="package://assets/wheel.stl"/>
      </geometry>
    </collision>
  </link>
  <!-- Joint from body_right to wheel_5 -->
  <joint name="wheel_1_right" type="continuous">
    <origin xyz="0.0766777 -0.0417374 0.01" rpy="-2.40478e-15 -1.41754e-14 -3.14159"/>
    <parent link="body_right"/>
    <child link="wheel_5"/>
    <axis xyz="0 0 1"/>
    <limit effort="10" velocity="10"/>
  </joint>
  <!-- Link wheel_6 -->
  <link name="wheel_6">
    <inertial>
      <origin xyz="1.92585e-20 -1.24246e-18 -0.0225" rpy="0 0 0"/>
      <mass value="0.1"/>
      <inertia ixx="2.26562e-05" ixy="0" ixz="1.70287e-35" iyy="2.26562e-05" iyz="0" izz="1.15625e-05"/>
    </inertial>
    <!-- Part wheel_6 -->
    <visual>
      <origin xyz="0 0 0" rpy="1.5708 1.5708 0"/>
      <geometry>
        <mesh filename="package://assets/wheel.stl"/>
      </geometry>
      <material name="wheel_6_material">
        <color rgba="0.615686 0.811765 0.929412 1"/>
      </material>
    </visual>
    <collision>
      <origin xyz="0 0 0" rpy="1.5708 1.5708 0"/>
      <geometry>
        <mesh filename="package://assets/wheel.stl"/>
      </geometry>
    </collision>
  </link>
  <!-- Joint from body_right to wheel_6 -->
  <joint name="wheel_2_right" type="continuous">
    <origin xyz="0.0510312 -0.0583795 0.01" rpy="-2.40478e-15 -1.41754e-14 -3.14159"/>
    <parent link="body_right"/>
    <child link="wheel_6"/>
    <axis xyz="0 0 1"/>
    <limit effort="10" velocity="10"/>
  </joint>
  <!-- Link wheel_7 -->
  <link name="wheel_7">
    <inertial>
      <origin xyz="1.92585e-20 -1.24246e-18 -0.0225" rpy="0 0 0"/>
      <mass value="0.1"/>
      <inertia ixx="2.26562e-05" ixy="0" ixz="1.70287e-35" iyy="2.26562e-05" iyz="0" izz="1.15625e-05"/>
    </inertial>
    <!-- Part wheel_7 -->
    <visual>
      <origin xyz="0 0 0" rpy="1.5708 1.5708 0"/>
      <geometry>
        <mesh filename="package://assets/wheel.stl"/>
      </geometry>
      <material name="wheel_7_material">
        <color rgba="0.615686 0.811765 0.929412 1"/>
      </material>
    </visual>
    <collision>
      <origin xyz="0 0 0" rpy="1.5708 1.5708 0"/>
      <geometry>
        <mesh filename="package://assets/wheel.stl"/>
      </geometry>
    </collision>
  </link>
  <!-- Joint from body_right to wheel_7 -->
  <joint name="wheel_3_right" type="continuous">
    <origin xyz="-1.11022e-16 -0.0583795 0.01" rpy="-2.40478e-15 -1.41754e-14 -3.14159"/>
    <parent link="body_right"/>
    <child link="wheel_7"/>
    <axis xyz="0 0 1"/>
    <limit effort="10" velocity="10"/>
  </joint>
  <!-- Link wheel_8 -->
  <link name="wheel_8">
    <inertial>
      <origin xyz="1.92585e-20 -1.24246e-18 -0.0225" rpy="0 0 0"/>
      <mass value="0.1"/>
      <inertia ixx="2.26562e-05" ixy="0" ixz="1.70287e-35" iyy="2.26562e-05" iyz="0" izz="1.15625e-05"/>
    </inertial>
    <!-- Part wheel_8 -->
    <visual>
      <origin xyz="0 0 0" rpy="1.5708 1.5708 0"/>
      <geometry>
        <mesh filename="package://assets/wheel.stl"/>
      </geometry>
      <material name="wheel_8_material">
        <color rgba="0.615686 0.811765 0.929412 1"/>
      </material>
    </visual>
    <collision>
      <origin xyz="0 0 0" rpy="1.5708 1.5708 0"/>
      <geometry>
        <mesh filename="package://assets/wheel.stl"/>
      </geometry>
    </collision>
  </link>
  <!-- Joint from body_right to wheel_8 -->
  <joint name="wheel_4_right" type="continuous">
    <origin xyz="-0.0484063 -0.0583795 0.01" rpy="-2.40478e-15 -1.41754e-14 -3.14159"/>
    <parent link="body_right"/>
    <child link="wheel_8"/>
    <axis xyz="0 0 1"/>
    <limit effort="10" velocity="10"/>
  </joint>
  <!-- Joint from leg to body_right -->
  <joint name="base_right" type="revolute">
    <origin xyz="-1.11022e-16 0 -0.06" rpy="-1.33599e-16 -7.87523e-16 -6.45781e-16"/>
    <parent link="leg"/>
    <child link="body_right"/>
    <axis xyz="0 0 1"/>
    <limit effort="10" velocity="10" lower="-0.785398" upper="0.785398"/>
  </joint>
  <!-- Joint from body_left to leg -->
  <joint name="base_left" type="revolute">
    <origin xyz="-0.129266 -0.0575005 -0.0715997" rpy="1.5708 -6.45781e-16 -1.5708"/>
    <parent link="body_left"/>
    <child link="leg"/>
    <axis xyz="0 0 1"/>
    <limit effort="10" velocity="10" lower="-0.785398" upper="0.785398"/>
  </joint>
</robot>
