<?xml version="1.0" ?>
<!-- Generated using onshape-to-robot -->
<!-- Onshape document_id: 1f813eeba4ab32efffd87c1d -->
<robot name="track_right">
  <!-- Link body_right -->
  <link name="body_right">
    <inertial>
      <origin xyz="-0.0238777 0.00412068 -0.00119624" rpy="0 0 0"/>
      <mass value="0.6"/>
      <inertia ixx="0.000408384" ixy="3.09979e-05" ixz="-6.93353e-06" iyy="0.000303698" iyz="2.90084e-05" izz="0.000335218"/>
    </inertial>
    <!-- Part body_right -->
    <visual>
      <origin xyz="1.06911e-50 -4.41854e-07 3.98827e-51" rpy="-1.5708 5.05322e-16 -3.14159"/>
      <geometry>
        <mesh filename="package://assets/body_right.stl"/>
      </geometry>
      <material name="body_right_material">
        <color rgba="0.647059 0.647059 0.647059 1"/>
      </material>
    </visual>
    <collision>
      <origin xyz="1.06911e-50 -4.41854e-07 3.98827e-51" rpy="-1.5708 5.05322e-16 -3.14159"/>
      <geometry>
        <mesh filename="package://assets/body_right.stl"/>
      </geometry>
    </collision>
  </link>
  <!-- Link wheel -->
  <link name="wheel">
    <inertial>
      <origin xyz="-1.38585e-17 -2.22698e-18 -0.0225" rpy="0 0 0"/>
      <mass value="0.1"/>
      <inertia ixx="2.26562e-05" ixy="1.25767e-21" ixz="-3.51752e-35" iyy="2.26562e-05" iyz="5.70075e-37" izz="1.15625e-05"/>
    </inertial>
    <!-- Part wheel -->
    <visual>
      <origin xyz="-1.38778e-17 -3.46945e-18 -0.045" rpy="-1.5708 -1.5708 0"/>
      <geometry>
        <mesh filename="package://assets/wheel.stl"/>
      </geometry>
      <material name="wheel_material">
        <color rgba="0.615686 0.811765 0.929412 1"/>
      </material>
    </visual>
    <collision>
      <origin xyz="-1.38778e-17 -3.46945e-18 -0.045" rpy="-1.5708 -1.5708 0"/>
      <geometry>
        <mesh filename="package://assets/wheel.stl"/>
      </geometry>
    </collision>
  </link>
  <!-- Joint from body_right to wheel -->
  <joint name="wheel_1_left" type="continuous">
    <origin xyz="2.08167e-17 0.0583795 0.0484062" rpy="-1.5708 0.992087 -1.5708"/>
    <parent link="body_right"/>
    <child link="wheel"/>
    <axis xyz="0 0 1"/>
    <limit effort="10" velocity="10"/>
  </joint>
  <!-- Link wheel_2 -->
  <link name="wheel_2">
    <inertial>
      <origin xyz="1.92585e-20 1.24246e-18 -0.0225" rpy="0 0 0"/>
      <mass value="0.1"/>
      <inertia ixx="2.26562e-05" ixy="-1.25767e-21" ixz="-5.70075e-37" iyy="2.26562e-05" iyz="0" izz="1.15625e-05"/>
    </inertial>
    <!-- Part wheel_2 -->
    <visual>
      <origin xyz="0 0 -0.045" rpy="-1.5708 -1.5708 0"/>
      <geometry>
        <mesh filename="package://assets/wheel.stl"/>
      </geometry>
      <material name="wheel_2_material">
        <color rgba="0.615686 0.811765 0.929412 1"/>
      </material>
    </visual>
    <collision>
      <origin xyz="0 0 -0.045" rpy="-1.5708 -1.5708 0"/>
      <geometry>
        <mesh filename="package://assets/wheel.stl"/>
      </geometry>
    </collision>
  </link>
  <!-- Joint from body_right to wheel_2 -->
  <joint name="wheel_2_left" type="continuous">
    <origin xyz="0 0.0583795 1.10544e-16" rpy="-1.5708 0.967866 -1.5708"/>
    <parent link="body_right"/>
    <child link="wheel_2"/>
    <axis xyz="0 0 1"/>
    <limit effort="10" velocity="10"/>
  </joint>
  <!-- Link wheel_3 -->
  <link name="wheel_3">
    <inertial>
      <origin xyz="1.75398e-18 1.24246e-18 -0.0225" rpy="0 0 0"/>
      <mass value="0.1"/>
      <inertia ixx="2.26562e-05" ixy="2.51535e-21" ixz="-1.61624e-35" iyy="2.26562e-05" iyz="9.50639e-36" izz="1.15625e-05"/>
    </inertial>
    <!-- Part wheel_3 -->
    <visual>
      <origin xyz="1.73472e-18 0 -0.045" rpy="-1.5708 -1.5708 0"/>
      <geometry>
        <mesh filename="package://assets/wheel.stl"/>
      </geometry>
      <material name="wheel_3_material">
        <color rgba="0.615686 0.811765 0.929412 1"/>
      </material>
    </visual>
    <collision>
      <origin xyz="1.73472e-18 0 -0.045" rpy="-1.5708 -1.5708 0"/>
      <geometry>
        <mesh filename="package://assets/wheel.stl"/>
      </geometry>
    </collision>
  </link>
  <!-- Joint from body_right to wheel_3 -->
  <joint name="wheel_3_left" type="continuous">
    <origin xyz="-2.08167e-17 0.0583795 -0.0510312" rpy="-1.5708 0.967866 -1.5708"/>
    <parent link="body_right"/>
    <child link="wheel_3"/>
    <axis xyz="0 0 1"/>
    <limit effort="10" velocity="10"/>
  </joint>
  <!-- Link wheel_4 -->
  <link name="wheel_4">
    <inertial>
      <origin xyz="1.92585e-20 1.51202e-17 -0.0225" rpy="0 0 0"/>
      <mass value="0.1"/>
      <inertia ixx="2.26562e-05" ixy="-1.25767e-21" ixz="0" iyy="2.26562e-05" iyz="0" izz="1.15625e-05"/>
    </inertial>
    <!-- Part wheel_4 -->
    <visual>
      <origin xyz="0 1.38778e-17 -0.045" rpy="-1.5708 -1.5708 0"/>
      <geometry>
        <mesh filename="package://assets/wheel.stl"/>
      </geometry>
      <material name="wheel_4_material">
        <color rgba="0.615686 0.811765 0.929412 1"/>
      </material>
    </visual>
    <collision>
      <origin xyz="0 1.38778e-17 -0.045" rpy="-1.5708 -1.5708 0"/>
      <geometry>
        <mesh filename="package://assets/wheel.stl"/>
      </geometry>
    </collision>
  </link>
  <!-- Joint from body_right to wheel_4 -->
  <joint name="wheel_4_left" type="continuous">
    <origin xyz="-3.46945e-17 0.0417374 -0.0766777" rpy="-1.5708 0.992087 -1.5708"/>
    <parent link="body_right"/>
    <child link="wheel_4"/>
    <axis xyz="0 0 1"/>
    <limit effort="10" velocity="10"/>
  </joint>
</robot>
