<?xml version="1.0" ?>
<!-- =================================================================================== -->
<!-- |    This document was autogenerated by xacro from mulinex.xacro                  | -->
<!-- |    EDITING THIS FILE BY HAND IS NOT RECOMMENDED                                 | -->
<!-- =================================================================================== -->
<robot name="mulinex">
  <!-- <xacro:property name="base_2_HFE_x" value="${190.00 * 0.001}" /> -->
  <!-- <xacro:property name="base_2_HFE_y" value="${104.60 * 0.001}" /> -->
  <!--  -->
  <!-- EACH MACRO CONSISTS OF THE LINK AND ITS PREVIOUS JOINT -->
  <!--  -->
  <!-- <xacro:property name="base_2_HFE_x" value="${190.00 * 0.001}" /> -->
  <!-- <xacro:property name="base_2_HFE_y" value="${104.60 * 0.001}" /> -->
  <!--  -->
  <!-- EACH MACRO CONSISTS OF THE LINK AND ITS PREVIOUS JOINT -->
  <!--  -->
  <material name="black">
    <color rgba="0.0 0.0 0.0 1.0"/>
  </material>
  <material name="blue">
    <color rgba="0.0 0.0 0.8 1.0"/>
  </material>
  <material name="green">
    <color rgba="0.0 0.8 0.0 1.0"/>
  </material>
  <material name="grey">
    <color rgba="0.2 0.2 0.2 1.0"/>
  </material>
  <material name="orange">
    <color rgba="1.0 0.4235294117647059 0.0392156862745098 0.5"/>
  </material>
  <material name="brown">
    <color rgba="0.8705882352941177 0.8117647058823529 0.7647058823529411 1.0"/>
  </material>
  <material name="red">
    <color rgba="0.8 0.0 0.0 1.0"/>
  </material>
  <material name="white">
    <color rgba="1.0 1.0 1.0 1.0"/>
  </material>
  <link name="base_link">
    <visual>
      <material name="white"/>
      <origin rpy="0 0 0" xyz="0 0 0"/>
      <geometry>
        <mesh filename="file:///home/francesco/Documents/mulinex_ws/install/mulinex_omni_description/share/mulinex_omni_description/meshes//Body.stl"/>
        <!-- <box size="0.353 0.090 0.066" /> -->
      </geometry>
    </visual>
    <collision>
      <origin rpy="0 0 0" xyz="0 0 0"/>
      <geometry>
        <box size="0.353 0.090 0.066"/>
      </geometry>
    </collision>
    <inertial>
      <mass value="1.3008737"/>
      <origin rpy="0 0 0" xyz="-1.4565496e-03 -2.5110071e-03 -4.2484136e-03"/>
      <inertia ixx="4.0762590e-03" ixy="-2.5234809e-05" ixz="-3.2587794e-06" iyy="9.2413606e-03" iyz="-8.0660183e-06" izz="1.2268730e-02"/>
    </inertial>
  </link>
  <!-- Joint to fix the leg to the base -->
  <joint name="LH_HAA" type="fixed">
    <parent link="base_link"/>
    <child link="LH_SHOULDER"/>
    <origin rpy="0 0 0" xyz="-0.045 0.081 0"/>
  </joint>
  <!-- Shoulder link -->
  <link name="LH_SHOULDER">
    <visual>
      <material name="white"/>
      <origin rpy="0 0 0" xyz="0 0 0"/>
      <geometry>
        <mesh filename="file:///home/francesco/Documents/mulinex_ws/install/mulinex_omni_description/share/mulinex_omni_description/meshes//Module_left_hind.stl"/>
      </geometry>
    </visual>
    <collision>
      <origin rpy="0 0 0" xyz="-0.0945 0 0"/>
      <geometry>
        <!-- <mesh filename="${mulinex_module_left_hind}" /> -->
        <box size="0.269 0.057 0.060"/>
      </geometry>
    </collision>
    <inertial>
      <mass value="0.47669673"/>
      <origin rpy="0 0 0" xyz="-7.2487360e-02 3.1582591e-02 2.4812434e-03"/>
      <inertia ixx="2.1574269e-04" ixy="3.3437484e-05" ixz="-2.4284668e-06" iyy="3.0607390e-03" iyz="-2.0388977e-06" izz="3.0504273e-03"/>
    </inertial>
  </link>
  <gazebo reference="LH_SHOULDER">
    <material>Gazebo/White</material>
    <collision>
      <surface>
        <friction>
          <ode>
            <mu>1</mu>
            <mu2>1</mu2>
            <slip1>0</slip1>
            <slip2>0</slip2>
          </ode>
        </friction>
        <contact>
          <ode>
            <kp>1000000.0</kp>
            <kd>100.0</kd>
            <min_depth>0.001</min_depth>
          </ode>
        </contact>
      </surface>
    </collision>
  </gazebo>
  <!-- Hip joint -->
  <joint name="LH_HFE" type="revolute">
    <parent link="LH_SHOULDER"/>
    <child link="LH_UPPER_LEG"/>
    <origin rpy="0 0 0" xyz="-0.19 0.044 0"/>
    <axis xyz="0 1 0"/>
    <limit effort="2.7" lower="-3.141592" upper="3.141592" velocity="1000"/>
    <!-- <dynamics damping="0.7" friction="100.0" /> -->
  </joint>
  <!-- Upper leg link -->
  <link name="LH_UPPER_LEG">
    <visual>
      <material name="white"/>
      <origin rpy="0 0 0" xyz="0 0 0"/>
      <geometry>
        <mesh filename="file:///home/francesco/Documents/mulinex_ws/install/mulinex_omni_description/share/mulinex_omni_description/meshes//Module_left_hind.stl"/>
      </geometry>
    </visual>
    <collision>
      <origin rpy="0 0 0" xyz="-0.0945 0.015 0"/>
      <geometry>
        <!-- <mesh filename="${mulinex_module_left_hind}" /> -->
        <box size="0.269 0.057 0.060"/>
      </geometry>
    </collision>
    <inertial>
      <mass value="0.47669673"/>
      <origin rpy="0 0 0" xyz="-7.2487360e-02 3.1582591e-02 2.4812434e-03"/>
      <inertia ixx="2.1574269e-04" ixy="3.3437484e-05" ixz="-2.4284668e-06" iyy="3.0607390e-03" iyz="-2.0388977e-06" izz="3.0504273e-03"/>
    </inertial>
  </link>
  <gazebo reference="LH_UPPER_LEG">
    <material>Gazebo/White</material>
    <collision>
      <surface>
        <friction>
          <ode>
            <mu>1</mu>
            <mu2>1</mu2>
            <slip1>0</slip1>
            <slip2>0</slip2>
          </ode>
        </friction>
        <contact>
          <ode>
            <kp>1000000.0</kp>
            <kd>100.0</kd>
            <min_depth>0.001</min_depth>
          </ode>
        </contact>
      </surface>
    </collision>
  </gazebo>
  <!-- Knee joint -->
  <joint name="LH_KFE" type="revolute">
    <parent link="LH_UPPER_LEG"/>
    <child link="LH_LOWER_LEG"/>
    <origin rpy="0 0 0" xyz="-0.19 0.044 0"/>
    <axis xyz="0 1 0"/>
    <limit effort="2.7" lower="-3.141592" upper="3.141592" velocity="1000"/>
    <!-- <dynamics damping="0.7" friction="100.0" /> -->
  </joint>
  <!-- Lower leg link -->
  <link name="LH_LOWER_LEG">
    <visual>
      <material name="white"/>
      <origin rpy="0 1.570796 0" xyz="0 0 0"/>
      <geometry>
        <mesh filename="file:///home/francesco/Documents/mulinex_ws/install/mulinex_omni_description/share/mulinex_omni_description/meshes//Lower_leg_left.stl"/>
      </geometry>
    </visual>
    <collision name="LH_LOWER_LEG">
      <origin rpy="0 1.570796 0" xyz="-0.096 0.012 0.0"/>
      <geometry>
        <box size="0.032 0.024 0.192"/>
      </geometry>
    </collision>
    <inertial>
      <mass value="0.30551"/>
      <origin rpy="0 0 0" xyz="-0.17801 0.030272 -1.8448E-05"/>
      <inertia ixx="6.1505E-05" ixy="1.5369E-05" ixz="-4.7734E-08" iyy="0.00054256" iyz="1.9337E-08" izz="0.00051876"/>
    </inertial>
  </link>
  <gazebo reference="LH_LOWER_LEG">
    <material>Gazebo/White</material>
    <collision>
      <surface>
        <friction>
          <ode>
            <mu>0.6</mu>
            <mu2>0.6</mu2>
            <slip1>0</slip1>
            <slip2>0</slip2>
          </ode>
        </friction>
        <contact>
          <ode>
            <kp>10000.0</kp>
            <kd>100.0</kd>
            <min_depth>0.001</min_depth>
          </ode>
        </contact>
      </surface>
    </collision>
  </gazebo>
  <joint name="LH_ANKLE" type="continuous">
    <parent link="LH_LOWER_LEG"/>
    <child link="LH_WHEEL"/>
    <origin rpy="0 0 0" xyz="-0.19 0.01145 0"/>
    <axis xyz="0 1 0"/>
  </joint>
  <link name="LH_WHEEL">
    <visual>
      <material name="white"/>
      <origin rpy="0 0 0" xyz="0 0  0"/>
      <geometry>
        <mesh filename="file:///home/francesco/Documents/mulinex_ws/install/mulinex_omni_description/share/mulinex_omni_description/meshes//mecanum_wheel_lh.STL"/>
      </geometry>
    </visual>
    <collision>
      <origin rpy="0 0 0" xyz="0 0 0"/>
      <geometry>
        <mesh filename="file:///home/francesco/Documents/mulinex_ws/install/mulinex_omni_description/share/mulinex_omni_description/meshes//mecanum_wheel_lh.STL"/>
      </geometry>
    </collision>
    <inertial>
      <origin rpy="0 0 0" xyz="0 0.047255 -1.5525E-07"/>
      <mass value="0.078525"/>
      <inertia ixx="4.9627E-05" ixy="-2.1009E-12" ixz="-1.8882E-09" iyy="7.8948E-05" iyz="4.4431E-12" izz="4.9622E-05"/>
    </inertial>
  </link>
  <gazebo reference="LH_WHEEL">
    <material>Gazebo/White</material>
    <collision>
      <surface>
        <friction>
          <ode>
            <mu>0.6</mu>
            <mu2>0.6</mu2>
            <slip1>0</slip1>
            <slip2>0</slip2>
          </ode>
        </friction>
        <contact>
          <ode>
            <kp>10000.0</kp>
            <kd>100.0</kd>
            <min_depth>0.001</min_depth>
          </ode>
        </contact>
      </surface>
    </collision>
  </gazebo>
  <!-- <joint name="${prefix}_DIRECTION" type="fixed">
                <parent link="${prefix}_WHEEL" />
                <child link="${prefix}_INDICATOR" />
                <xacro:if value="${prefix == 'LF'}">
                    <origin xyz="0 0.0501 0" rpy="0 0 0" />
                </xacro:if>
                <xacro:if value="${prefix == 'LH'}">
                    <origin xyz="0 0.0501 0" rpy="0 0 0" />
                </xacro:if>
                <xacro:if value="${prefix == 'RF'}">
                    <origin xyz="0 -0.0501 0" rpy="0 0 0" />
                </xacro:if>
                <xacro:if value="${prefix == 'RH'}">
                    <origin xyz="0 -0.0501 0" rpy="0 0 0" />
                </xacro:if>
            </joint> -->
  <!-- <link name="${prefix}_INDICATOR">
                <visual>
                    <origin xyz="0 0 0.0075" rpy="0 0 0" />
                    <geometry>
                        <box size="0.004 0.0001 0.015" />
                    </geometry>
                    <material name="red" />
                </visual>
            </link> -->
  <link name="LH_Roller1">
    <inertial>
      <origin rpy="0 0 0" xyz="0 0 6.3075E-15"/>
      <mass value="0.0059616"/>
      <inertia ixx="7.911E-07" ixy="1.2914E-12" ixz="1.9521E-22" iyy="7.9113E-07" iyz="-5.0954E-22" izz="2.3532E-07"/>
    </inertial>
    <visual>
      <origin rpy="0 0 0" xyz="0 0 0"/>
      <geometry>
        <mesh filename="file:///home/francesco/Documents/mulinex_ws/install/mulinex_omni_description/share/mulinex_omni_description/meshes//roller_1.STL"/>
      </geometry>
      <material name="white"/>
    </visual>
    <collision>
      <origin rpy="0 0 0" xyz="0 0 0"/>
      <geometry>
        <mesh filename="file:///home/francesco/Documents/mulinex_ws/install/mulinex_omni_description/share/mulinex_omni_description/meshes//roller_1.STL"/>
      </geometry>
    </collision>
  </link>
  <gazebo reference="LH_Roller1">
    <material>Gazebo/White</material>
    <collision>
      <surface>
        <friction>
          <ode>
            <mu>0.6</mu>
            <mu2>0.6</mu2>
            <slip1>0</slip1>
            <slip2>0</slip2>
          </ode>
        </friction>
        <contact>
          <ode>
            <kp>10000.0</kp>
            <kd>100.0</kd>
            <min_depth>0.001</min_depth>
          </ode>
        </contact>
      </surface>
    </collision>
    <sensor name="LH_contactsensor_sensor" type="contact">
      <always_on>true</always_on>
      <update_rate>50</update_rate>
      <contact>
        <collision>
                            LH_LOWER_LEG_fixed_joint_lump__LH_FOOT_collision_1</collision>
      </contact>
    </sensor>
  </gazebo>
  <link name="LH_Roller2">
    <inertial>
      <origin rpy="0 0 0" xyz="0 0 6.3075E-15"/>
      <mass value="0.0059616"/>
      <inertia ixx="7.911E-07" ixy="1.2914E-12" ixz="-7.6101E-23" iyy="7.9113E-07" iyz="1.522E-22" izz="2.3532E-07"/>
    </inertial>
    <visual>
      <origin rpy="0 0 0" xyz="0 0 0"/>
      <geometry>
        <mesh filename="file:///home/francesco/Documents/mulinex_ws/install/mulinex_omni_description/share/mulinex_omni_description/meshes//roller_1.STL"/>
      </geometry>
      <material name="white"/>
    </visual>
    <collision>
      <origin rpy="0 0 0" xyz="0 0 0"/>
      <geometry>
        <mesh filename="file:///home/francesco/Documents/mulinex_ws/install/mulinex_omni_description/share/mulinex_omni_description/meshes//roller_1.STL"/>
      </geometry>
    </collision>
  </link>
  <gazebo reference="LH_Rollert2">
    <material>Gazebo/White</material>
    <collision>
      <surface>
        <friction>
          <ode>
            <mu>0.6</mu>
            <mu2>0.6</mu2>
            <slip1>0</slip1>
            <slip2>0</slip2>
          </ode>
        </friction>
        <contact>
          <ode>
            <kp>10000.0</kp>
            <kd>100.0</kd>
            <min_depth>0.001</min_depth>
          </ode>
        </contact>
      </surface>
    </collision>
    <sensor name="LH_contactsensor_sensor" type="contact">
      <always_on>true</always_on>
      <update_rate>50</update_rate>
      <contact>
        <collision>
                            LH_LOWER_LEG_fixed_joint_lump__LH_FOOT_collision_1</collision>
      </contact>
    </sensor>
  </gazebo>
  <link name="LH_Roller3">
    <inertial>
      <origin rpy="0 0 0" xyz="0 0 6.3075E-15"/>
      <mass value="0.0059616"/>
      <inertia ixx="7.911E-07" ixy="1.2914E-12" ixz="-7.6101E-23" iyy="7.9113E-07" iyz="1.522E-22" izz="2.3532E-07"/>
    </inertial>
    <visual>
      <origin rpy="0 0 0" xyz="0 0 0"/>
      <geometry>
        <mesh filename="file:///home/francesco/Documents/mulinex_ws/install/mulinex_omni_description/share/mulinex_omni_description/meshes//roller_1.STL"/>
      </geometry>
      <material name="white"/>
    </visual>
    <collision>
      <origin rpy="0 0 0" xyz="0 0 0"/>
      <geometry>
        <mesh filename="file:///home/francesco/Documents/mulinex_ws/install/mulinex_omni_description/share/mulinex_omni_description/meshes//roller_1.STL"/>
      </geometry>
    </collision>
  </link>
  <gazebo reference="LH_Roller3">
    <material>Gazebo/White</material>
    <collision>
      <surface>
        <friction>
          <ode>
            <mu>0.6</mu>
            <mu2>0.6</mu2>
            <slip1>0</slip1>
            <slip2>0</slip2>
          </ode>
        </friction>
        <contact>
          <ode>
            <kp>10000.0</kp>
            <kd>100.0</kd>
            <min_depth>0.001</min_depth>
          </ode>
        </contact>
      </surface>
    </collision>
    <sensor name="LH_contactsensor_sensor" type="contact">
      <always_on>true</always_on>
      <update_rate>50</update_rate>
      <contact>
        <collision>
                            LH_LOWER_LEG_fixed_joint_lump__LH_FOOT_collision_1</collision>
      </contact>
    </sensor>
  </gazebo>
  <link name="LH_Roller4">
    <inertial>
      <origin rpy="0 0 0" xyz="0 0 6.3075E-15"/>
      <mass value="0.0059616"/>
      <inertia ixx="7.911E-07" ixy="1.2914E-12" ixz="2.4485E-22" iyy="7.9113E-07" iyz="5.0293E-22" izz="2.3532E-07"/>
    </inertial>
    <visual>
      <origin rpy="0 0 0" xyz="0 0 0"/>
      <geometry>
        <mesh filename="file:///home/francesco/Documents/mulinex_ws/install/mulinex_omni_description/share/mulinex_omni_description/meshes//roller_1.STL"/>
      </geometry>
      <material name="white"/>
    </visual>
    <collision>
      <origin rpy="0 0 0" xyz="0 0 0"/>
      <geometry>
        <mesh filename="file:///home/francesco/Documents/mulinex_ws/install/mulinex_omni_description/share/mulinex_omni_description/meshes//roller_1.STL"/>
      </geometry>
    </collision>
  </link>
  <gazebo reference="LH_Roller4">
    <material>Gazebo/White</material>
    <collision>
      <surface>
        <friction>
          <ode>
            <mu>0.6</mu>
            <mu2>0.6</mu2>
            <slip1>0</slip1>
            <slip2>0</slip2>
          </ode>
        </friction>
        <contact>
          <ode>
            <kp>10000.0</kp>
            <kd>100.0</kd>
            <min_depth>0.001</min_depth>
          </ode>
        </contact>
      </surface>
    </collision>
    <sensor name="LH_contactsensor_sensor" type="contact">
      <always_on>true</always_on>
      <update_rate>50</update_rate>
      <contact>
        <collision>
                              LH_LOWER_LEG_fixed_joint_lump__LH_FOOT_collision_1</collision>
      </contact>
    </sensor>
  </gazebo>
  <link name="LH_Roller5">
    <inertial>
      <origin rpy="0 0 0" xyz="0 0 6.3075E-15"/>
      <mass value="0.0059616"/>
      <inertia ixx="7.911E-07" ixy="1.2914E-12" ixz="-8.2718E-23" iyy="7.9113E-07" iyz="3.1764E-22" izz="2.3532E-07"/>
    </inertial>
    <visual>
      <origin rpy="0 0 0" xyz="0 0 0"/>
      <geometry>
        <mesh filename="file:///home/francesco/Documents/mulinex_ws/install/mulinex_omni_description/share/mulinex_omni_description/meshes//roller_1.STL"/>
      </geometry>
      <material name="white"/>
    </visual>
    <collision>
      <origin rpy="0 0 0" xyz="0 0 0"/>
      <geometry>
        <mesh filename="file:///home/francesco/Documents/mulinex_ws/install/mulinex_omni_description/share/mulinex_omni_description/meshes//roller_1.STL"/>
      </geometry>
    </collision>
  </link>
  <gazebo reference="LH_Roller5">
    <material>Gazebo/White</material>
    <collision>
      <surface>
        <friction>
          <ode>
            <mu>0.6</mu>
            <mu2>0.6</mu2>
            <slip1>0</slip1>
            <slip2>0</slip2>
          </ode>
        </friction>
        <contact>
          <ode>
            <kp>10000.0</kp>
            <kd>100.0</kd>
            <min_depth>0.001</min_depth>
          </ode>
        </contact>
      </surface>
    </collision>
    <sensor name="LH_contactsensor_sensor" type="contact">
      <always_on>true</always_on>
      <update_rate>50</update_rate>
      <contact>
        <collision>
                            LH_LOWER_LEG_fixed_joint_lump__LH_FOOT_collision_1</collision>
      </contact>
    </sensor>
  </gazebo>
  <link name="LH_Roller6">
    <inertial>
      <origin rpy="0 0 0" xyz="0 0 6.3075E-15"/>
      <mass value="0.0059616"/>
      <inertia ixx="7.911E-07" ixy="1.2914E-12" ixz="1.3235E-23" iyy="7.9113E-07" iyz="1.3235E-23" izz="2.3532E-07"/>
    </inertial>
    <visual>
      <origin rpy="0 0 0" xyz="0 0 0"/>
      <geometry>
        <mesh filename="file:///home/francesco/Documents/mulinex_ws/install/mulinex_omni_description/share/mulinex_omni_description/meshes//roller_1.STL"/>
      </geometry>
      <material name="white"/>
    </visual>
    <collision>
      <origin rpy="0 0 0" xyz="0 0 0"/>
      <geometry>
        <mesh filename="file:///home/francesco/Documents/mulinex_ws/install/mulinex_omni_description/share/mulinex_omni_description/meshes//roller_1.STL"/>
      </geometry>
    </collision>
  </link>
  <gazebo reference="LH_Roller6">
    <material>Gazebo/White</material>
    <collision>
      <surface>
        <friction>
          <ode>
            <mu>0.6</mu>
            <mu2>0.6</mu2>
            <slip1>0</slip1>
            <slip2>0</slip2>
          </ode>
        </friction>
        <contact>
          <ode>
            <kp>10000.0</kp>
            <kd>100.0</kd>
            <min_depth>0.001</min_depth>
          </ode>
        </contact>
      </surface>
    </collision>
    <sensor name="LH_contactsensor_sensor" type="contact">
      <always_on>true</always_on>
      <update_rate>50</update_rate>
      <contact>
        <collision>
                            LH_LOWER_LEG_fixed_joint_lump__LH_FOOT_collision_1</collision>
      </contact>
    </sensor>
  </gazebo>
  <link name="LH_Roller7">
    <inertial>
      <origin rpy="0 0 0" xyz="0 0 6.3075E-15"/>
      <mass value="0.0059616"/>
      <inertia ixx="7.9113E-07" ixy="-9.1022E-13" ixz="-8.4703E-22" iyy="7.911E-07" iyz="-2.8124E-22" izz="2.3532E-07"/>
    </inertial>
    <visual>
      <origin rpy="0 0 0" xyz="0 0 0"/>
      <geometry>
        <mesh filename="file:///home/francesco/Documents/mulinex_ws/install/mulinex_omni_description/share/mulinex_omni_description/meshes//roller_1.STL"/>
      </geometry>
      <material name="white"/>
    </visual>
    <collision>
      <origin rpy="0 0 0" xyz="0 0 0"/>
      <geometry>
        <mesh filename="file:///home/francesco/Documents/mulinex_ws/install/mulinex_omni_description/share/mulinex_omni_description/meshes//roller_1.STL"/>
      </geometry>
    </collision>
  </link>
  <gazebo reference="LH_Roller7">
    <material>Gazebo/White</material>
    <collision>
      <surface>
        <friction>
          <ode>
            <mu>0.6</mu>
            <mu2>0.6</mu2>
            <slip1>0</slip1>
            <slip2>0</slip2>
          </ode>
        </friction>
        <contact>
          <ode>
            <kp>10000.0</kp>
            <kd>100.0</kd>
            <min_depth>0.001</min_depth>
          </ode>
        </contact>
      </surface>
    </collision>
    <sensor name="LH_contactsensor_sensor" type="contact">
      <always_on>true</always_on>
      <update_rate>50</update_rate>
      <contact>
        <collision>
                            LH_LOWER_LEG_fixed_joint_lump__LH_FOOT_collision_1</collision>
      </contact>
    </sensor>
  </gazebo>
  <link name="LH_Roller8">
    <inertial>
      <origin rpy="0 0 0" xyz="0 0 6.3075E-15"/>
      <mass value="0.0059616"/>
      <inertia ixx="7.911E-07" ixy="1.2914E-12" ixz="4.3013E-23" iyy="7.9113E-07" iyz="-5.294E-22" izz="2.3532E-07"/>
    </inertial>
    <visual>
      <origin rpy="0 0 0" xyz="0 0 0"/>
      <geometry>
        <mesh filename="file:///home/francesco/Documents/mulinex_ws/install/mulinex_omni_description/share/mulinex_omni_description/meshes//roller_1.STL"/>
      </geometry>
      <material name="white"/>
    </visual>
    <collision>
      <origin rpy="0 0 0" xyz="0 0 0"/>
      <geometry>
        <mesh filename="file:///home/francesco/Documents/mulinex_ws/install/mulinex_omni_description/share/mulinex_omni_description/meshes//roller_1.STL"/>
      </geometry>
    </collision>
  </link>
  <gazebo reference="LH_Roller8">
    <material>Gazebo/White</material>
    <collision>
      <surface>
        <friction>
          <ode>
            <mu>0.6</mu>
            <mu2>0.6</mu2>
            <slip1>0</slip1>
            <slip2>0</slip2>
          </ode>
        </friction>
        <contact>
          <ode>
            <kp>10000.0</kp>
            <kd>100.0</kd>
            <min_depth>0.001</min_depth>
          </ode>
        </contact>
      </surface>
    </collision>
    <sensor name="LH_contactsensor_sensor" type="contact">
      <always_on>true</always_on>
      <update_rate>50</update_rate>
      <contact>
        <collision>
                            LH_LOWER_LEG_fixed_joint_lump__LH_FOOT_collision_1</collision>
      </contact>
    </sensor>
  </gazebo>
  <link name="LH_Roller9">
    <inertial>
      <origin rpy="0 0 0" xyz="0 0 6.3075E-15"/>
      <mass value="0.0059616"/>
      <inertia ixx="7.911E-07" ixy="1.2914E-12" ixz="1.7205E-22" iyy="7.9113E-07" iyz="7.2792E-23" izz="2.3532E-07"/>
    </inertial>
    <visual>
      <origin rpy="0 0 0" xyz="0 0 0"/>
      <geometry>
        <mesh filename="file:///home/francesco/Documents/mulinex_ws/install/mulinex_omni_description/share/mulinex_omni_description/meshes//roller_1.STL"/>
      </geometry>
      <material name="white"/>
    </visual>
    <collision>
      <origin rpy="0 0 0" xyz="0 0 0"/>
      <geometry>
        <mesh filename="file:///home/francesco/Documents/mulinex_ws/install/mulinex_omni_description/share/mulinex_omni_description/meshes//roller_1.STL"/>
      </geometry>
    </collision>
  </link>
  <gazebo reference="LH_Roller9">
    <material>Gazebo/White</material>
    <collision>
      <surface>
        <friction>
          <ode>
            <mu>0.6</mu>
            <mu2>0.6</mu2>
            <slip1>0</slip1>
            <slip2>0</slip2>
          </ode>
        </friction>
        <contact>
          <ode>
            <kp>10000.0</kp>
            <kd>100.0</kd>
            <min_depth>0.001</min_depth>
          </ode>
        </contact>
      </surface>
    </collision>
    <sensor name="LH_contactsensor_sensor" type="contact">
      <always_on>true</always_on>
      <update_rate>50</update_rate>
      <contact>
        <collision>
                            LH_LOWER_LEG_fixed_joint_lump__LH_FOOT_collision_1</collision>
      </contact>
    </sensor>
  </gazebo>
  <link name="LH_Roller10">
    <inertial>
      <origin rpy="0 0 0" xyz="0 0 6.3075E-15"/>
      <mass value="0.0059616"/>
      <inertia ixx="7.911E-07" ixy="1.2914E-12" ixz="-7.2792E-23" iyy="7.9113E-07" iyz="5.294E-23" izz="2.3532E-07"/>
    </inertial>
    <visual>
      <origin rpy="0 0 0" xyz="0 0 0"/>
      <geometry>
        <mesh filename="file:///home/francesco/Documents/mulinex_ws/install/mulinex_omni_description/share/mulinex_omni_description/meshes//roller_1.STL"/>
      </geometry>
      <material name="white"/>
    </visual>
    <collision>
      <origin rpy="0 0 0" xyz="0 0 0"/>
      <geometry>
        <mesh filename="file:///home/francesco/Documents/mulinex_ws/install/mulinex_omni_description/share/mulinex_omni_description/meshes//roller_1.STL"/>
      </geometry>
    </collision>
  </link>
  <gazebo reference="LH_Roller9">
    <material>Gazebo/White</material>
    <collision>
      <surface>
        <friction>
          <ode>
            <mu>0.6</mu>
            <mu2>0.6</mu2>
            <slip1>0</slip1>
            <slip2>0</slip2>
          </ode>
        </friction>
        <contact>
          <ode>
            <kp>10000.0</kp>
            <kd>100.0</kd>
            <min_depth>0.001</min_depth>
          </ode>
        </contact>
      </surface>
    </collision>
    <sensor name="LH_contactsensor_sensor" type="contact">
      <always_on>true</always_on>
      <update_rate>50</update_rate>
      <contact>
        <collision>
                            LH_LOWER_LEG_fixed_joint_lump__LH_FOOT_collision_1</collision>
      </contact>
    </sensor>
  </gazebo>
  <!--           <joint
            name="${prefix}_rol1"
            type="continuous">
            <origin
              xyz="-0.026605 -0.015694 0.01516"
              rpy="${-PI/2} 0 0" />
            <parent
              link="${prefix}_WHEEL"/>
            <child
              link="${prefix}_Roller1" />
            <axis
              xyz="-0.37796 0.65465 -0.65465" />
          </joint> -->
  <joint name="LH_rol1" type="continuous">
    <parent link="LH_WHEEL"/>
    <child link="LH_Roller1"/>
    <axis xyz="0 0 -1"/>
    <origin rpy="-0.46325 -0.87701 -0.46325" xyz="0.033776 0.04345 0.02454"/>
  </joint>
  <joint name="LH_rol2" type="continuous">
    <parent link="LH_WHEEL"/>
    <child link="LH_Roller2"/>
    <axis xyz="0 0 -1 "/>
    <origin rpy="0.70109 -1.2808 -1.5327" xyz="0.0129 0.04345 0.039707"/>
  </joint>
  <joint name="LH_rol3" type="continuous">
    <parent link="LH_WHEEL"/>
    <child link="LH_Roller3"/>
    <origin rpy="1.9287 -0.8973 -2.6657" xyz="-0.012901 0.04345 0.039707"/>
    <axis xyz="0 0 -1"/>
  </joint>
  <joint name="LH_rol4" type="continuous">
    <parent link="LH_WHEEL"/>
    <child link="LH_Roller4"/>
    <origin rpy="2.2155 -0.31149 -2.8367" xyz="-0.03378 0.04345 0.02454"/>
    <axis xyz="0 0 -1"/>
  </joint>
  <joint name="LH_rol5" type="continuous">
    <parent link="LH_WHEEL"/>
    <child link="LH_Roller5"/>
    <origin rpy="2.4007 0.28978 -2.8388" xyz="-0.04175 0.04345 0"/>
    <axis xyz="0 0 -1"/>
  </joint>
  <joint name="LH_rol6" type="continuous">
    <parent link="LH_WHEEL"/>
    <child link="LH_Roller6"/>
    <origin rpy="2.6783 0.87701 -2.6783" xyz="-0.03378 0.04345 -0.02454"/>
    <axis xyz="0 0 -1"/>
  </joint>
  <joint name="LH_rol7" type="continuous">
    <parent link="LH_WHEEL"/>
    <child link="LH_Roller7"/>
    <origin rpy="1.7956 0.19988 2.4267" xyz="-0.012901 0.04345 -0.039707"/>
    <axis xyz="0 0 -1"/>
  </joint>
  <joint name="LH_rol8" type="continuous">
    <parent link="LH_WHEEL"/>
    <child link="LH_Roller8"/>
    <origin rpy="-1.2129 0.8973 -0.47589" xyz="0.012901 0.04345 -0.039707"/>
    <axis xyz="0 0 -1"/>
  </joint>
  <joint name="LH_rol9" type="continuous">
    <parent link="LH_WHEEL"/>
    <child link="LH_Roller9"/>
    <origin rpy="-0.92607 0.31149 -0.30489" xyz="0.03378 0.04345 -0.02454"/>
    <axis xyz="0 0 -1"/>
  </joint>
  <joint name="LH_rol10" type="continuous">
    <parent link="LH_WHEEL"/>
    <child link="LH_Roller10"/>
    <origin rpy="-0.74088 -0.28978 -0.30278" xyz="0.04175 0.04345 0"/>
    <axis xyz="0 0 -1"/>
  </joint>
  <!-- Joint to fix the leg to the base -->
  <joint name="LF_HAA" type="fixed">
    <parent link="base_link"/>
    <child link="LF_SHOULDER"/>
    <origin rpy="0 0 0" xyz="0.045 0.081 0"/>
  </joint>
  <!-- Shoulder link -->
  <link name="LF_SHOULDER">
    <visual>
      <material name="white"/>
      <origin rpy="0 0 0" xyz="0 0 0"/>
      <geometry>
        <mesh filename="file:///home/francesco/Documents/mulinex_ws/install/mulinex_omni_description/share/mulinex_omni_description/meshes//Module_left_front.stl"/>
      </geometry>
    </visual>
    <collision>
      <origin rpy="0 0 0" xyz="0.0945 0 0"/>
      <geometry>
        <!-- <mesh filename="${mulinex_module_left_front}" /> -->
        <box size="0.269 0.057 0.060"/>
      </geometry>
    </collision>
    <inertial>
      <mass value="0.47669673"/>
      <origin rpy="0 0 0" xyz="7.2487360e-02 3.1582591e-02 -2.4812434e-03"/>
      <inertia ixx="2.1574269e-04" ixy="-3.3437484e-05" ixz="-2.4284668e-06" iyy="3.0607390e-03" iyz="-2.0388977e-06" izz="3.0504273e-03"/>
    </inertial>
  </link>
  <gazebo reference="LF_SHOULDER">
    <material>Gazebo/White</material>
    <collision>
      <surface>
        <friction>
          <ode>
            <mu>1</mu>
            <mu2>1</mu2>
            <slip1>0</slip1>
            <slip2>0</slip2>
          </ode>
        </friction>
        <contact>
          <ode>
            <kp>1000000.0</kp>
            <kd>100.0</kd>
            <min_depth>0.001</min_depth>
          </ode>
        </contact>
      </surface>
    </collision>
  </gazebo>
  <!-- Hip joint -->
  <joint name="LF_HFE" type="revolute">
    <parent link="LF_SHOULDER"/>
    <child link="LF_UPPER_LEG"/>
    <origin rpy="0 0 0" xyz="0.19 0.044 0"/>
    <axis xyz="0 1 0"/>
    <limit effort="2.7" lower="-3.141592" upper="3.141592" velocity="1000"/>
    <!-- <dynamics damping="0.7" friction="100.0" /> -->
  </joint>
  <!-- Upper leg link -->
  <link name="LF_UPPER_LEG">
    <visual>
      <material name="white"/>
      <origin rpy="0 0 0" xyz="0 0 0"/>
      <geometry>
        <mesh filename="file:///home/francesco/Documents/mulinex_ws/install/mulinex_omni_description/share/mulinex_omni_description/meshes//Module_left_front.stl"/>
      </geometry>
    </visual>
    <collision>
      <origin rpy="0 0 0" xyz="0.0945 0.015 0"/>
      <geometry>
        <!-- <mesh filename="${mulinex_module_left_front}" /> -->
        <box size="0.269 0.057 0.060"/>
      </geometry>
    </collision>
    <inertial>
      <mass value="0.47669673"/>
      <origin rpy="0 0 0" xyz="7.2487360e-02 3.1582591e-02 -2.4812434e-03"/>
      <inertia ixx="2.1574269e-04" ixy="-3.3437484e-05" ixz="-2.4284668e-06" iyy="3.0607390e-03" iyz="-2.0388977e-06" izz="3.0504273e-03"/>
    </inertial>
  </link>
  <gazebo reference="LF_UPPER_LEG">
    <material>Gazebo/White</material>
    <collision>
      <surface>
        <friction>
          <ode>
            <mu>1</mu>
            <mu2>1</mu2>
            <slip1>0</slip1>
            <slip2>0</slip2>
          </ode>
        </friction>
        <contact>
          <ode>
            <kp>1000000.0</kp>
            <kd>100.0</kd>
            <min_depth>0.001</min_depth>
          </ode>
        </contact>
      </surface>
    </collision>
  </gazebo>
  <!-- Knee joint -->
  <joint name="LF_KFE" type="revolute">
    <parent link="LF_UPPER_LEG"/>
    <child link="LF_LOWER_LEG"/>
    <origin rpy="0 0 0" xyz="0.19 0.044 0"/>
    <axis xyz="0 1 0"/>
    <limit effort="2.7" lower="-3.141592" upper="3.141592" velocity="1000"/>
    <!-- <dynamics damping="0.7" friction="100.0" /> -->
  </joint>
  <!-- Lower leg link -->
  <link name="LF_LOWER_LEG">
    <visual>
      <material name="white"/>
      <origin rpy="0 -1.570796 0" xyz="0 0 0"/>
      <geometry>
        <mesh filename="file:///home/francesco/Documents/mulinex_ws/install/mulinex_omni_description/share/mulinex_omni_description/meshes//Lower_leg_left.stl"/>
      </geometry>
    </visual>
    <collision name="LF_LOWER_LEG">
      <origin rpy="0 -1.570796 0" xyz="0.096 0.012 0.0"/>
      <geometry>
        <box size="0.032 0.024 0.192"/>
      </geometry>
    </collision>
    <inertial>
      <mass value="0.30551"/>
      <origin rpy="0 0 0" xyz="0.17801 0.030272 1.8448E-05"/>
      <inertia ixx="6.1505E-05" ixy="-1.5369E-05" ixz="-4.7734E-08" iyy="0.00054256" iyz="-1.9337E-08" izz="0.00051876"/>
    </inertial>
  </link>
  <gazebo reference="LF_LOWER_LEG">
    <material>Gazebo/White</material>
    <collision>
      <surface>
        <friction>
          <ode>
            <mu>0.6</mu>
            <mu2>0.6</mu2>
            <slip1>0</slip1>
            <slip2>0</slip2>
          </ode>
        </friction>
        <contact>
          <ode>
            <kp>10000.0</kp>
            <kd>100.0</kd>
            <min_depth>0.001</min_depth>
          </ode>
        </contact>
      </surface>
    </collision>
  </gazebo>
  <joint name="LF_ANKLE" type="continuous">
    <parent link="LF_LOWER_LEG"/>
    <child link="LF_WHEEL"/>
    <origin rpy="0 0 0" xyz="0.19 0.01145 0"/>
    <axis xyz="0 1 0"/>
  </joint>
  <link name="LF_WHEEL">
    <visual>
      <material name="white"/>
      <origin rpy="0 0 0" xyz="0 0 0"/>
      <geometry>
        <mesh filename="file:///home/francesco/Documents/mulinex_ws/install/mulinex_omni_description/share/mulinex_omni_description/meshes//mecanum_wheel_lf.STL"/>
      </geometry>
    </visual>
    <collision>
      <origin rpy="0 0 0" xyz="0 0 0"/>
      <geometry>
        <mesh filename="file:///home/francesco/Documents/mulinex_ws/install/mulinex_omni_description/share/mulinex_omni_description/meshes//mecanum_wheel_lf.STL"/>
      </geometry>
    </collision>
    <inertial>
      <origin rpy="0 0 0" xyz="0 0.047255 -2.335E-07"/>
      <mass value="0.078919"/>
      <inertia ixx="4.9627E-05" ixy="1.7873E-11" ixz="-2.2576E-09" iyy="7.8948E-05" iyz="-7.6317E-12" izz="4.9622E-05"/>
    </inertial>
  </link>
  <gazebo reference="LF_WHEEL">
    <material>Gazebo/White</material>
    <collision>
      <surface>
        <friction>
          <ode>
            <mu>0.6</mu>
            <mu2>0.6</mu2>
            <slip1>0</slip1>
            <slip2>0</slip2>
          </ode>
        </friction>
        <contact>
          <ode>
            <kp>10000.0</kp>
            <kd>100.0</kd>
            <min_depth>0.001</min_depth>
          </ode>
        </contact>
      </surface>
    </collision>
  </gazebo>
  <!-- <joint name="${prefix}_DIRECTION" type="fixed">
                <parent link="${prefix}_WHEEL" />
                <child link="${prefix}_INDICATOR" />
                <xacro:if value="${prefix == 'LF'}">
                    <origin xyz="0 0.0501 0" rpy="0 0 0" />
                </xacro:if>
                <xacro:if value="${prefix == 'LH'}">
                    <origin xyz="0 0.0501 0" rpy="0 0 0" />
                </xacro:if>
                <xacro:if value="${prefix == 'RF'}">
                    <origin xyz="0 -0.0501 0" rpy="0 0 0" />
                </xacro:if>
                <xacro:if value="${prefix == 'RH'}">
                    <origin xyz="0 -0.0501 0" rpy="0 0 0" />
                </xacro:if>
            </joint> -->
  <!-- <link name="${prefix}_INDICATOR">
                <visual>
                    <origin xyz="0 0 0.0075" rpy="0 0 0" />
                    <geometry>
                        <box size="0.004 0.0001 0.015" />
                    </geometry>
                    <material name="red" />
                </visual>
            </link> -->
  <link name="LF_Roller1">
    <inertial>
      <origin rpy="0 0 0" xyz="0 0 6.3075E-15"/>
      <mass value="0.0059616"/>
      <inertia ixx="7.911E-07" ixy="1.2914E-12" ixz="1.2242E-22" iyy="7.9113E-07" iyz="-5.294E-23" izz="2.3532E-07"/>
    </inertial>
    <visual>
      <origin rpy="0 0 0" xyz="0 0 0"/>
      <geometry>
        <mesh filename="file:///home/francesco/Documents/mulinex_ws/install/mulinex_omni_description/share/mulinex_omni_description/meshes//roller_1.STL"/>
      </geometry>
      <material name="white"/>
    </visual>
    <collision>
      <origin rpy="0 0 0" xyz="0 0 0"/>
      <geometry>
        <mesh filename="file:///home/francesco/Documents/mulinex_ws/install/mulinex_omni_description/share/mulinex_omni_description/meshes//roller_1.STL"/>
      </geometry>
    </collision>
  </link>
  <gazebo reference="LF_Roller1">
    <material>Gazebo/White</material>
    <collision>
      <surface>
        <friction>
          <ode>
            <mu>0.6</mu>
            <mu2>0.6</mu2>
            <slip1>0</slip1>
            <slip2>0</slip2>
          </ode>
        </friction>
        <contact>
          <ode>
            <kp>10000.0</kp>
            <kd>100.0</kd>
            <min_depth>0.001</min_depth>
          </ode>
        </contact>
      </surface>
    </collision>
    <sensor name="LF_contactsensor_sensor" type="contact">
      <always_on>true</always_on>
      <update_rate>50</update_rate>
      <contact>
        <collision>
                            LF_LOWER_LEG_fixed_joint_lump__LF_FOOT_collision_1</collision>
      </contact>
    </sensor>
  </gazebo>
  <link name="LF_Roller2">
    <inertial>
      <origin rpy="0 0 0" xyz="0 0 6.3075E-15"/>
      <mass value="0.0059616"/>
      <inertia ixx="7.911E-07" ixy="1.2914E-12" ixz="-2.0183E-22" iyy="7.9113E-07" iyz="2.8455E-22" izz="2.3532E-07"/>
    </inertial>
    <visual>
      <origin rpy="0 0 0" xyz="0 0 0"/>
      <geometry>
        <mesh filename="file:///home/francesco/Documents/mulinex_ws/install/mulinex_omni_description/share/mulinex_omni_description/meshes//roller_1.STL"/>
      </geometry>
      <material name="white"/>
    </visual>
    <collision>
      <origin rpy="0 0 0" xyz="0 0 0"/>
      <geometry>
        <mesh filename="file:///home/francesco/Documents/mulinex_ws/install/mulinex_omni_description/share/mulinex_omni_description/meshes//roller_1.STL"/>
      </geometry>
    </collision>
  </link>
  <gazebo reference="LF_Rollert2">
    <material>Gazebo/White</material>
    <collision>
      <surface>
        <friction>
          <ode>
            <mu>0.6</mu>
            <mu2>0.6</mu2>
            <slip1>0</slip1>
            <slip2>0</slip2>
          </ode>
        </friction>
        <contact>
          <ode>
            <kp>10000.0</kp>
            <kd>100.0</kd>
            <min_depth>0.001</min_depth>
          </ode>
        </contact>
      </surface>
    </collision>
    <sensor name="LF_contactsensor_sensor" type="contact">
      <always_on>true</always_on>
      <update_rate>50</update_rate>
      <contact>
        <collision>
                            LF_LOWER_LEG_fixed_joint_lump__LF_FOOT_collision_1</collision>
      </contact>
    </sensor>
  </gazebo>
  <link name="LF_Roller3">
    <inertial>
      <origin rpy="0 0 0" xyz="0 0 6.3075E-15"/>
      <mass value="0.0059616"/>
      <inertia ixx="7.911E-07" ixy="1.2914E-12" ixz="-2.9448E-22" iyy="7.9113E-07" iyz="-3.3749E-22" izz="2.3532E-07"/>
    </inertial>
    <visual>
      <origin rpy="0 0 0" xyz="0 0 0"/>
      <geometry>
        <mesh filename="file:///home/francesco/Documents/mulinex_ws/install/mulinex_omni_description/share/mulinex_omni_description/meshes//roller_1.STL"/>
      </geometry>
      <material name="white"/>
    </visual>
    <collision>
      <origin rpy="0 0 0" xyz="0 0 0"/>
      <geometry>
        <mesh filename="file:///home/francesco/Documents/mulinex_ws/install/mulinex_omni_description/share/mulinex_omni_description/meshes//roller_1.STL"/>
      </geometry>
    </collision>
  </link>
  <gazebo reference="LF_Roller3">
    <material>Gazebo/White</material>
    <collision>
      <surface>
        <friction>
          <ode>
            <mu>0.6</mu>
            <mu2>0.6</mu2>
            <slip1>0</slip1>
            <slip2>0</slip2>
          </ode>
        </friction>
        <contact>
          <ode>
            <kp>10000.0</kp>
            <kd>100.0</kd>
            <min_depth>0.001</min_depth>
          </ode>
        </contact>
      </surface>
    </collision>
    <sensor name="LF_contactsensor_sensor" type="contact">
      <always_on>true</always_on>
      <update_rate>50</update_rate>
      <contact>
        <collision>
                            LF_LOWER_LEG_fixed_joint_lump__LF_FOOT_collision_1</collision>
      </contact>
    </sensor>
  </gazebo>
  <link name="LF_Roller4">
    <inertial>
      <origin rpy="0 0 0" xyz="0 0 6.3075E-15"/>
      <mass value="0.0059616"/>
      <inertia ixx="7.911E-07" ixy="1.2914E-12" ixz="1.0588E-22" iyy="7.9113E-07" iyz="3.7058E-22" izz="2.3532E-07"/>
    </inertial>
    <visual>
      <origin rpy="0 0 0" xyz="0 0 0"/>
      <geometry>
        <mesh filename="file:///home/francesco/Documents/mulinex_ws/install/mulinex_omni_description/share/mulinex_omni_description/meshes//roller_1.STL"/>
      </geometry>
      <material name="white"/>
    </visual>
    <collision>
      <origin rpy="0 0 0" xyz="0 0 0"/>
      <geometry>
        <mesh filename="file:///home/francesco/Documents/mulinex_ws/install/mulinex_omni_description/share/mulinex_omni_description/meshes//roller_1.STL"/>
      </geometry>
    </collision>
  </link>
  <gazebo reference="LF_Roller4">
    <material>Gazebo/White</material>
    <collision>
      <surface>
        <friction>
          <ode>
            <mu>0.6</mu>
            <mu2>0.6</mu2>
            <slip1>0</slip1>
            <slip2>0</slip2>
          </ode>
        </friction>
        <contact>
          <ode>
            <kp>10000.0</kp>
            <kd>100.0</kd>
            <min_depth>0.001</min_depth>
          </ode>
        </contact>
      </surface>
    </collision>
    <sensor name="LF_contactsensor_sensor" type="contact">
      <always_on>true</always_on>
      <update_rate>50</update_rate>
      <contact>
        <collision>
                              LF_LOWER_LEG_fixed_joint_lump__LF_FOOT_collision_1</collision>
      </contact>
    </sensor>
  </gazebo>
  <link name="LF_Roller5">
    <inertial>
      <origin rpy="0 0 0" xyz="0 0 6.3075E-15"/>
      <mass value="0.0059616"/>
      <inertia ixx="7.911E-07" ixy="1.2914E-12" ixz="-1.2242E-22" iyy="7.9113E-07" iyz="-1.3235E-22" izz="2.3532E-07"/>
    </inertial>
    <visual>
      <origin rpy="0 0 0" xyz="0 0 0"/>
      <geometry>
        <mesh filename="file:///home/francesco/Documents/mulinex_ws/install/mulinex_omni_description/share/mulinex_omni_description/meshes//roller_1.STL"/>
      </geometry>
      <material name="white"/>
    </visual>
    <collision>
      <origin rpy="0 0 0" xyz="0 0 0"/>
      <geometry>
        <mesh filename="file:///home/francesco/Documents/mulinex_ws/install/mulinex_omni_description/share/mulinex_omni_description/meshes//roller_1.STL"/>
      </geometry>
    </collision>
  </link>
  <gazebo reference="LF_Roller5">
    <material>Gazebo/White</material>
    <collision>
      <surface>
        <friction>
          <ode>
            <mu>0.6</mu>
            <mu2>0.6</mu2>
            <slip1>0</slip1>
            <slip2>0</slip2>
          </ode>
        </friction>
        <contact>
          <ode>
            <kp>10000.0</kp>
            <kd>100.0</kd>
            <min_depth>0.001</min_depth>
          </ode>
        </contact>
      </surface>
    </collision>
    <sensor name="LF_contactsensor_sensor" type="contact">
      <always_on>true</always_on>
      <update_rate>50</update_rate>
      <contact>
        <collision>
                            LF_LOWER_LEG_fixed_joint_lump__LF_FOOT_collision_1</collision>
      </contact>
    </sensor>
  </gazebo>
  <link name="LF_Roller6">
    <inertial>
      <origin rpy="0 0 0" xyz="0 0 6.3075E-15"/>
      <mass value="0.0059616"/>
      <inertia ixx="7.911E-07" ixy="1.2914E-12" ixz="1.1911E-22" iyy="7.9113E-07" iyz="1.2573E-22" izz="2.3532E-07"/>
    </inertial>
    <visual>
      <origin rpy="0 0 0" xyz="0 0 0"/>
      <geometry>
        <mesh filename="file:///home/francesco/Documents/mulinex_ws/install/mulinex_omni_description/share/mulinex_omni_description/meshes//roller_1.STL"/>
      </geometry>
      <material name="white"/>
    </visual>
    <collision>
      <origin rpy="0 0 0" xyz="0 0 0"/>
      <geometry>
        <mesh filename="file:///home/francesco/Documents/mulinex_ws/install/mulinex_omni_description/share/mulinex_omni_description/meshes//roller_1.STL"/>
      </geometry>
    </collision>
  </link>
  <gazebo reference="LF_Roller6">
    <material>Gazebo/White</material>
    <collision>
      <surface>
        <friction>
          <ode>
            <mu>0.6</mu>
            <mu2>0.6</mu2>
            <slip1>0</slip1>
            <slip2>0</slip2>
          </ode>
        </friction>
        <contact>
          <ode>
            <kp>10000.0</kp>
            <kd>100.0</kd>
            <min_depth>0.001</min_depth>
          </ode>
        </contact>
      </surface>
    </collision>
    <sensor name="LF_contactsensor_sensor" type="contact">
      <always_on>true</always_on>
      <update_rate>50</update_rate>
      <contact>
        <collision>
                            LF_LOWER_LEG_fixed_joint_lump__LF_FOOT_collision_1</collision>
      </contact>
    </sensor>
  </gazebo>
  <link name="LF_Roller7">
    <inertial>
      <origin rpy="0 0 0" xyz="0 0 6.3075E-15"/>
      <mass value="0.0059616"/>
      <inertia ixx="7.911E-07" ixy="1.2914E-12" ixz="5.9557E-23" iyy="7.9113E-07" iyz="7.9409E-23" izz="2.3532E-07"/>
    </inertial>
    <visual>
      <origin rpy="0 0 0" xyz="0 0 0"/>
      <geometry>
        <mesh filename="file:///home/francesco/Documents/mulinex_ws/install/mulinex_omni_description/share/mulinex_omni_description/meshes//roller_1.STL"/>
      </geometry>
      <material name="white"/>
    </visual>
    <collision>
      <origin rpy="0 0 0" xyz="0 0 0"/>
      <geometry>
        <mesh filename="file:///home/francesco/Documents/mulinex_ws/install/mulinex_omni_description/share/mulinex_omni_description/meshes//roller_1.STL"/>
      </geometry>
    </collision>
  </link>
  <gazebo reference="LF_Roller7">
    <material>Gazebo/White</material>
    <collision>
      <surface>
        <friction>
          <ode>
            <mu>0.6</mu>
            <mu2>0.6</mu2>
            <slip1>0</slip1>
            <slip2>0</slip2>
          </ode>
        </friction>
        <contact>
          <ode>
            <kp>10000.0</kp>
            <kd>100.0</kd>
            <min_depth>0.001</min_depth>
          </ode>
        </contact>
      </surface>
    </collision>
    <sensor name="LF_contactsensor_sensor" type="contact">
      <always_on>true</always_on>
      <update_rate>50</update_rate>
      <contact>
        <collision>
                            LF_LOWER_LEG_fixed_joint_lump__LF_FOOT_collision_1</collision>
      </contact>
    </sensor>
  </gazebo>
  <link name="LF_Roller8">
    <inertial>
      <origin rpy="0 0 0" xyz="0 0 6.3075E-15"/>
      <mass value="0.0059616"/>
      <inertia ixx="7.911E-07" ixy="1.2914E-12" ixz="-1.8529E-22" iyy="7.9113E-07" iyz="-3.1764E-22" izz="2.3532E-07"/>
    </inertial>
    <visual>
      <origin rpy="0 0 0" xyz="0 0 0"/>
      <geometry>
        <mesh filename="file:///home/francesco/Documents/mulinex_ws/install/mulinex_omni_description/share/mulinex_omni_description/meshes//roller_1.STL"/>
      </geometry>
      <material name="white"/>
    </visual>
    <collision>
      <origin rpy="0 0 0" xyz="0 0 0"/>
      <geometry>
        <mesh filename="file:///home/francesco/Documents/mulinex_ws/install/mulinex_omni_description/share/mulinex_omni_description/meshes//roller_1.STL"/>
      </geometry>
    </collision>
  </link>
  <gazebo reference="LF_Roller8">
    <material>Gazebo/White</material>
    <collision>
      <surface>
        <friction>
          <ode>
            <mu>0.6</mu>
            <mu2>0.6</mu2>
            <slip1>0</slip1>
            <slip2>0</slip2>
          </ode>
        </friction>
        <contact>
          <ode>
            <kp>10000.0</kp>
            <kd>100.0</kd>
            <min_depth>0.001</min_depth>
          </ode>
        </contact>
      </surface>
    </collision>
    <sensor name="LF_contactsensor_sensor" type="contact">
      <always_on>true</always_on>
      <update_rate>50</update_rate>
      <contact>
        <collision>
                            LF_LOWER_LEG_fixed_joint_lump__LF_FOOT_collision_1</collision>
      </contact>
    </sensor>
  </gazebo>
  <link name="LF_Roller9">
    <inertial>
      <origin rpy="0 0 0" xyz="0 0 6.3075E-15"/>
      <mass value="0.0059616"/>
      <inertia ixx="7.911E-07" ixy="1.2914E-12" ixz="1.3897E-22" iyy="7.9113E-07" iyz="-6.6174E-24" izz="2.3532E-07"/>
    </inertial>
    <visual>
      <origin rpy="0 0 0" xyz="0 0 0"/>
      <geometry>
        <mesh filename="file:///home/francesco/Documents/mulinex_ws/install/mulinex_omni_description/share/mulinex_omni_description/meshes//roller_1.STL"/>
      </geometry>
      <material name="white"/>
    </visual>
    <collision>
      <origin rpy="0 0 0" xyz="0 0 0"/>
      <geometry>
        <mesh filename="file:///home/francesco/Documents/mulinex_ws/install/mulinex_omni_description/share/mulinex_omni_description/meshes//roller_1.STL"/>
      </geometry>
    </collision>
  </link>
  <gazebo reference="LF_Roller9">
    <material>Gazebo/White</material>
    <collision>
      <surface>
        <friction>
          <ode>
            <mu>0.6</mu>
            <mu2>0.6</mu2>
            <slip1>0</slip1>
            <slip2>0</slip2>
          </ode>
        </friction>
        <contact>
          <ode>
            <kp>10000.0</kp>
            <kd>100.0</kd>
            <min_depth>0.001</min_depth>
          </ode>
        </contact>
      </surface>
    </collision>
    <sensor name="LF_contactsensor_sensor" type="contact">
      <always_on>true</always_on>
      <update_rate>50</update_rate>
      <contact>
        <collision>
                            LF_LOWER_LEG_fixed_joint_lump__LF_FOOT_collision_1</collision>
      </contact>
    </sensor>
  </gazebo>
  <link name="LF_Roller10">
    <inertial>
      <origin rpy="0 0 0" xyz="0 0 6.3075E-15"/>
      <mass value="0.0059616"/>
      <inertia ixx="7.911E-07" ixy="1.2914E-12" ixz="-1.6544E-22" iyy="7.9113E-07" iyz="-3.9705E-23" izz="2.3532E-07"/>
    </inertial>
    <visual>
      <origin rpy="0 0 0" xyz="0 0 0"/>
      <geometry>
        <mesh filename="file:///home/francesco/Documents/mulinex_ws/install/mulinex_omni_description/share/mulinex_omni_description/meshes//roller_1.STL"/>
      </geometry>
      <material name="white"/>
    </visual>
    <collision>
      <origin rpy="0 0 0" xyz="0 0 0"/>
      <geometry>
        <mesh filename="file:///home/francesco/Documents/mulinex_ws/install/mulinex_omni_description/share/mulinex_omni_description/meshes//roller_1.STL"/>
      </geometry>
    </collision>
  </link>
  <gazebo reference="LF_Roller9">
    <material>Gazebo/White</material>
    <collision>
      <surface>
        <friction>
          <ode>
            <mu>0.6</mu>
            <mu2>0.6</mu2>
            <slip1>0</slip1>
            <slip2>0</slip2>
          </ode>
        </friction>
        <contact>
          <ode>
            <kp>10000.0</kp>
            <kd>100.0</kd>
            <min_depth>0.001</min_depth>
          </ode>
        </contact>
      </surface>
    </collision>
    <sensor name="LF_contactsensor_sensor" type="contact">
      <always_on>true</always_on>
      <update_rate>50</update_rate>
      <contact>
        <collision>
                            LF_LOWER_LEG_fixed_joint_lump__LF_FOOT_collision_1</collision>
      </contact>
    </sensor>
  </gazebo>
  <!--           <joint
            name="${prefix}_rol1"
            type="continuous">
            <origin
              xyz="-0.026605 -0.015694 0.01516"
              rpy="${-PI/2} 0 0" />
            <parent
              link="${prefix}_WHEEL"/>
            <child
              link="${prefix}_Roller1" />
            <axis
              xyz="-0.37796 0.65465 -0.65465" />
          </joint> -->
  <joint name="LF_rol1" type="continuous">
    <parent link="LF_WHEEL"/>
    <child link="LF_Roller1"/>
    <axis xyz="0 0 -1"/>
    <origin rpy="-2.5315 0.60848 2.7559" xyz="-0.039707 0.04345 -0.012901"/>
  </joint>
  <joint name="LF_rol2" type="continuous">
    <parent link="LF_WHEEL"/>
    <child link="LF_Roller2"/>
    <axis xyz="0 0 -1"/>
    <origin rpy="-3.0918 1.1416 2.3058" xyz="-0.02454 0.04345 -0.033776"/>
  </joint>
  <joint name="LF_rol3" type="continuous">
    <parent link="LF_WHEEL"/>
    <child link="LF_Roller3"/>
    <origin rpy="1.5708 1.119 0.7854" xyz="0 0.04345 -0.04175"/>
    <axis xyz="0 0 -1"/>
  </joint>
  <joint name="LF_rol4" type="continuous">
    <parent link="LF_WHEEL"/>
    <child link="LF_Roller4"/>
    <origin rpy="1.0515 0.57804 0.3775" xyz="0.02454 0.04345 -0.033776"/>
    <axis xyz="0 0 -1"/>
  </joint>
  <joint name="LF_rol5" type="continuous">
    <parent link="LF_WHEEL"/>
    <child link="LF_Roller5"/>
    <origin rpy="0.83311 -0.015598 0.31388" xyz="0.039707 0.04345 -0.012901"/>
    <axis xyz="0 0 -1"/>
  </joint>
  <joint name="LF_rol6" type="continuous">
    <parent link="LF_WHEEL"/>
    <child link="LF_Roller6"/>
    <origin rpy="0.61008 -0.60848 0.38574" xyz="0.039707 0.04345 0.012901"/>
    <axis xyz="0 0 -1"/>
  </joint>
  <joint name="LF_rol7" type="continuous">
    <parent link="LF_WHEEL"/>
    <child link="LF_Roller7"/>
    <origin rpy="0.049792 -1.1416 0.83583" xyz="0.02454 0.04345 0.033776"/>
    <axis xyz="0 0 -1"/>
  </joint>
  <joint name="LF_rol8" type="continuous">
    <parent link="LF_WHEEL"/>
    <child link="LF_Roller8"/>
    <origin rpy="-1.5708 -1.119 2.3562" xyz="0 0.04345 0.04175"/>
    <axis xyz="0 0 -1"/>
  </joint>
  <joint name="LF_rol9" type="continuous">
    <parent link="LF_WHEEL"/>
    <child link="LF_Roller9"/>
    <origin rpy="-2.0901 -0.57804 2.7641" xyz="-0.02454 0.04345 0.033776"/>
    <axis xyz="0 0 -1"/>
  </joint>
  <joint name="LF_rol10" type="continuous">
    <parent link="LF_WHEEL"/>
    <child link="LF_Roller10"/>
    <origin rpy="-2.3085 0.015598 2.8277" xyz="-0.039707 0.04345 0.012901"/>
    <axis xyz="0 0 -1"/>
  </joint>
  <!-- Joint to fix the leg to the base -->
  <joint name="RF_HAA" type="fixed">
    <parent link="base_link"/>
    <child link="RF_SHOULDER"/>
    <origin rpy="0 0 0" xyz="0.045 -0.081 0"/>
  </joint>
  <!-- Shoulder link -->
  <link name="RF_SHOULDER">
    <visual>
      <material name="white"/>
      <origin rpy="0 0 0" xyz="0 0 0"/>
      <geometry>
        <mesh filename="file:///home/francesco/Documents/mulinex_ws/install/mulinex_omni_description/share/mulinex_omni_description/meshes//Module_right_front.stl"/>
      </geometry>
    </visual>
    <collision>
      <origin rpy="0 0 0" xyz="0.0945 0 0"/>
      <geometry>
        <!-- <mesh filename="${mulinex_module_right_front}" /> -->
        <box size="0.269 0.057 0.060"/>
      </geometry>
    </collision>
    <inertial>
      <mass value="0.47669673"/>
      <origin rpy="0 0 0" xyz="7.2487360e-02 -3.1582591e-02 2.4812434e-03"/>
      <inertia ixx="2.1574269e-04" ixy="3.3437484e-05" ixz="2.4284668e-06" iyy="3.0607390e-03" iyz="-2.0388977e-06" izz="3.0504273e-03"/>
    </inertial>
  </link>
  <gazebo reference="RF_SHOULDER">
    <material>Gazebo/White</material>
    <collision>
      <surface>
        <friction>
          <ode>
            <mu>1</mu>
            <mu2>1</mu2>
            <slip1>0</slip1>
            <slip2>0</slip2>
          </ode>
        </friction>
        <contact>
          <ode>
            <kp>1000000.0</kp>
            <kd>100.0</kd>
            <min_depth>0.001</min_depth>
          </ode>
        </contact>
      </surface>
    </collision>
  </gazebo>
  <!-- Hip joint -->
  <joint name="RF_HFE" type="revolute">
    <parent link="RF_SHOULDER"/>
    <child link="RF_UPPER_LEG"/>
    <origin rpy="0 0 0" xyz="0.19 -0.044 0"/>
    <axis xyz="0 -1 0"/>
    <limit effort="2.7" lower="-3.141592" upper="3.141592" velocity="1000"/>
    <!-- <dynamics damping="0.7" friction="100.0" /> -->
  </joint>
  <!-- Upper leg link -->
  <link name="RF_UPPER_LEG">
    <visual>
      <material name="white"/>
      <origin rpy="0 0 0" xyz="0 0 0"/>
      <geometry>
        <mesh filename="file:///home/francesco/Documents/mulinex_ws/install/mulinex_omni_description/share/mulinex_omni_description/meshes//Module_right_front.stl"/>
      </geometry>
    </visual>
    <collision>
      <origin rpy="0 0 0" xyz="0.0945 -0.015 0"/>
      <geometry>
        <!-- <mesh filename="${mulinex_module_right_front}" /> -->
        <box size="0.269 0.057 0.060"/>
      </geometry>
    </collision>
    <inertial>
      <mass value="0.47669673"/>
      <origin rpy="0 0 0" xyz="7.2487360e-02 -3.1582591e-02 2.4812434e-03"/>
      <inertia ixx="2.1574269e-04" ixy="3.3437484e-05" ixz="2.4284668e-06" iyy="3.0607390e-03" iyz="-2.0388977e-06" izz="3.0504273e-03"/>
    </inertial>
  </link>
  <gazebo reference="RF_UPPER_LEG">
    <material>Gazebo/White</material>
    <collision>
      <surface>
        <friction>
          <ode>
            <mu>1</mu>
            <mu2>1</mu2>
            <slip1>0</slip1>
            <slip2>0</slip2>
          </ode>
        </friction>
        <contact>
          <ode>
            <kp>1000000.0</kp>
            <kd>100.0</kd>
            <min_depth>0.001</min_depth>
          </ode>
        </contact>
      </surface>
    </collision>
  </gazebo>
  <!-- Knee joint -->
  <joint name="RF_KFE" type="revolute">
    <parent link="RF_UPPER_LEG"/>
    <child link="RF_LOWER_LEG"/>
    <origin rpy="0 0 0" xyz="0.19 -0.044 0"/>
    <axis xyz="0 -1 0"/>
    <limit effort="2.7" lower="-3.141592" upper="3.141592" velocity="1000"/>
    <!-- <dynamics damping="0.7" friction="100.0" /> -->
  </joint>
  <!-- Lower leg link -->
  <link name="RF_LOWER_LEG">
    <visual>
      <material name="white"/>
      <origin rpy="0 -1.570796 0" xyz="0 0 0"/>
      <geometry>
        <mesh filename="file:///home/francesco/Documents/mulinex_ws/install/mulinex_omni_description/share/mulinex_omni_description/meshes//Lower_leg_right.stl"/>
      </geometry>
    </visual>
    <collision name="RF_LOWER_LEG">
      <origin rpy="0 -1.570796 0" xyz="0.096 -0.012 0.0"/>
      <geometry>
        <box size="0.032 0.024 0.192"/>
      </geometry>
    </collision>
    <inertial>
      <mass value="0.30551"/>
      <origin rpy="0 0 0" xyz="0.17801 -0.030272 1.8448E-05"/>
      <inertia ixx="6.1505E-05" ixy="-1.5369E-05" ixz="-4.7734E-08" iyy="0.00054256" iyz="-1.9337E-08" izz="0.00051876"/>
    </inertial>
  </link>
  <gazebo reference="RF_LOWER_LEG">
    <material>Gazebo/White</material>
    <collision>
      <surface>
        <friction>
          <ode>
            <mu>0.6</mu>
            <mu2>0.6</mu2>
            <slip1>0</slip1>
            <slip2>0</slip2>
          </ode>
        </friction>
        <contact>
          <ode>
            <kp>10000.0</kp>
            <kd>100.0</kd>
            <min_depth>0.001</min_depth>
          </ode>
        </contact>
      </surface>
    </collision>
  </gazebo>
  <joint name="RF_ANKLE" type="continuous">
    <parent link="RF_LOWER_LEG"/>
    <child link="RF_WHEEL"/>
    <origin rpy="0 0 0" xyz="0.19 -0.01145 0"/>
    <axis xyz="0 1 0"/>
  </joint>
  <link name="RF_WHEEL">
    <visual>
      <material name="white"/>
      <origin rpy="0 0 0" xyz="0 0 0"/>
      <geometry>
        <mesh filename="file:///home/francesco/Documents/mulinex_ws/install/mulinex_omni_description/share/mulinex_omni_description/meshes//mecanum_wheel_rf.STL"/>
      </geometry>
    </visual>
    <collision>
      <origin rpy="0 0 0" xyz="0 0 0"/>
      <geometry>
        <mesh filename="file:///home/francesco/Documents/mulinex_ws/install/mulinex_omni_description/share/mulinex_omni_description/meshes//mecanum_wheel_rf.STL"/>
      </geometry>
    </collision>
    <inertial>
      <origin rpy="0 0 0" xyz="0 -0.047255 -1.5525E-07"/>
      <mass value="0.078525"/>
      <inertia ixx="4.9627E-05" ixy="-2.1009E-12" ixz="1.8882E-09" iyy="7.8948E-05" iyz="-4.4431E-12" izz="4.9622E-05"/>
    </inertial>
  </link>
  <gazebo reference="RF_WHEEL">
    <material>Gazebo/White</material>
    <collision>
      <surface>
        <friction>
          <ode>
            <mu>0.6</mu>
            <mu2>0.6</mu2>
            <slip1>0</slip1>
            <slip2>0</slip2>
          </ode>
        </friction>
        <contact>
          <ode>
            <kp>10000.0</kp>
            <kd>100.0</kd>
            <min_depth>0.001</min_depth>
          </ode>
        </contact>
      </surface>
    </collision>
  </gazebo>
  <!-- <joint name="${prefix}_DIRECTION" type="fixed">
                <parent link="${prefix}_WHEEL" />
                <child link="${prefix}_INDICATOR" />
                <xacro:if value="${prefix == 'LF'}">
                    <origin xyz="0 0.0501 0" rpy="0 0 0" />
                </xacro:if>
                <xacro:if value="${prefix == 'LH'}">
                    <origin xyz="0 0.0501 0" rpy="0 0 0" />
                </xacro:if>
                <xacro:if value="${prefix == 'RF'}">
                    <origin xyz="0 -0.0501 0" rpy="0 0 0" />
                </xacro:if>
                <xacro:if value="${prefix == 'RH'}">
                    <origin xyz="0 -0.0501 0" rpy="0 0 0" />
                </xacro:if>
            </joint> -->
  <!-- <link name="${prefix}_INDICATOR">
                <visual>
                    <origin xyz="0 0 0.0075" rpy="0 0 0" />
                    <geometry>
                        <box size="0.004 0.0001 0.015" />
                    </geometry>
                    <material name="red" />
                </visual>
            </link> -->
  <link name="RF_Roller1">
    <inertial>
      <origin rpy="0 0 0" xyz="0 0 0"/>
      <mass value="0.0059616"/>
      <inertia ixx="7.911E-07" ixy="1.2914E-12" ixz="2.5808E-22" iyy="7.9113E-07" iyz="-5.4263E-22" izz="2.3532E-07"/>
    </inertial>
    <visual>
      <origin rpy="0 0 0" xyz="0 0 0"/>
      <geometry>
        <mesh filename="file:///home/francesco/Documents/mulinex_ws/install/mulinex_omni_description/share/mulinex_omni_description/meshes//roller_1.STL"/>
      </geometry>
      <material name="white"/>
    </visual>
    <collision>
      <origin rpy="0 0 0" xyz="0 0 0"/>
      <geometry>
        <mesh filename="file:///home/francesco/Documents/mulinex_ws/install/mulinex_omni_description/share/mulinex_omni_description/meshes//roller_1.STL"/>
      </geometry>
    </collision>
  </link>
  <gazebo reference="RF_Roller1">
    <material>Gazebo/White</material>
    <collision>
      <surface>
        <friction>
          <ode>
            <mu>0.6</mu>
            <mu2>0.6</mu2>
            <slip1>0</slip1>
            <slip2>0</slip2>
          </ode>
        </friction>
        <contact>
          <ode>
            <kp>10000.0</kp>
            <kd>100.0</kd>
            <min_depth>0.001</min_depth>
          </ode>
        </contact>
      </surface>
    </collision>
    <sensor name="RF_contactsensor_sensor" type="contact">
      <always_on>true</always_on>
      <update_rate>50</update_rate>
      <contact>
        <collision>
                            RF_LOWER_LEG_fixed_joint_lump__RF_FOOT_collision_1</collision>
      </contact>
    </sensor>
  </gazebo>
  <link name="RF_Roller2">
    <inertial>
      <origin rpy="0 0 0" xyz="0 0 0"/>
      <mass value="0.0059616"/>
      <inertia ixx="7.911E-07" ixy="1.2914E-12" ixz="1.4228E-22" iyy="7.9113E-07" iyz="-1.3301E-21" izz="2.3532E-07"/>
    </inertial>
    <visual>
      <origin rpy="0 0 0" xyz="0 0 0"/>
      <geometry>
        <mesh filename="file:///home/francesco/Documents/mulinex_ws/install/mulinex_omni_description/share/mulinex_omni_description/meshes//roller_1.STL"/>
      </geometry>
      <material name="white"/>
    </visual>
    <collision>
      <origin rpy="0 0 0" xyz="0 0 0"/>
      <geometry>
        <mesh filename="file:///home/francesco/Documents/mulinex_ws/install/mulinex_omni_description/share/mulinex_omni_description/meshes//roller_1.STL"/>
      </geometry>
    </collision>
  </link>
  <gazebo reference="RF_Rollert2">
    <material>Gazebo/White</material>
    <collision>
      <surface>
        <friction>
          <ode>
            <mu>0.6</mu>
            <mu2>0.6</mu2>
            <slip1>0</slip1>
            <slip2>0</slip2>
          </ode>
        </friction>
        <contact>
          <ode>
            <kp>10000.0</kp>
            <kd>100.0</kd>
            <min_depth>0.001</min_depth>
          </ode>
        </contact>
      </surface>
    </collision>
    <sensor name="RF_contactsensor_sensor" type="contact">
      <always_on>true</always_on>
      <update_rate>50</update_rate>
      <contact>
        <collision>
                            RF_LOWER_LEG_fixed_joint_lump__RF_FOOT_collision_1</collision>
      </contact>
    </sensor>
  </gazebo>
  <link name="RF_Roller3">
    <inertial>
      <origin rpy="0 0 0" xyz="0 0 6.3075E-15"/>
      <mass value="0.0059616"/>
      <inertia ixx="7.911E-07" ixy="1.2914E-12" ixz="-7.6101E-23" iyy="7.9113E-07" iyz="2.1176E-22" izz="2.3532E-07"/>
    </inertial>
    <visual>
      <origin rpy="0 0 0" xyz="0 0 0"/>
      <geometry>
        <mesh filename="file:///home/francesco/Documents/mulinex_ws/install/mulinex_omni_description/share/mulinex_omni_description/meshes//roller_1.STL"/>
      </geometry>
      <material name="white"/>
    </visual>
    <collision>
      <origin rpy="0 0 0" xyz="0 0 0"/>
      <geometry>
        <mesh filename="file:///home/francesco/Documents/mulinex_ws/install/mulinex_omni_description/share/mulinex_omni_description/meshes//roller_1.STL"/>
      </geometry>
    </collision>
  </link>
  <gazebo reference="RF_Roller3">
    <material>Gazebo/White</material>
    <collision>
      <surface>
        <friction>
          <ode>
            <mu>0.6</mu>
            <mu2>0.6</mu2>
            <slip1>0</slip1>
            <slip2>0</slip2>
          </ode>
        </friction>
        <contact>
          <ode>
            <kp>10000.0</kp>
            <kd>100.0</kd>
            <min_depth>0.001</min_depth>
          </ode>
        </contact>
      </surface>
    </collision>
    <sensor name="RF_contactsensor_sensor" type="contact">
      <always_on>true</always_on>
      <update_rate>50</update_rate>
      <contact>
        <collision>
                            RF_LOWER_LEG_fixed_joint_lump__RF_FOOT_collision_1</collision>
      </contact>
    </sensor>
  </gazebo>
  <link name="RF_Roller4">
    <inertial>
      <origin rpy="0 0 0" xyz="0 0 6.3075E-15"/>
      <mass value="0.0059616"/>
      <inertia ixx="7.911E-07" ixy="1.2914E-12" ixz="2.4485E-22" iyy="7.9113E-07" iyz="5.0293E-22" izz="2.3532E-07"/>
    </inertial>
    <visual>
      <origin rpy="0 0 0" xyz="0 0 0"/>
      <geometry>
        <mesh filename="file:///home/francesco/Documents/mulinex_ws/install/mulinex_omni_description/share/mulinex_omni_description/meshes//roller_1.STL"/>
      </geometry>
      <material name="white"/>
    </visual>
    <collision>
      <origin rpy="0 0 0" xyz="0 0 0"/>
      <geometry>
        <mesh filename="file:///home/francesco/Documents/mulinex_ws/install/mulinex_omni_description/share/mulinex_omni_description/meshes//roller_1.STL"/>
      </geometry>
    </collision>
  </link>
  <gazebo reference="RF_Roller4">
    <material>Gazebo/White</material>
    <collision>
      <surface>
        <friction>
          <ode>
            <mu>0.6</mu>
            <mu2>0.6</mu2>
            <slip1>0</slip1>
            <slip2>0</slip2>
          </ode>
        </friction>
        <contact>
          <ode>
            <kp>10000.0</kp>
            <kd>100.0</kd>
            <min_depth>0.001</min_depth>
          </ode>
        </contact>
      </surface>
    </collision>
    <sensor name="RF_contactsensor_sensor" type="contact">
      <always_on>true</always_on>
      <update_rate>50</update_rate>
      <contact>
        <collision>
                              RF_LOWER_LEG_fixed_joint_lump__RF_FOOT_collision_1</collision>
      </contact>
    </sensor>
  </gazebo>
  <link name="RF_Roller5">
    <inertial>
      <origin rpy="0 0 0" xyz="0 0 6.3075E-15"/>
      <mass value="0.0059616"/>
      <inertia ixx="7.911E-07" ixy="1.2914E-12" ixz="-8.2718E-23" iyy="7.9113E-07" iyz="3.1764E-22" izz="2.3532E-07"/>
    </inertial>
    <visual>
      <origin rpy="0 0 0" xyz="0 0 0"/>
      <geometry>
        <mesh filename="file:///home/francesco/Documents/mulinex_ws/install/mulinex_omni_description/share/mulinex_omni_description/meshes//roller_1.STL"/>
      </geometry>
      <material name="white"/>
    </visual>
    <collision>
      <origin rpy="0 0 0" xyz="0 0 0"/>
      <geometry>
        <mesh filename="file:///home/francesco/Documents/mulinex_ws/install/mulinex_omni_description/share/mulinex_omni_description/meshes//roller_1.STL"/>
      </geometry>
    </collision>
  </link>
  <gazebo reference="RF_Roller5">
    <material>Gazebo/White</material>
    <collision>
      <surface>
        <friction>
          <ode>
            <mu>0.6</mu>
            <mu2>0.6</mu2>
            <slip1>0</slip1>
            <slip2>0</slip2>
          </ode>
        </friction>
        <contact>
          <ode>
            <kp>10000.0</kp>
            <kd>100.0</kd>
            <min_depth>0.001</min_depth>
          </ode>
        </contact>
      </surface>
    </collision>
    <sensor name="RF_contactsensor_sensor" type="contact">
      <always_on>true</always_on>
      <update_rate>50</update_rate>
      <contact>
        <collision>
                            RF_LOWER_LEG_fixed_joint_lump__RF_FOOT_collision_1</collision>
      </contact>
    </sensor>
  </gazebo>
  <link name="RF_Roller6">
    <inertial>
      <origin rpy="0 0 0" xyz="0 0 6.3075E-15"/>
      <mass value="0.0059616"/>
      <inertia ixx="7.911E-07" ixy="1.2914E-12" ixz="3.6396E-23" iyy="7.9113E-07" iyz="0" izz="2.3532E-07"/>
    </inertial>
    <visual>
      <origin rpy="0 0 0" xyz="0 0 0"/>
      <geometry>
        <mesh filename="file:///home/francesco/Documents/mulinex_ws/install/mulinex_omni_description/share/mulinex_omni_description/meshes//roller_1.STL"/>
      </geometry>
      <material name="white"/>
    </visual>
    <collision>
      <origin rpy="0 0 0" xyz="0 0 0"/>
      <geometry>
        <mesh filename="file:///home/francesco/Documents/mulinex_ws/install/mulinex_omni_description/share/mulinex_omni_description/meshes//roller_1.STL"/>
      </geometry>
    </collision>
  </link>
  <gazebo reference="RF_Roller6">
    <material>Gazebo/White</material>
    <collision>
      <surface>
        <friction>
          <ode>
            <mu>0.6</mu>
            <mu2>0.6</mu2>
            <slip1>0</slip1>
            <slip2>0</slip2>
          </ode>
        </friction>
        <contact>
          <ode>
            <kp>10000.0</kp>
            <kd>100.0</kd>
            <min_depth>0.001</min_depth>
          </ode>
        </contact>
      </surface>
    </collision>
    <sensor name="RF_contactsensor_sensor" type="contact">
      <always_on>true</always_on>
      <update_rate>50</update_rate>
      <contact>
        <collision>
                            RF_LOWER_LEG_fixed_joint_lump__RF_FOOT_collision_1</collision>
      </contact>
    </sensor>
  </gazebo>
  <link name="RF_Roller7">
    <inertial>
      <origin rpy="0 0 0" xyz="0 0 6.3075E-15"/>
      <mass value="0.0059616"/>
      <inertia ixx="7.911E-07" ixy="1.2914E-12" ixz="2.283E-22" iyy="7.9113E-07" iyz="-8.2718E-22" izz="2.3532E-07"/>
    </inertial>
    <visual>
      <origin rpy="0 0 0" xyz="0 0 0"/>
      <geometry>
        <mesh filename="file:///home/francesco/Documents/mulinex_ws/install/mulinex_omni_description/share/mulinex_omni_description/meshes//roller_1.STL"/>
      </geometry>
      <material name="white"/>
    </visual>
    <collision>
      <origin rpy="0 0 0" xyz="0 0 0"/>
      <geometry>
        <mesh filename="file:///home/francesco/Documents/mulinex_ws/install/mulinex_omni_description/share/mulinex_omni_description/meshes//roller_1.STL"/>
      </geometry>
    </collision>
  </link>
  <gazebo reference="RF_Roller7">
    <material>Gazebo/White</material>
    <collision>
      <surface>
        <friction>
          <ode>
            <mu>0.6</mu>
            <mu2>0.6</mu2>
            <slip1>0</slip1>
            <slip2>0</slip2>
          </ode>
        </friction>
        <contact>
          <ode>
            <kp>10000.0</kp>
            <kd>100.0</kd>
            <min_depth>0.001</min_depth>
          </ode>
        </contact>
      </surface>
    </collision>
    <sensor name="RF_contactsensor_sensor" type="contact">
      <always_on>true</always_on>
      <update_rate>50</update_rate>
      <contact>
        <collision>
                            RF_LOWER_LEG_fixed_joint_lump__RF_FOOT_collision_1</collision>
      </contact>
    </sensor>
  </gazebo>
  <link name="RF_Roller8">
    <inertial>
      <origin rpy="0 0 0" xyz="0 0 6.3075E-15"/>
      <mass value="0.0059616"/>
      <inertia ixx="7.911E-07" ixy="1.2914E-12" ixz="4.3013E-23" iyy="7.9113E-07" iyz="-5.294E-22" izz="2.3532E-07"/>
    </inertial>
    <visual>
      <origin rpy="0 0 0" xyz="0 0 0"/>
      <geometry>
        <mesh filename="file:///home/francesco/Documents/mulinex_ws/install/mulinex_omni_description/share/mulinex_omni_description/meshes//roller_1.STL"/>
      </geometry>
      <material name="white"/>
    </visual>
    <collision>
      <origin rpy="0 0 0" xyz="0 0 0"/>
      <geometry>
        <mesh filename="file:///home/francesco/Documents/mulinex_ws/install/mulinex_omni_description/share/mulinex_omni_description/meshes//roller_1.STL"/>
      </geometry>
    </collision>
  </link>
  <gazebo reference="RF_Roller8">
    <material>Gazebo/White</material>
    <collision>
      <surface>
        <friction>
          <ode>
            <mu>0.6</mu>
            <mu2>0.6</mu2>
            <slip1>0</slip1>
            <slip2>0</slip2>
          </ode>
        </friction>
        <contact>
          <ode>
            <kp>10000.0</kp>
            <kd>100.0</kd>
            <min_depth>0.001</min_depth>
          </ode>
        </contact>
      </surface>
    </collision>
    <sensor name="RF_contactsensor_sensor" type="contact">
      <always_on>true</always_on>
      <update_rate>50</update_rate>
      <contact>
        <collision>
                            RF_LOWER_LEG_fixed_joint_lump__RF_FOOT_collision_1</collision>
      </contact>
    </sensor>
  </gazebo>
  <link name="RF_Roller9">
    <inertial>
      <origin rpy="0 0 0" xyz="0 0 6.3075E-15"/>
      <mass value="0.0059616"/>
      <inertia ixx="7.911E-07" ixy="1.2914E-12" ixz="1.7205E-22" iyy="7.9113E-07" iyz="7.2792E-23" izz="2.3532E-07"/>
    </inertial>
    <visual>
      <origin rpy="0 0 0" xyz="0 0 0"/>
      <geometry>
        <mesh filename="file:///home/francesco/Documents/mulinex_ws/install/mulinex_omni_description/share/mulinex_omni_description/meshes//roller_1.STL"/>
      </geometry>
      <material name="white"/>
    </visual>
    <collision>
      <origin rpy="0 0 0" xyz="0 0 0"/>
      <geometry>
        <mesh filename="file:///home/francesco/Documents/mulinex_ws/install/mulinex_omni_description/share/mulinex_omni_description/meshes//roller_1.STL"/>
      </geometry>
    </collision>
  </link>
  <gazebo reference="RF_Roller9">
    <material>Gazebo/White</material>
    <collision>
      <surface>
        <friction>
          <ode>
            <mu>0.6</mu>
            <mu2>0.6</mu2>
            <slip1>0</slip1>
            <slip2>0</slip2>
          </ode>
        </friction>
        <contact>
          <ode>
            <kp>10000.0</kp>
            <kd>100.0</kd>
            <min_depth>0.001</min_depth>
          </ode>
        </contact>
      </surface>
    </collision>
    <sensor name="RF_contactsensor_sensor" type="contact">
      <always_on>true</always_on>
      <update_rate>50</update_rate>
      <contact>
        <collision>
                            RF_LOWER_LEG_fixed_joint_lump__RF_FOOT_collision_1</collision>
      </contact>
    </sensor>
  </gazebo>
  <link name="RF_Roller10">
    <inertial>
      <origin rpy="0 0 0" xyz="0 0 6.3075E-15"/>
      <mass value="0.0059616"/>
      <inertia ixx="7.911E-07" ixy="1.2914E-12" ixz="-7.2792E-23" iyy="7.9113E-07" iyz="5.294E-23" izz="2.3532E-07"/>
    </inertial>
    <visual>
      <origin rpy="0 0 0" xyz="0 0 0"/>
      <geometry>
        <mesh filename="file:///home/francesco/Documents/mulinex_ws/install/mulinex_omni_description/share/mulinex_omni_description/meshes//roller_1.STL"/>
      </geometry>
      <material name="white"/>
    </visual>
    <collision>
      <origin rpy="0 0 0" xyz="0 0 0"/>
      <geometry>
        <mesh filename="file:///home/francesco/Documents/mulinex_ws/install/mulinex_omni_description/share/mulinex_omni_description/meshes//roller_1.STL"/>
      </geometry>
    </collision>
  </link>
  <gazebo reference="RF_Roller9">
    <material>Gazebo/White</material>
    <collision>
      <surface>
        <friction>
          <ode>
            <mu>0.6</mu>
            <mu2>0.6</mu2>
            <slip1>0</slip1>
            <slip2>0</slip2>
          </ode>
        </friction>
        <contact>
          <ode>
            <kp>10000.0</kp>
            <kd>100.0</kd>
            <min_depth>0.001</min_depth>
          </ode>
        </contact>
      </surface>
    </collision>
    <sensor name="RF_contactsensor_sensor" type="contact">
      <always_on>true</always_on>
      <update_rate>50</update_rate>
      <contact>
        <collision>
                            RF_LOWER_LEG_fixed_joint_lump__RF_FOOT_collision_1</collision>
      </contact>
    </sensor>
  </gazebo>
  <!--           <joint
            name="${prefix}_rol1"
            type="continuous">
            <origin
              xyz="-0.026605 -0.015694 0.01516"
              rpy="${-PI/2} 0 0" />
            <parent
              link="${prefix}_WHEEL"/>
            <child
              link="${prefix}_Roller1" />
            <axis
              xyz="-0.37796 0.65465 -0.65465" />
          </joint> -->
  <joint name="RF_rol1" type="continuous">
    <parent link="RF_WHEEL"/>
    <child link="RF_Roller1"/>
    <axis xyz="0 0 -1"/>
    <origin rpy="-0.463248165454369 -0.877005281485064 2.67834448813542" xyz="-0.033776 -0.04345 0.024540037909306"/>
  </joint>
  <joint name="RF_rol2" type="continuous">
    <parent link="RF_WHEEL"/>
    <child link="RF_Roller2"/>
    <axis xyz="0 0 -1 "/>
    <origin rpy="0.701089986692213 -1.28079549479079 1.60893080425537" xyz="-0.0129 -0.04345 0.0397066131814208"/>
  </joint>
  <joint name="RF_rol3" type="continuous">
    <parent link="RF_WHEEL"/>
    <child link="RF_Roller3"/>
    <origin rpy="1.92871673572211 -0.897296357859899 0.475886236073787" xyz="0.012901 -0.04345 0.039706613181424"/>
    <axis xyz="0 0 -1"/>
  </joint>
  <joint name="RF_rol4" type="continuous">
    <parent link="RF_WHEEL"/>
    <child link="RF_Roller4"/>
    <origin rpy="2.21552653989221 -0.311494977109638 0.304893303643105" xyz="0.03378 -0.04345 0.0245400379093143"/>
    <axis xyz="0 0 -1"/>
  </joint>
  <joint name="RF_rol5" type="continuous">
    <parent link="RF_WHEEL"/>
    <child link="RF_Roller5"/>
    <origin rpy="2.40070816117922 0.289783882998016 0.302782663929541" xyz="0.04175 -0.04345 0"/>
    <axis xyz="0 0 -1"/>
  </joint>
  <joint name="RF_rol6" type="continuous">
    <parent link="RF_WHEEL"/>
    <child link="RF_Roller6"/>
    <origin rpy="2.6783 0.87701 0.46325" xyz="0.03378 -0.04345 -0.02454"/>
    <axis xyz="0 0 -1"/>
  </joint>
  <joint name="RF_rol7" type="continuous">
    <parent link="RF_WHEEL"/>
    <child link="RF_Roller7"/>
    <origin rpy="-2.4405 1.2808 1.5327" xyz="0.012901 -0.04345 -0.039707"/>
    <axis xyz="0 0 -1"/>
  </joint>
  <joint name="RF_rol8" type="continuous">
    <parent link="RF_WHEEL"/>
    <child link="RF_Roller8"/>
    <origin rpy="-1.2129 0.8973 2.6657" xyz="-0.012901 -0.04345 -0.039707"/>
    <axis xyz="0 0 -1"/>
  </joint>
  <joint name="RF_rol9" type="continuous">
    <parent link="RF_WHEEL"/>
    <child link="RF_Roller9"/>
    <origin rpy="-0.92607 0.31149 2.8367" xyz="-0.03378 -0.04345 -0.02454"/>
    <axis xyz="0 0 -1"/>
  </joint>
  <joint name="RF_rol10" type="continuous">
    <parent link="RF_WHEEL"/>
    <child link="RF_Roller10"/>
    <origin rpy="-0.74088 -0.28978 2.8388" xyz="-0.04175 -0.04345 0"/>
    <axis xyz="0 0 -1"/>
  </joint>
  <!-- Joint to fix the leg to the base -->
  <joint name="RH_HAA" type="fixed">
    <parent link="base_link"/>
    <child link="RH_SHOULDER"/>
    <origin rpy="0 0 0" xyz="-0.045 -0.081 0"/>
  </joint>
  <!-- Shoulder link -->
  <link name="RH_SHOULDER">
    <visual>
      <material name="white"/>
      <origin rpy="0 0 0" xyz="0 0 0"/>
      <geometry>
        <mesh filename="file:///home/francesco/Documents/mulinex_ws/install/mulinex_omni_description/share/mulinex_omni_description/meshes//Module_right_hind.stl"/>
      </geometry>
    </visual>
    <collision>
      <origin rpy="0 0 0" xyz="-0.0945 0 0"/>
      <geometry>
        <!-- <mesh filename="${mulinex_module_right_hind}" /> -->
        <box size="0.269 0.057 0.060"/>
      </geometry>
    </collision>
    <inertial>
      <mass value="0.47669673"/>
      <origin rpy="0 0 0" xyz="-7.2487360e-02 -3.1582591e-02 -2.4812434e-03"/>
      <inertia ixx="2.1574269e-04" ixy="-3.3437484e-05" ixz="2.4284668e-06" iyy="3.0607390e-03" iyz="-2.0388977e-06" izz="3.0504273e-03"/>
    </inertial>
  </link>
  <gazebo reference="RH_SHOULDER">
    <material>Gazebo/White</material>
    <collision>
      <surface>
        <friction>
          <ode>
            <mu>1</mu>
            <mu2>1</mu2>
            <slip1>0</slip1>
            <slip2>0</slip2>
          </ode>
        </friction>
        <contact>
          <ode>
            <kp>1000000.0</kp>
            <kd>100.0</kd>
            <min_depth>0.001</min_depth>
          </ode>
        </contact>
      </surface>
    </collision>
  </gazebo>
  <!-- Hip joint -->
  <joint name="RH_HFE" type="revolute">
    <parent link="RH_SHOULDER"/>
    <child link="RH_UPPER_LEG"/>
    <origin rpy="0 0 0" xyz="-0.19 -0.044 0"/>
    <axis xyz="0 -1 0"/>
    <limit effort="2.7" lower="-3.141592" upper="3.141592" velocity="1000"/>
    <!-- <dynamics damping="0.7" friction="100.0" /> -->
  </joint>
  <!-- Upper leg link -->
  <link name="RH_UPPER_LEG">
    <visual>
      <material name="white"/>
      <origin rpy="0 0 0" xyz="0 0 0"/>
      <geometry>
        <mesh filename="file:///home/francesco/Documents/mulinex_ws/install/mulinex_omni_description/share/mulinex_omni_description/meshes//Module_right_hind.stl"/>
      </geometry>
    </visual>
    <collision>
      <origin rpy="0 0 0" xyz="-0.0945 -0.015 0"/>
      <geometry>
        <!-- <mesh filename="${mulinex_module_right_hind}" /> -->
        <box size="0.269 0.057 0.060"/>
      </geometry>
    </collision>
    <inertial>
      <mass value="0.47669673"/>
      <origin rpy="0 0 0" xyz="-7.2487360e-02 -3.1582591e-02 -2.4812434e-03"/>
      <inertia ixx="2.1574269e-04" ixy="-3.3437484e-05" ixz="2.4284668e-06" iyy="3.0607390e-03" iyz="-2.0388977e-06" izz="3.0504273e-03"/>
    </inertial>
  </link>
  <gazebo reference="RH_UPPER_LEG">
    <material>Gazebo/White</material>
    <collision>
      <surface>
        <friction>
          <ode>
            <mu>1</mu>
            <mu2>1</mu2>
            <slip1>0</slip1>
            <slip2>0</slip2>
          </ode>
        </friction>
        <contact>
          <ode>
            <kp>1000000.0</kp>
            <kd>100.0</kd>
            <min_depth>0.001</min_depth>
          </ode>
        </contact>
      </surface>
    </collision>
  </gazebo>
  <!-- Knee joint -->
  <joint name="RH_KFE" type="revolute">
    <parent link="RH_UPPER_LEG"/>
    <child link="RH_LOWER_LEG"/>
    <origin rpy="0 0 0" xyz="-0.19 -0.044 0"/>
    <axis xyz="0 -1 0"/>
    <limit effort="2.7" lower="-3.141592" upper="3.141592" velocity="1000"/>
    <!-- <dynamics damping="0.7" friction="100.0" /> -->
  </joint>
  <!-- Lower leg link -->
  <link name="RH_LOWER_LEG">
    <visual>
      <material name="white"/>
      <origin rpy="0 1.570796 0" xyz="0 0 0"/>
      <geometry>
        <mesh filename="file:///home/francesco/Documents/mulinex_ws/install/mulinex_omni_description/share/mulinex_omni_description/meshes//Lower_leg_right.stl"/>
      </geometry>
    </visual>
    <collision name="RH_LOWER_LEG">
      <origin rpy="0 1.570796 0" xyz="-0.096 -0.012 0.0"/>
      <geometry>
        <box size="0.032 0.024 0.192"/>
      </geometry>
    </collision>
    <inertial>
      <mass value="0.30551"/>
      <origin rpy="0 0 0" xyz="-0.17801 -0.030272 1.8448E-05"/>
      <inertia ixx="6.1505E-05" ixy="-1.5369E-05" ixz="4.7734E-08" iyy="0.00054256" iyz="1.9337E-08" izz="0.00051876"/>
    </inertial>
  </link>
  <gazebo reference="RH_LOWER_LEG">
    <material>Gazebo/White</material>
    <collision>
      <surface>
        <friction>
          <ode>
            <mu>0.6</mu>
            <mu2>0.6</mu2>
            <slip1>0</slip1>
            <slip2>0</slip2>
          </ode>
        </friction>
        <contact>
          <ode>
            <kp>10000.0</kp>
            <kd>100.0</kd>
            <min_depth>0.001</min_depth>
          </ode>
        </contact>
      </surface>
    </collision>
  </gazebo>
  <joint name="RH_ANKLE" type="continuous">
    <parent link="RH_LOWER_LEG"/>
    <child link="RH_WHEEL"/>
    <origin rpy="0 0 0" xyz="-0.19 -0.01145 0"/>
    <axis xyz="0 1 0"/>
  </joint>
  <link name="RH_WHEEL">
    <visual>
      <material name="white"/>
      <origin rpy="0 0 0" xyz="0 0 0"/>
      <geometry>
        <mesh filename="file:///home/francesco/Documents/mulinex_ws/install/mulinex_omni_description/share/mulinex_omni_description/meshes//mecanum_wheel_rh.STL"/>
      </geometry>
    </visual>
    <collision>
      <origin rpy="0 0 0" xyz="0 0 0"/>
      <geometry>
        <mesh filename="file:///home/francesco/Documents/mulinex_ws/install/mulinex_omni_description/share/mulinex_omni_description/meshes//mecanum_wheel_rh.STL"/>
      </geometry>
    </collision>
    <inertial>
      <origin rpy="0 0 0" xyz="0 -0.047255 -2.3351E-07"/>
      <mass value="0.078919"/>
      <inertia ixx="4.9627E-05" ixy="1.7873E-11" ixz="-2.2576E-09" iyy="7.8948E-05" iyz="-7.6317E-12" izz="4.9622E-05"/>
    </inertial>
  </link>
  <gazebo reference="RH_WHEEL">
    <material>Gazebo/White</material>
    <collision>
      <surface>
        <friction>
          <ode>
            <mu>0.6</mu>
            <mu2>0.6</mu2>
            <slip1>0</slip1>
            <slip2>0</slip2>
          </ode>
        </friction>
        <contact>
          <ode>
            <kp>10000.0</kp>
            <kd>100.0</kd>
            <min_depth>0.001</min_depth>
          </ode>
        </contact>
      </surface>
    </collision>
  </gazebo>
  <!-- <joint name="${prefix}_DIRECTION" type="fixed">
                <parent link="${prefix}_WHEEL" />
                <child link="${prefix}_INDICATOR" />
                <xacro:if value="${prefix == 'LF'}">
                    <origin xyz="0 0.0501 0" rpy="0 0 0" />
                </xacro:if>
                <xacro:if value="${prefix == 'LH'}">
                    <origin xyz="0 0.0501 0" rpy="0 0 0" />
                </xacro:if>
                <xacro:if value="${prefix == 'RF'}">
                    <origin xyz="0 -0.0501 0" rpy="0 0 0" />
                </xacro:if>
                <xacro:if value="${prefix == 'RH'}">
                    <origin xyz="0 -0.0501 0" rpy="0 0 0" />
                </xacro:if>
            </joint> -->
  <!-- <link name="${prefix}_INDICATOR">
                <visual>
                    <origin xyz="0 0 0.0075" rpy="0 0 0" />
                    <geometry>
                        <box size="0.004 0.0001 0.015" />
                    </geometry>
                    <material name="red" />
                </visual>
            </link> -->
  <link name="RH_Roller1">
    <inertial>
      <origin rpy="0 0 0" xyz="0 0 6.3075E-15"/>
      <mass value="0.0059616"/>
      <inertia ixx="7.911E-07" ixy="1.2914E-12" ixz="1.2242E-22" iyy="7.9113E-07" iyz="-5.294E-23" izz="2.3532E-07"/>
    </inertial>
    <visual>
      <origin rpy="0 0 0" xyz="0 0 0"/>
      <geometry>
        <mesh filename="file:///home/francesco/Documents/mulinex_ws/install/mulinex_omni_description/share/mulinex_omni_description/meshes//roller_1.STL"/>
      </geometry>
      <material name="white"/>
    </visual>
    <collision>
      <origin rpy="0 0 0" xyz="0 0 0"/>
      <geometry>
        <mesh filename="file:///home/francesco/Documents/mulinex_ws/install/mulinex_omni_description/share/mulinex_omni_description/meshes//roller_1.STL"/>
      </geometry>
    </collision>
  </link>
  <gazebo reference="RH_Roller1">
    <material>Gazebo/White</material>
    <collision>
      <surface>
        <friction>
          <ode>
            <mu>0.6</mu>
            <mu2>0.6</mu2>
            <slip1>0</slip1>
            <slip2>0</slip2>
          </ode>
        </friction>
        <contact>
          <ode>
            <kp>10000.0</kp>
            <kd>100.0</kd>
            <min_depth>0.001</min_depth>
          </ode>
        </contact>
      </surface>
    </collision>
    <sensor name="RH_contactsensor_sensor" type="contact">
      <always_on>true</always_on>
      <update_rate>50</update_rate>
      <contact>
        <collision>
                            RH_LOWER_LEG_fixed_joint_lump__RH_FOOT_collision_1</collision>
      </contact>
    </sensor>
  </gazebo>
  <link name="RH_Roller2">
    <inertial>
      <origin rpy="0 0 0" xyz="0 0 6.3075E-15"/>
      <mass value="0.0059616"/>
      <inertia ixx="7.911E-07" ixy="1.2914E-12" ixz="-1.7536E-22" iyy="7.9113E-07" iyz="2.2499E-22" izz="2.3532E-07"/>
    </inertial>
    <visual>
      <origin rpy="0 0 0" xyz="0 0 0"/>
      <geometry>
        <mesh filename="file:///home/francesco/Documents/mulinex_ws/install/mulinex_omni_description/share/mulinex_omni_description/meshes//roller_1.STL"/>
      </geometry>
      <material name="white"/>
    </visual>
    <collision>
      <origin rpy="0 0 0" xyz="0 0 0"/>
      <geometry>
        <mesh filename="file:///home/francesco/Documents/mulinex_ws/install/mulinex_omni_description/share/mulinex_omni_description/meshes//roller_1.STL"/>
      </geometry>
    </collision>
  </link>
  <gazebo reference="RH_Rollert2">
    <material>Gazebo/White</material>
    <collision>
      <surface>
        <friction>
          <ode>
            <mu>0.6</mu>
            <mu2>0.6</mu2>
            <slip1>0</slip1>
            <slip2>0</slip2>
          </ode>
        </friction>
        <contact>
          <ode>
            <kp>10000.0</kp>
            <kd>100.0</kd>
            <min_depth>0.001</min_depth>
          </ode>
        </contact>
      </surface>
    </collision>
    <sensor name="RH_contactsensor_sensor" type="contact">
      <always_on>true</always_on>
      <update_rate>50</update_rate>
      <contact>
        <collision>
                            RH_LOWER_LEG_fixed_joint_lump__RH_FOOT_collision_1</collision>
      </contact>
    </sensor>
  </gazebo>
  <link name="RH_Roller3">
    <inertial>
      <origin rpy="0 0 0" xyz="0 0 6.3075E-15"/>
      <mass value="0.0059616"/>
      <inertia ixx="7.911E-07" ixy="1.2914E-12" ixz="-2.9448E-22" iyy="7.9113E-07" iyz="-3.3749E-22" izz="2.3532E-07"/>
    </inertial>
    <visual>
      <origin rpy="0 0 0" xyz="0 0 0"/>
      <geometry>
        <mesh filename="file:///home/francesco/Documents/mulinex_ws/install/mulinex_omni_description/share/mulinex_omni_description/meshes//roller_1.STL"/>
      </geometry>
      <material name="white"/>
    </visual>
    <collision>
      <origin rpy="0 0 0" xyz="0 0 0"/>
      <geometry>
        <mesh filename="file:///home/francesco/Documents/mulinex_ws/install/mulinex_omni_description/share/mulinex_omni_description/meshes//roller_1.STL"/>
      </geometry>
    </collision>
  </link>
  <gazebo reference="RH_Roller3">
    <material>Gazebo/White</material>
    <collision>
      <surface>
        <friction>
          <ode>
            <mu>0.6</mu>
            <mu2>0.6</mu2>
            <slip1>0</slip1>
            <slip2>0</slip2>
          </ode>
        </friction>
        <contact>
          <ode>
            <kp>10000.0</kp>
            <kd>100.0</kd>
            <min_depth>0.001</min_depth>
          </ode>
        </contact>
      </surface>
    </collision>
    <sensor name="RH_contactsensor_sensor" type="contact">
      <always_on>true</always_on>
      <update_rate>50</update_rate>
      <contact>
        <collision>
                            RH_LOWER_LEG_fixed_joint_lump__RH_FOOT_collision_1</collision>
      </contact>
    </sensor>
  </gazebo>
  <link name="RH_Roller4">
    <inertial>
      <origin rpy="0 0 0" xyz="0 0 6.3075E-15"/>
      <mass value="0.0059616"/>
      <inertia ixx="7.911E-07" ixy="1.2914E-12" ixz="1.0588E-22" iyy="7.9113E-07" iyz="3.7058E-22" izz="2.3532E-07"/>
    </inertial>
    <visual>
      <origin rpy="0 0 0" xyz="0 0 0"/>
      <geometry>
        <mesh filename="file:///home/francesco/Documents/mulinex_ws/install/mulinex_omni_description/share/mulinex_omni_description/meshes//roller_1.STL"/>
      </geometry>
      <material name="white"/>
    </visual>
    <collision>
      <origin rpy="0 0 0" xyz="0 0 0"/>
      <geometry>
        <mesh filename="file:///home/francesco/Documents/mulinex_ws/install/mulinex_omni_description/share/mulinex_omni_description/meshes//roller_1.STL"/>
      </geometry>
    </collision>
  </link>
  <gazebo reference="RH_Roller4">
    <material>Gazebo/White</material>
    <collision>
      <surface>
        <friction>
          <ode>
            <mu>0.6</mu>
            <mu2>0.6</mu2>
            <slip1>0</slip1>
            <slip2>0</slip2>
          </ode>
        </friction>
        <contact>
          <ode>
            <kp>10000.0</kp>
            <kd>100.0</kd>
            <min_depth>0.001</min_depth>
          </ode>
        </contact>
      </surface>
    </collision>
    <sensor name="RH_contactsensor_sensor" type="contact">
      <always_on>true</always_on>
      <update_rate>50</update_rate>
      <contact>
        <collision>
                              RH_LOWER_LEG_fixed_joint_lump__RH_FOOT_collision_1</collision>
      </contact>
    </sensor>
  </gazebo>
  <link name="RH_Roller5">
    <inertial>
      <origin rpy="0 0 0" xyz="0 0 6.3075E-15"/>
      <mass value="0.0059616"/>
      <inertia ixx="7.911E-07" ixy="1.2914E-12" ixz="-1.2242E-22" iyy="7.9113E-07" iyz="-1.3235E-22" izz="2.3532E-07"/>
    </inertial>
    <visual>
      <origin rpy="0 0 0" xyz="0 0 0"/>
      <geometry>
        <mesh filename="file:///home/francesco/Documents/mulinex_ws/install/mulinex_omni_description/share/mulinex_omni_description/meshes//roller_1.STL"/>
      </geometry>
      <material name="white"/>
    </visual>
    <collision>
      <origin rpy="0 0 0" xyz="0 0 0"/>
      <geometry>
        <mesh filename="file:///home/francesco/Documents/mulinex_ws/install/mulinex_omni_description/share/mulinex_omni_description/meshes//roller_1.STL"/>
      </geometry>
    </collision>
  </link>
  <gazebo reference="RH_Roller5">
    <material>Gazebo/White</material>
    <collision>
      <surface>
        <friction>
          <ode>
            <mu>0.6</mu>
            <mu2>0.6</mu2>
            <slip1>0</slip1>
            <slip2>0</slip2>
          </ode>
        </friction>
        <contact>
          <ode>
            <kp>10000.0</kp>
            <kd>100.0</kd>
            <min_depth>0.001</min_depth>
          </ode>
        </contact>
      </surface>
    </collision>
    <sensor name="RH_contactsensor_sensor" type="contact">
      <always_on>true</always_on>
      <update_rate>50</update_rate>
      <contact>
        <collision>
                            RH_LOWER_LEG_fixed_joint_lump__RH_FOOT_collision_1</collision>
      </contact>
    </sensor>
  </gazebo>
  <link name="RH_Roller6">
    <inertial>
      <origin rpy="0 0 0" xyz="0 0 6.3075E-15"/>
      <mass value="0.0059616"/>
      <inertia ixx="7.911E-07" ixy="1.2914E-12" ixz="1.1911E-22" iyy="7.9113E-07" iyz="1.2573E-22" izz="2.3532E-07"/>
    </inertial>
    <visual>
      <origin rpy="0 0 0" xyz="0 0 0"/>
      <geometry>
        <mesh filename="file:///home/francesco/Documents/mulinex_ws/install/mulinex_omni_description/share/mulinex_omni_description/meshes//roller_1.STL"/>
      </geometry>
      <material name="white"/>
    </visual>
    <collision>
      <origin rpy="0 0 0" xyz="0 0 0"/>
      <geometry>
        <mesh filename="file:///home/francesco/Documents/mulinex_ws/install/mulinex_omni_description/share/mulinex_omni_description/meshes//roller_1.STL"/>
      </geometry>
    </collision>
  </link>
  <gazebo reference="RH_Roller6">
    <material>Gazebo/White</material>
    <collision>
      <surface>
        <friction>
          <ode>
            <mu>0.6</mu>
            <mu2>0.6</mu2>
            <slip1>0</slip1>
            <slip2>0</slip2>
          </ode>
        </friction>
        <contact>
          <ode>
            <kp>10000.0</kp>
            <kd>100.0</kd>
            <min_depth>0.001</min_depth>
          </ode>
        </contact>
      </surface>
    </collision>
    <sensor name="RH_contactsensor_sensor" type="contact">
      <always_on>true</always_on>
      <update_rate>50</update_rate>
      <contact>
        <collision>
                            RH_LOWER_LEG_fixed_joint_lump__RH_FOOT_collision_1</collision>
      </contact>
    </sensor>
  </gazebo>
  <link name="RH_Roller7">
    <inertial>
      <origin rpy="0 0 0" xyz="0 0 6.3075E-15"/>
      <mass value="0.0059616"/>
      <inertia ixx="7.911E-07" ixy="1.2914E-12" ixz="8.6027E-23" iyy="7.9113E-07" iyz="6.6174E-23" izz="2.3532E-07"/>
    </inertial>
    <visual>
      <origin rpy="0 0 0" xyz="0 0 0"/>
      <geometry>
        <mesh filename="file:///home/francesco/Documents/mulinex_ws/install/mulinex_omni_description/share/mulinex_omni_description/meshes//roller_1.STL"/>
      </geometry>
      <material name="white"/>
    </visual>
    <collision>
      <origin rpy="0 0 0" xyz="0 0 0"/>
      <geometry>
        <mesh filename="file:///home/francesco/Documents/mulinex_ws/install/mulinex_omni_description/share/mulinex_omni_description/meshes//roller_1.STL"/>
      </geometry>
    </collision>
  </link>
  <gazebo reference="RH_Roller7">
    <material>Gazebo/White</material>
    <collision>
      <surface>
        <friction>
          <ode>
            <mu>0.6</mu>
            <mu2>0.6</mu2>
            <slip1>0</slip1>
            <slip2>0</slip2>
          </ode>
        </friction>
        <contact>
          <ode>
            <kp>10000.0</kp>
            <kd>100.0</kd>
            <min_depth>0.001</min_depth>
          </ode>
        </contact>
      </surface>
    </collision>
    <sensor name="RH_contactsensor_sensor" type="contact">
      <always_on>true</always_on>
      <update_rate>50</update_rate>
      <contact>
        <collision>
                            RH_LOWER_LEG_fixed_joint_lump__RH_FOOT_collision_1</collision>
      </contact>
    </sensor>
  </gazebo>
  <link name="RH_Roller8">
    <inertial>
      <origin rpy="0 0 0" xyz="0 0 6.3075E-15"/>
      <mass value="0.0059616"/>
      <inertia ixx="7.911E-07" ixy="1.2914E-12" ixz="-1.9852E-22" iyy="7.9113E-07" iyz="-3.1764E-22" izz="2.3532E-07"/>
    </inertial>
    <visual>
      <origin rpy="0 0 0" xyz="0 0 0"/>
      <geometry>
        <mesh filename="file:///home/francesco/Documents/mulinex_ws/install/mulinex_omni_description/share/mulinex_omni_description/meshes//roller_1.STL"/>
      </geometry>
      <material name="white"/>
    </visual>
    <collision>
      <origin rpy="0 0 0" xyz="0 0 0"/>
      <geometry>
        <mesh filename="file:///home/francesco/Documents/mulinex_ws/install/mulinex_omni_description/share/mulinex_omni_description/meshes//roller_1.STL"/>
      </geometry>
    </collision>
  </link>
  <gazebo reference="RH_Roller8">
    <material>Gazebo/White</material>
    <collision>
      <surface>
        <friction>
          <ode>
            <mu>0.6</mu>
            <mu2>0.6</mu2>
            <slip1>0</slip1>
            <slip2>0</slip2>
          </ode>
        </friction>
        <contact>
          <ode>
            <kp>10000.0</kp>
            <kd>100.0</kd>
            <min_depth>0.001</min_depth>
          </ode>
        </contact>
      </surface>
    </collision>
    <sensor name="RH_contactsensor_sensor" type="contact">
      <always_on>true</always_on>
      <update_rate>50</update_rate>
      <contact>
        <collision>
                            RH_LOWER_LEG_fixed_joint_lump__RH_FOOT_collision_1</collision>
      </contact>
    </sensor>
  </gazebo>
  <link name="RH_Roller9">
    <inertial>
      <origin rpy="0 0 0" xyz="0 0 6.3075E-15"/>
      <mass value="0.0059616"/>
      <inertia ixx="7.911E-07" ixy="1.2914E-12" ixz="1.3897E-22" iyy="7.9113E-07" iyz="-6.6174E-24" izz="2.3532E-07"/>
    </inertial>
    <visual>
      <origin rpy="0 0 0" xyz="0 0 0"/>
      <geometry>
        <mesh filename="file:///home/francesco/Documents/mulinex_ws/install/mulinex_omni_description/share/mulinex_omni_description/meshes//roller_1.STL"/>
      </geometry>
      <material name="white"/>
    </visual>
    <collision>
      <origin rpy="0 0 0" xyz="0 0 0"/>
      <geometry>
        <mesh filename="file:///home/francesco/Documents/mulinex_ws/install/mulinex_omni_description/share/mulinex_omni_description/meshes//roller_1.STL"/>
      </geometry>
    </collision>
  </link>
  <gazebo reference="RH_Roller9">
    <material>Gazebo/White</material>
    <collision>
      <surface>
        <friction>
          <ode>
            <mu>0.6</mu>
            <mu2>0.6</mu2>
            <slip1>0</slip1>
            <slip2>0</slip2>
          </ode>
        </friction>
        <contact>
          <ode>
            <kp>10000.0</kp>
            <kd>100.0</kd>
            <min_depth>0.001</min_depth>
          </ode>
        </contact>
      </surface>
    </collision>
    <sensor name="RH_contactsensor_sensor" type="contact">
      <always_on>true</always_on>
      <update_rate>50</update_rate>
      <contact>
        <collision>
                            RH_LOWER_LEG_fixed_joint_lump__RH_FOOT_collision_1</collision>
      </contact>
    </sensor>
  </gazebo>
  <link name="RH_Roller10">
    <inertial>
      <origin rpy="0 0 0" xyz="0 0 6.3075E-15"/>
      <mass value="0.0059616"/>
      <inertia ixx="7.911E-07" ixy="1.2914E-12" ixz="-1.8529E-22" iyy="7.9113E-07" iyz="-6.6174E-24" izz="2.3532E-07"/>
    </inertial>
    <visual>
      <origin rpy="0 0 0" xyz="0 0 0"/>
      <geometry>
        <mesh filename="file:///home/francesco/Documents/mulinex_ws/install/mulinex_omni_description/share/mulinex_omni_description/meshes//roller_1.STL"/>
      </geometry>
      <material name="white"/>
    </visual>
    <collision>
      <origin rpy="0 0 0" xyz="0 0 0"/>
      <geometry>
        <mesh filename="file:///home/francesco/Documents/mulinex_ws/install/mulinex_omni_description/share/mulinex_omni_description/meshes//roller_1.STL"/>
      </geometry>
    </collision>
  </link>
  <gazebo reference="RH_Roller9">
    <material>Gazebo/White</material>
    <collision>
      <surface>
        <friction>
          <ode>
            <mu>0.6</mu>
            <mu2>0.6</mu2>
            <slip1>0</slip1>
            <slip2>0</slip2>
          </ode>
        </friction>
        <contact>
          <ode>
            <kp>10000.0</kp>
            <kd>100.0</kd>
            <min_depth>0.001</min_depth>
          </ode>
        </contact>
      </surface>
    </collision>
    <sensor name="RH_contactsensor_sensor" type="contact">
      <always_on>true</always_on>
      <update_rate>50</update_rate>
      <contact>
        <collision>
                            RH_LOWER_LEG_fixed_joint_lump__RH_FOOT_collision_1</collision>
      </contact>
    </sensor>
  </gazebo>
  <!--           <joint
            name="${prefix}_rol1"
            type="continuous">
            <origin
              xyz="-0.026605 -0.015694 0.01516"
              rpy="${-PI/2} 0 0" />
            <parent
              link="${prefix}_WHEEL"/>
            <child
              link="${prefix}_Roller1" />
            <axis
              xyz="-0.37796 0.65465 -0.65465" />
          </joint> -->
  <joint name="RH_rol1" type="continuous">
    <parent link="RH_WHEEL"/>
    <child link="RH_Roller1"/>
    <axis xyz="0 0 -1"/>
    <origin rpy="-2.5315 0.60848 -0.38574" xyz="0.039707 -0.04345 -0.012901"/>
  </joint>
  <joint name="RH_rol2" type="continuous">
    <parent link="RH_WHEEL"/>
    <child link="RH_Roller2"/>
    <axis xyz="0 0 -1"/>
    <origin rpy="-3.0918 1.1416 -0.83583" xyz="0.02454 -0.04345 -0.033776"/>
  </joint>
  <joint name="RH_rol3" type="continuous">
    <parent link="RH_WHEEL"/>
    <child link="RH_Roller3"/>
    <origin rpy="1.5708 1.119 -2.3562" xyz="0 -0.04345 -0.04175"/>
    <axis xyz="0 0 -1"/>
  </joint>
  <joint name="RH_rol4" type="continuous">
    <parent link="RH_WHEEL"/>
    <child link="RH_Roller4"/>
    <origin rpy="1.0515 0.57804 -2.7641" xyz="-0.02454 -0.04345 -0.033776"/>
    <axis xyz="0 0 -1"/>
  </joint>
  <joint name="RH_rol5" type="continuous">
    <parent link="RH_WHEEL"/>
    <child link="RH_Roller5"/>
    <origin rpy="0.83311 -0.015598 -2.8277" xyz="-0.039707 -0.04345 -0.012901"/>
    <axis xyz="0 0 -1"/>
  </joint>
  <joint name="RH_rol6" type="continuous">
    <parent link="RH_WHEEL"/>
    <child link="RH_Roller6"/>
    <origin rpy="0.61008 -0.60848 -2.7559" xyz="-0.039707 -0.04345 0.012901"/>
    <axis xyz="0 0 -1"/>
  </joint>
  <joint name="RH_rol7" type="continuous">
    <parent link="RH_WHEEL"/>
    <child link="RH_Roller7"/>
    <origin rpy="0.049792 -1.1416 -2.3058" xyz="-0.02454 -0.04345 0.033776"/>
    <axis xyz="0 0 -1"/>
  </joint>
  <joint name="RH_rol8" type="continuous">
    <parent link="RH_WHEEL"/>
    <child link="RH_Roller8"/>
    <origin rpy="-1.5708 -1.119 -0.7854" xyz="0 -0.04345 0.04175"/>
    <axis xyz="0 0 -1"/>
  </joint>
  <joint name="RH_rol9" type="continuous">
    <parent link="RH_WHEEL"/>
    <child link="RH_Roller9"/>
    <origin rpy="-2.0901 -0.57804 -0.3775" xyz="0.02454 -0.04345 0.033776"/>
    <axis xyz="0 0 -1"/>
  </joint>
  <joint name="RH_rol10" type="continuous">
    <parent link="RH_WHEEL"/>
    <child link="RH_Roller10"/>
    <origin rpy="-2.3085 0.015598 -0.31388" xyz="0.039707 -0.04345 0.012901"/>
    <axis xyz="0 0 -1"/>
  </joint>
  <gazebo reference="base_link">
    <material>Gazebo/White</material>
  </gazebo>
  <!-- <gazebo>
            <plugin filename="libgazebo_ros2_control.so" name="gazebo_ros2_control">
                <parameters>$(find mulinex_gazebo)/config/mulinex_gazebo_sim_jnt_PD_IMU.yaml</parameters>
            </plugin>
        </gazebo> -->
  <ros2_control name="GazeboSystem" type="system">
    <hardware>
      <plugin>gazebo_ros2_control/GazeboSystem</plugin>
    </hardware>
    <joint name="LH_HAA">
      <command_interface name="effort"/>
      <state_interface name="position">
        <param name="initial_value">0.0</param>
      </state_interface>
      <state_interface name="velocity">
        <param name="initial_value">0.0</param>
      </state_interface>
      <state_interface name="effort"/>
    </joint>
    <joint name="LH_HFE">
      <command_interface name="effort"/>
      <state_interface name="position">
        <param name="initial_value">0.0</param>
      </state_interface>
      <state_interface name="velocity">
        <param name="initial_value">0.0</param>
      </state_interface>
      <state_interface name="effort"/>
    </joint>
    <joint name="LH_KFE">
      <command_interface name="effort"/>
      <state_interface name="position">
        <param name="initial_value">0.0</param>
      </state_interface>
      <state_interface name="velocity">
        <param name="initial_value">0.0</param>
      </state_interface>
      <state_interface name="effort"/>
    </joint>
    <joint name="LF_HAA">
      <command_interface name="effort"/>
      <state_interface name="position">
        <param name="initial_value">0.0</param>
      </state_interface>
      <state_interface name="velocity">
        <param name="initial_value">0.0</param>
      </state_interface>
      <state_interface name="effort"/>
    </joint>
    <joint name="LF_HFE">
      <command_interface name="effort"/>
      <state_interface name="position">
        <param name="initial_value">0.0</param>
      </state_interface>
      <state_interface name="velocity">
        <param name="initial_value">0.0</param>
      </state_interface>
      <state_interface name="effort"/>
    </joint>
    <joint name="LF_KFE">
      <command_interface name="effort"/>
      <state_interface name="position">
        <param name="initial_value">0.0</param>
      </state_interface>
      <state_interface name="velocity">
        <param name="initial_value">0.0</param>
      </state_interface>
      <state_interface name="effort"/>
    </joint>
    <joint name="RH_HAA">
      <command_interface name="effort"/>
      <state_interface name="position">
        <param name="initial_value">0.0</param>
      </state_interface>
      <state_interface name="velocity">
        <param name="initial_value">0.0</param>
      </state_interface>
      <state_interface name="effort"/>
    </joint>
    <joint name="RH_HFE">
      <command_interface name="effort"/>
      <state_interface name="position">
        <param name="initial_value">0.0</param>
      </state_interface>
      <state_interface name="velocity">
        <param name="initial_value">0.0</param>
      </state_interface>
      <state_interface name="effort"/>
    </joint>
    <joint name="RH_KFE">
      <command_interface name="effort"/>
      <state_interface name="position">
        <param name="initial_value">0.0</param>
      </state_interface>
      <state_interface name="velocity">
        <param name="initial_value">0.0</param>
      </state_interface>
      <state_interface name="effort"/>
    </joint>
    <joint name="RF_HAA">
      <command_interface name="effort"/>
      <state_interface name="position">
        <param name="initial_value">0.0</param>
      </state_interface>
      <state_interface name="velocity">
        <param name="initial_value">0.0</param>
      </state_interface>
      <state_interface name="effort"/>
    </joint>
    <joint name="RF_HFE">
      <command_interface name="effort"/>
      <state_interface name="position">
        <param name="initial_value">0.0</param>
      </state_interface>
      <state_interface name="velocity">
        <param name="initial_value">0.0</param>
      </state_interface>
      <state_interface name="effort"/>
    </joint>
    <joint name="RF_KFE">
      <command_interface name="effort"/>
      <state_interface name="position">
        <param name="initial_value">0.0</param>
      </state_interface>
      <state_interface name="velocity">
        <param name="initial_value">0.0</param>
      </state_interface>
      <state_interface name="effort"/>
    </joint>
  </ros2_control>
  <gazebo reference="base_link">
    <sensor name="br_imu" type="imu">
      <always_on>true</always_on>
      <update_rate>100</update_rate>
      <imu>
        <angular_velocity>
          <x>
            <noise type="gaussian">
              <mean>0.0</mean>
              <stddev>2e-4</stddev>
            </noise>
          </x>
          <y>
            <noise type="gaussian">
              <mean>0.0</mean>
              <stddev>2e-4</stddev>
            </noise>
          </y>
          <z>
            <noise type="gaussian">
              <mean>0.0</mean>
              <stddev>2e-4</stddev>
            </noise>
          </z>
        </angular_velocity>
        <linear_acceleration>
          <x>
            <noise type="gaussian">
              <mean>0.0</mean>
              <stddev>1.7e-2</stddev>
            </noise>
          </x>
          <y>
            <noise type="gaussian">
              <mean>0.0</mean>
              <stddev>1.7e-2</stddev>
            </noise>
          </y>
          <z>
            <noise type="gaussian">
              <mean>0.0</mean>
              <stddev>1.7e-2</stddev>
            </noise>
          </z>
        </linear_acceleration>
      </imu>
      <plugin filename="libgazebo_ros_imu_sensor.so" name="bytes_imu">
        <ros>
          <namespace>imu</namespace>
          <remapping>~/out:=data</remapping>
        </ros>
        <initial_orientation_as_reference>false</initial_orientation_as_reference>
      </plugin>
    </sensor>
  </gazebo>
</robot>
