<?xml version="1.0" ?>
<robot name="mulinex">
  <!-- <xacro:property name="base_2_HFE_x" value="${190.00 * 0.001}" /> -->
  <!-- <xacro:property name="base_2_HFE_y" value="${104.60 * 0.001}" /> -->
  <!--  -->
  <!-- EACH MACRO CONSISTS OF THE LINK AND ITS PREVIOUS JOINT -->
  <!--  -->
  <!-- <xacro:property name="base_2_HFE_x" value="${190.00 * 0.001}" /> -->
  <!-- <xacro:property name="base_2_HFE_y" value="${104.60 * 0.001}" /> -->
  <!--  -->
  <!-- EACH MACRO CONSISTS OF THE LINK AND ITS PREVIOUS JOINT -->
  <!--  -->
  <material name="black">
    <color rgba="0.0 0.0 0.0 1.0"/>
  </material>
  <material name="blue">
    <color rgba="0.0 0.0 0.8 1.0"/>
  </material>
  <material name="green">
    <color rgba="0.0 0.8 0.0 1.0"/>
  </material>
  <material name="grey">
    <color rgba="0.2 0.2 0.2 1.0"/>
  </material>
  <material name="orange">
    <color rgba="1.0 0.4235294117647059 0.0392156862745098 0.5"/>
  </material>
  <material name="brown">
    <color rgba="0.8705882352941177 0.8117647058823529 0.7647058823529411 1.0"/>
  </material>
  <material name="red">
    <color rgba="0.8 0.0 0.0 1.0"/>
  </material>
  <material name="white">
    <color rgba="1.0 1.0 1.0 1.0"/>
  </material>

  <link name="base_link">
    <visual>
      <material name="white"/>
      <origin rpy="0 0 0" xyz="0 0 0"/>
      <geometry>
        <mesh filename="package://assets/Base.stl"/>
        <!-- <box size="0.353 0.090 0.066" /> -->
      </geometry>
    </visual>
    <collision>
      <origin rpy="0 0 0" xyz="0 0 0"/>
      <geometry>
        <box size="0.353 0.090 0.066"/>
      </geometry>
    </collision>
    <inertial>
      <mass value="1.3008737"/>
      <origin rpy="0 0 0" xyz="-1.4565496e-03 -2.5110071e-03 -4.2484136e-03"/>
      <inertia ixx="4.0762590e-03" ixy="-2.5234809e-05" ixz="-3.2587794e-06" iyy="9.2413606e-03" iyz="-8.0660183e-06" izz="1.2268730e-02"/>
    </inertial>
  </link>
  <!-- Joint to fix the leg to the base -->
  <joint name="LH_HAA" type="fixed">
    <parent link="base_link"/>
    <child link="LH_SHOULDER"/>
    <origin rpy="0 0 0" xyz="-0.045 0.081 0"/>
  </joint>
  <!-- Shoulder link -->
  <link name="LH_SHOULDER">
    <visual>
      <material name="white"/>
      <origin rpy="0 0 0" xyz="0 0 0"/>
      <geometry>
        <mesh filename="package://assets/Module_left_hind.stl"/>
      </geometry>
    </visual>
    <collision>
      <origin rpy="0 0 0" xyz="-0.0945 0 0"/>
      <geometry>
        <!-- <mesh filename="${mulinex_module_left_hind}" /> -->
        <box size="0.269 0.057 0.060"/>
      </geometry>
    </collision>
    <inertial>
      <mass value="0.47669673"/>
      <origin rpy="0 0 0" xyz="-7.2487360e-02 3.1582591e-02 2.4812434e-03"/>
      <inertia ixx="2.1574269e-04" ixy="3.3437484e-05" ixz="-2.4284668e-06" iyy="3.0607390e-03" iyz="-2.0388977e-06" izz="3.0504273e-03"/>
    </inertial>
  </link>
  <gazebo reference="LH_SHOULDER">
    <material>Gazebo/White</material>
    <collision>
      <surface>
        <friction>
          <ode>
            <mu>1</mu>
            <mu2>1</mu2>
            <slip1>0</slip1>
            <slip2>0</slip2>
          </ode>
        </friction>
        <contact>
          <ode>
            <kp>1000000.0</kp>
            <kd>100.0</kd>
            <min_depth>0.001</min_depth>
          </ode>
        </contact>
      </surface>
    </collision>
  </gazebo>
  <!-- Hip joint -->
  <joint name="LH_HFE" type="revolute">
    <parent link="LH_SHOULDER"/>
    <child link="LH_UPPER_LEG"/>
    <origin rpy="0 0 0" xyz="-0.19 0.044 0"/>
    <axis xyz="0 1 0"/>
    <limit effort="2.7" lower="-3.141592" upper="3.141592" velocity="1000"/>
    <!-- <dynamics damping="0.7" friction="100.0" /> -->
  </joint>
  <!-- Upper leg link -->
  <link name="LH_UPPER_LEG">
    <visual>
      <material name="white"/>
      <origin rpy="0 0 0" xyz="0 0 0"/>
      <geometry>
        <mesh filename="package://assets/Module_left_hind.stl"/>
      </geometry>
    </visual>
    <collision>
      <origin rpy="0 0 0" xyz="-0.0945 0.015 0"/>
      <geometry>
        <!-- <mesh filename="${mulinex_module_left_hind}" /> -->
        <box size="0.269 0.057 0.060"/>
      </geometry>
    </collision>
    <inertial>
      <mass value="0.47669673"/>
      <origin rpy="0 0 0" xyz="-7.2487360e-02 3.1582591e-02 2.4812434e-03"/>
      <inertia ixx="2.1574269e-04" ixy="3.3437484e-05" ixz="-2.4284668e-06" iyy="3.0607390e-03" iyz="-2.0388977e-06" izz="3.0504273e-03"/>
    </inertial>
  </link>

  <!--joint caviglia -->
  <joint name="LF_ANKLE" type="revolute">
    <origin rpy="1.5708 0 1.5708" xyz="-0.19 0.05 0"/>
    <parent link="LH_UPPER_LEG"/>
    <child link="body_left_H"/>
    <axis xyz="1 0 0"/>
    <limit effort="10" velocity="10" lower="-0.785398" upper="0.785398"/>
  </joint>


  <link name="body_left_H">
    <inertial>
      <origin xyz="0.0238777 -0.00119624 -0.00412068" rpy="0 0 0"/>
      <mass value="0.6"/>
      <inertia ixx="0.000408384" ixy="6.93353e-06" ixz="3.09979e-05" iyy="0.000335218" iyz="-2.90084e-05" izz="0.000303698"/>
    </inertial>
    <!-- Part body_left -->
    <visual>
      <origin xyz="2.26711e-87 3.26265e-55 4.41854e-07" rpy="1.67587e-64 -0 3.14159"/>
      <geometry>
        <mesh filename="package://assets/body_left.stl"/>
      </geometry>
      <material name="body_left_material">
        <color rgba="0.647059 0.647059 0.647059 1"/>
      </material>
    </visual>
    <collision>
      <origin xyz="2.26711e-87 3.26265e-55 4.41854e-07" rpy="1.67587e-64 -0 3.14159"/>
      <geometry>
        <mesh filename="package://assets/body_left.stl"/>
      </geometry>
    </collision>
  </link>
  <!-- Link wheel -->
  <link name="wheel_1_LEFT_H">
    <inertial>
      <origin xyz="1.92585e-20 -5.69643e-18 -0.0225" rpy="0 0 0"/>
      <mass value="0.1"/>
      <inertia ixx="2.26562e-05" ixy="0" ixz="0" iyy="2.26562e-05" iyz="5.3406e-69" izz="1.15625e-05"/>
    </inertial>
    <!-- Part wheel -->
    <visual>
      <origin xyz="0 -6.93889e-18 -0.045" rpy="-1.5708 -1.5708 0"/>
      <geometry>
        <mesh filename="package://assets/wheel.stl"/>
      </geometry>
      <material name="wheel_material">
        <color rgba="0.615686 0.811765 0.929412 1"/>
      </material>
    </visual>
    <collision>
      <origin xyz="0 -6.93889e-18 -0.045" rpy="-1.5708 -1.5708 0"/>
      <geometry>
        <mesh filename="package://assets/wheel.stl"/>
      </geometry>
    </collision>
  </link>
  <!-- Joint from body_left to wheel -->
  <joint name="joint_1_LEFT_H" type="continuous">
    <origin xyz="0 0.0484063 -0.0583795" rpy="-6.12323e-17 -1.5708 0"/>
    <parent link="body_left_H"/>
    <child link="wheel_1_LEFT_H"/>
    <axis xyz="0 0 1"/>
    <limit effort="10" velocity="10"/>
  </joint>
  <!-- Link wheel_2 -->
  <link name="wheel_2_LEFT_H">
    <inertial>
      <origin xyz="1.92585e-20 3.02108e-19 -0.0225" rpy="0 0 0"/>
      <mass value="0.1"/>
      <inertia ixx="2.26562e-05" ixy="0" ixz="0" iyy="2.26562e-05" iyz="5.3406e-69" izz="1.15625e-05"/>
    </inertial>
    <!-- Part wheel_2 -->
    <visual>
      <origin xyz="0 -9.40354e-19 -0.045" rpy="-1.5708 -1.5708 0"/>
      <geometry>
        <mesh filename="package://assets/wheel.stl"/>
      </geometry>
      <material name="wheel_2_material">
        <color rgba="0.615686 0.811765 0.929412 1"/>
      </material>
    </visual>
    <collision>
      <origin xyz="0 -9.40354e-19 -0.045" rpy="-1.5708 -1.5708 0"/>
      <geometry>
        <mesh filename="package://assets/wheel.stl"/>
      </geometry>
    </collision>
  </link>
  <!-- Joint from body_left to wheel_2 -->
  <joint name="joint_2_LEFT_H" type="continuous">
    <origin xyz="0 1.07779e-16 -0.0583795" rpy="-6.12323e-17 -1.5708 0"/>
    <parent link="body_left_H"/>
    <child link="wheel_2_LEFT_H"/>
    <axis xyz="0 0 1"/>
    <limit effort="10" velocity="10"/>
  </joint>
  <!-- Link wheel_3 -->
  <link name="wheel_3_LEFT_H">
    <inertial>
      <origin xyz="1.92585e-20 1.24246e-18 -0.0225" rpy="0 0 0"/>
      <mass value="0.1"/>
      <inertia ixx="2.26562e-05" ixy="0" ixz="0" iyy="2.26562e-05" iyz="5.3406e-69" izz="1.15625e-05"/>
    </inertial>
    <!-- Part wheel_3 -->
    <visual>
      <origin xyz="0 0 -0.045" rpy="-1.5708 -1.5708 0"/>
      <geometry>
        <mesh filename="package://assets/wheel.stl"/>
      </geometry>
      <material name="wheel_3_material">
        <color rgba="0.615686 0.811765 0.929412 1"/>
      </material>
    </visual>
    <collision>
      <origin xyz="0 0 -0.045" rpy="-1.5708 -1.5708 0"/>
      <geometry>
        <mesh filename="package://assets/wheel.stl"/>
      </geometry>
    </collision>
  </link>
  <!-- Joint from body_left to wheel_3 -->
  <joint name="joint_3_LEFT_H" type="continuous">
    <origin xyz="0 -0.0510313 -0.0583795" rpy="-6.12323e-17 -1.5708 0"/>
    <parent link="body_left_H"/>
    <child link="wheel_3_LEFT_H"/>
    <axis xyz="0 0 1"/>
    <limit effort="10" velocity="10"/>
  </joint>
  <!-- Link wheel_4 -->
  <link name="wheel_4_LEFT_H">
    <inertial>
      <origin xyz="1.92585e-20 1.24246e-18 -0.0225" rpy="0 0 0"/>
      <mass value="0.1"/>
      <inertia ixx="2.26562e-05" ixy="0" ixz="0" iyy="2.26562e-05" iyz="5.3406e-69" izz="1.15625e-05"/>
    </inertial>
    <!-- Part wheel_4 -->
    <visual>
      <origin xyz="0 0 -0.045" rpy="-1.5708 -1.5708 0"/>
      <geometry>
        <mesh filename="package://assets/wheel.stl"/>
      </geometry>
      <material name="wheel_4_material">
        <color rgba="0.615686 0.811765 0.929412 1"/>
      </material>
    </visual>
    <collision>
      <origin xyz="0 0 -0.045" rpy="-1.5708 -1.5708 0"/>
      <geometry>
        <mesh filename="package://assets/wheel.stl"/>
      </geometry>
    </collision>
  </link>
  <!-- Joint from body_left to wheel_4 -->
  <joint name="joint_4_LEFT_H" type="continuous">
    <origin xyz="0 -0.0766777 -0.0417374" rpy="-6.12323e-17 -1.5708 0"/>
    <parent link="body_left_H"/>
    <child link="wheel_4_LEFT_H"/>
    <axis xyz="0 0 1"/>
    <limit effort="10" velocity="10"/>
  </joint>



    






  <gazebo reference="LH_UPPER_LEG">
    <material>Gazebo/White</material>
    <collision>
      <surface>
        <friction>
          <ode>
            <mu>1</mu>
            <mu2>1</mu2>
            <slip1>0</slip1>
            <slip2>0</slip2>
          </ode>
        </friction>
        <contact>
          <ode>
            <kp>1000000.0</kp>
            <kd>100.0</kd>
            <min_depth>0.001</min_depth>
          </ode>
        </contact>
      </surface>
    </collision>
  </gazebo>
  <!-- Knee joint -->
  <!-- <joint name="LH_KFE" type="revolute">
    <parent link="LH_UPPER_LEG"/>
    <child link="LH_LOWER_LEG"/>
    <origin rpy="0 0 0" xyz="-0.19 0.044 0"/>
    <axis xyz="0 1 0"/>
    <limit effort="2.7" lower="-3.141592" upper="3.141592" velocity="1000"/>
  </joint> -->
  <!-- Track -->
 
  <!-- Joint to fix the leg to the base -->
  <joint name="LF_HAA" type="fixed">
    <parent link="base_link"/>
    <child link="LF_SHOULDER"/>
    <origin rpy="0 0 0" xyz="0.045 0.081 0"/>
  </joint>
  <!-- Shoulder link -->
  <link name="LF_SHOULDER">
    <visual>
      <material name="white"/>
      <origin rpy="0 0 0" xyz="0 0 0"/>
      <geometry>
        <mesh filename="package://assets/Module_left_front.stl"/>
      </geometry>
    </visual>
    <collision>
      <origin rpy="0 0 0" xyz="0.0945 0 0"/>
      <geometry>
        <!-- <mesh filename="${mulinex_module_left_front}" /> -->
        <box size="0.269 0.057 0.060"/>
      </geometry>
    </collision>
    <inertial>
      <mass value="0.47669673"/>
      <origin rpy="0 0 0" xyz="7.2487360e-02 3.1582591e-02 -2.4812434e-03"/>
      <inertia ixx="2.1574269e-04" ixy="-3.3437484e-05" ixz="-2.4284668e-06" iyy="3.0607390e-03" iyz="-2.0388977e-06" izz="3.0504273e-03"/>
    </inertial>
  </link>
  <gazebo reference="LF_SHOULDER">
    <material>Gazebo/White</material>
    <collision>
      <surface>
        <friction>
          <ode>
            <mu>1</mu>
            <mu2>1</mu2>
            <slip1>0</slip1>
            <slip2>0</slip2>
          </ode>
        </friction>
        <contact>
          <ode>
            <kp>1000000.0</kp>
            <kd>100.0</kd>
            <min_depth>0.001</min_depth>
          </ode>
        </contact>
      </surface>
    </collision>
  </gazebo>
  <!-- Hip joint -->
  <joint name="LF_HFE" type="revolute">
    <parent link="LF_SHOULDER"/>
    <child link="LF_UPPER_LEG"/>
    <origin rpy="0 0 0" xyz="0.19 0.044 0"/>
    <axis xyz="0 1 0"/>
    <limit effort="2.7" lower="-3.141592" upper="3.141592" velocity="1000"/>
    <!-- <dynamics damping="0.7" friction="100.0" /> -->
  </joint>
  <!-- Upper leg link -->
  <link name="LF_UPPER_LEG">
    <visual>
      <material name="white"/>
      <origin rpy="0 0 0" xyz="0 0 0"/>
      <geometry>
        <mesh filename="package://assets/Module_left_front.stl"/>
      </geometry>
    </visual>
    <collision>
      <origin rpy="0 0 0" xyz="0.0945 0.015 0"/>
      <geometry>
        <!-- <mesh filename="${mulinex_module_left_front}" /> -->
        <box size="0.269 0.057 0.060"/>
      </geometry>
    </collision>
    <inertial>
      <mass value="0.47669673"/>
      <origin rpy="0 0 0" xyz="7.2487360e-02 3.1582591e-02 -2.4812434e-03"/>
      <inertia ixx="2.1574269e-04" ixy="-3.3437484e-05" ixz="-2.4284668e-06" iyy="3.0607390e-03" iyz="-2.0388977e-06" izz="3.0504273e-03"/>
    </inertial>
  </link>
  <gazebo reference="LF_UPPER_LEG">
    <material>Gazebo/White</material>
    <collision>
      <surface>
        <friction>
          <ode>
            <mu>1</mu>
            <mu2>1</mu2>
            <slip1>0</slip1>
            <slip2>0</slip2>
          </ode>
        </friction>
        <contact>
          <ode>
            <kp>1000000.0</kp>
            <kd>100.0</kd>
            <min_depth>0.001</min_depth>
          </ode>
        </contact>
      </surface>
    </collision>
  </gazebo>
  <!-- Knee joint -->
  <!-- <joint name="LF_KFE" type="revolute">
    <parent link="LF_UPPER_LEG"/>
    <child link="LF_LOWER_LEG"/>
    <origin rpy="0 0 0" xyz="0.19 0.044 0"/>
    <axis xyz="0 1 0"/>
    <limit effort="2.7" lower="-3.141592" upper="3.141592" velocity="1000"/>
  </joint> -->
  <!-- Lower leg link -->

<!--joint caviglia -->
  <joint name="LH_ANKLE" type="revolute">
    <origin rpy="-1.5708 0 1.5708" xyz="0.19 0.05 0"/>
    <parent link="LF_UPPER_LEG"/>
    <child link="body_left_F"/>
    <axis xyz="1 0 0"/>
    <limit effort="10" velocity="10" lower="-0.785398" upper="0.785398"/>
  </joint>


  <link name="body_left_F">
    <inertial>
      <origin xyz="0.0238777 -0.00119624 -0.00412068" rpy="0 0 0"/>
      <mass value="0.6"/>
      <inertia ixx="0.000408384" ixy="6.93353e-06" ixz="3.09979e-05" iyy="0.000335218" iyz="-2.90084e-05" izz="0.000303698"/>
    </inertial>
    <!-- Part body_left -->
    <visual>
      <origin xyz="2.26711e-87 3.26265e-55 4.41854e-07" rpy="1.67587e-64 -0 3.14159"/>
      <geometry>
        <mesh filename="package://assets/body_left.stl"/>
      </geometry>
      <material name="body_left_material">
        <color rgba="0.647059 0.647059 0.647059 1"/>
      </material>
    </visual>
    <collision>
      <origin xyz="2.26711e-87 3.26265e-55 4.41854e-07" rpy="1.67587e-64 -0 3.14159"/>
      <geometry>
        <mesh filename="package://assets/body_left.stl"/>
      </geometry>
    </collision>
  </link>
  <!-- Link wheel -->
  <link name="wheel_1_LEFT_F">
    <inertial>
      <origin xyz="1.92585e-20 -5.69643e-18 -0.0225" rpy="0 0 0"/>
      <mass value="0.1"/>
      <inertia ixx="2.26562e-05" ixy="0" ixz="0" iyy="2.26562e-05" iyz="5.3406e-69" izz="1.15625e-05"/>
    </inertial>
    <!-- Part wheel -->
    <visual>
      <origin xyz="0 -6.93889e-18 -0.045" rpy="-1.5708 -1.5708 0"/>
      <geometry>
        <mesh filename="package://assets/wheel.stl"/>
      </geometry>
      <material name="wheel_material">
        <color rgba="0.615686 0.811765 0.929412 1"/>
      </material>
    </visual>
    <collision>
      <origin xyz="0 -6.93889e-18 -0.045" rpy="-1.5708 -1.5708 0"/>
      <geometry>
        <mesh filename="package://assets/wheel.stl"/>
      </geometry>
    </collision>
  </link>
  <!-- Joint from body_left to wheel -->
  <joint name="joint_1_LEFT_F" type="continuous">
    <origin xyz="0 0.0484063 -0.0583795" rpy="-6.12323e-17 -1.5708 0"/>
    <parent link="body_left_F"/>
    <child link="wheel_1_LEFT_F"/>
    <axis xyz="0 0 1"/>
    <limit effort="10" velocity="10"/>
  </joint>
  <!-- Link wheel_2 -->
  <link name="wheel_2_LEFT_F">
    <inertial>
      <origin xyz="1.92585e-20 3.02108e-19 -0.0225" rpy="0 0 0"/>
      <mass value="0.1"/>
      <inertia ixx="2.26562e-05" ixy="0" ixz="0" iyy="2.26562e-05" iyz="5.3406e-69" izz="1.15625e-05"/>
    </inertial>
    <!-- Part wheel_2 -->
    <visual>
      <origin xyz="0 -9.40354e-19 -0.045" rpy="-1.5708 -1.5708 0"/>
      <geometry>
        <mesh filename="package://assets/wheel.stl"/>
      </geometry>
      <material name="wheel_2_material">
        <color rgba="0.615686 0.811765 0.929412 1"/>
      </material>
    </visual>
    <collision>
      <origin xyz="0 -9.40354e-19 -0.045" rpy="-1.5708 -1.5708 0"/>
      <geometry>
        <mesh filename="package://assets/wheel.stl"/>
      </geometry>
    </collision>
  </link>
  <!-- Joint from body_left to wheel_2 -->
  <joint name="joint_2_LEFT_F" type="continuous">
    <origin xyz="0 1.07779e-16 -0.0583795" rpy="-6.12323e-17 -1.5708 0"/>
    <parent link="body_left_F"/>
    <child link="wheel_2_LEFT_F"/>
    <axis xyz="0 0 1"/>
    <limit effort="10" velocity="10"/>
  </joint>
  <!-- Link wheel_3 -->
  <link name="wheel_3_LEFT_F">
    <inertial>
      <origin xyz="1.92585e-20 1.24246e-18 -0.0225" rpy="0 0 0"/>
      <mass value="0.1"/>
      <inertia ixx="2.26562e-05" ixy="0" ixz="0" iyy="2.26562e-05" iyz="5.3406e-69" izz="1.15625e-05"/>
    </inertial>
    <!-- Part wheel_3 -->
    <visual>
      <origin xyz="0 0 -0.045" rpy="-1.5708 -1.5708 0"/>
      <geometry>
        <mesh filename="package://assets/wheel.stl"/>
      </geometry>
      <material name="wheel_3_material">
        <color rgba="0.615686 0.811765 0.929412 1"/>
      </material>
    </visual>
    <collision>
      <origin xyz="0 0 -0.045" rpy="-1.5708 -1.5708 0"/>
      <geometry>
        <mesh filename="package://assets/wheel.stl"/>
      </geometry>
    </collision>
  </link>
  <!-- Joint from body_left to wheel_3 -->
  <joint name="joint_3_LEFT_F" type="continuous">
    <origin xyz="0 -0.0510313 -0.0583795" rpy="-6.12323e-17 -1.5708 0"/>
    <parent link="body_left_F"/>
    <child link="wheel_3_LEFT_F"/>
    <axis xyz="0 0 1"/>
    <limit effort="10" velocity="10"/>
  </joint>
  <!-- Link wheel_4 -->
  <link name="wheel_4_LEFT_F">
    <inertial>
      <origin xyz="1.92585e-20 1.24246e-18 -0.0225" rpy="0 0 0"/>
      <mass value="0.1"/>
      <inertia ixx="2.26562e-05" ixy="0" ixz="0" iyy="2.26562e-05" iyz="5.3406e-69" izz="1.15625e-05"/>
    </inertial>
    <!-- Part wheel_4 -->
    <visual>
      <origin xyz="0 0 -0.045" rpy="-1.5708 -1.5708 0"/>
      <geometry>
        <mesh filename="package://assets/wheel.stl"/>
      </geometry>
      <material name="wheel_4_material">
        <color rgba="0.615686 0.811765 0.929412 1"/>
      </material>
    </visual>
    <collision>
      <origin xyz="0 0 -0.045" rpy="-1.5708 -1.5708 0"/>
      <geometry>
        <mesh filename="package://assets/wheel.stl"/>
      </geometry>
    </collision>
  </link>
  <!-- Joint from body_left to wheel_4 -->
  <joint name="joint_4_LEFT_F" type="continuous">
    <origin xyz="0 -0.0766777 -0.0417374" rpy="-6.12323e-17 -1.5708 0"/>
    <parent link="body_left_F"/>
    <child link="wheel_4_LEFT_F"/>
    <axis xyz="0 0 1"/>
    <limit effort="10" velocity="10"/>
  </joint>





  
  <!-- Joint to fix the leg to the base -->
  <joint name="RF_HAA" type="fixed">
    <parent link="base_link"/>
    <child link="RF_SHOULDER"/>
    <origin rpy="0 0 0" xyz="0.045 -0.081 0"/>
  </joint>
  <!-- Shoulder link -->
  <link name="RF_SHOULDER">
    <visual>
      <material name="white"/>
      <origin rpy="0 0 0" xyz="0 0 0"/>
      <geometry>
        <mesh filename="package://assets/Module_right_front.stl"/>
      </geometry>
    </visual>
    <collision>
      <origin rpy="0 0 0" xyz="0.0945 0 0"/>
      <geometry>
        <!-- <mesh filename="${mulinex_module_right_front}" /> -->
        <box size="0.269 0.057 0.060"/>
      </geometry>
    </collision>
    <inertial>
      <mass value="0.47669673"/>
      <origin rpy="0 0 0" xyz="7.2487360e-02 -3.1582591e-02 2.4812434e-03"/>
      <inertia ixx="2.1574269e-04" ixy="3.3437484e-05" ixz="2.4284668e-06" iyy="3.0607390e-03" iyz="-2.0388977e-06" izz="3.0504273e-03"/>
    </inertial>
  </link>
  <gazebo reference="RF_SHOULDER">
    <material>Gazebo/White</material>
    <collision>
      <surface>
        <friction>
          <ode>
            <mu>1</mu>
            <mu2>1</mu2>
            <slip1>0</slip1>
            <slip2>0</slip2>
          </ode>
        </friction>
        <contact>
          <ode>
            <kp>1000000.0</kp>
            <kd>100.0</kd>
            <min_depth>0.001</min_depth>
          </ode>
        </contact>
      </surface>
    </collision>
  </gazebo>
  <!-- Hip joint -->
  <joint name="RF_HFE" type="revolute">
    <parent link="RF_SHOULDER"/>
    <child link="RF_UPPER_LEG"/>
    <origin rpy="0 0 0" xyz="0.19 -0.044 0"/>
    <axis xyz="0 -1 0"/>
    <limit effort="2.7" lower="-3.141592" upper="3.141592" velocity="1000"/>
    <!-- <dynamics damping="0.7" friction="100.0" /> -->
  </joint>



  <!-- Upper leg link -->
  <link name="RF_UPPER_LEG">
    <visual>
      <material name="white"/>
      <origin rpy="0 0 0" xyz="0 0 0"/>
      <geometry>
        <mesh filename="package://assets/Module_right_front.stl"/>
      </geometry>
    </visual>
    <collision>
      <origin rpy="0 0 0" xyz="0.0945 -0.015 0"/>
      <geometry>
        <!-- <mesh filename="${mulinex_module_right_front}" /> -->
        <box size="0.269 0.057 0.060"/>
      </geometry>
    </collision>
    <inertial>
      <mass value="0.47669673"/>
      <origin rpy="0 0 0" xyz="7.2487360e-02 -3.1582591e-02 2.4812434e-03"/>
      <inertia ixx="2.1574269e-04" ixy="3.3437484e-05" ixz="2.4284668e-06" iyy="3.0607390e-03" iyz="-2.0388977e-06" izz="3.0504273e-03"/>
    </inertial>
  </link>
  <gazebo reference="RF_UPPER_LEG">
    <material>Gazebo/White</material>
    <collision>
      <surface>
        <friction>
          <ode>
            <mu>1</mu>
            <mu2>1</mu2>
            <slip1>0</slip1>
            <slip2>0</slip2>
          </ode>
        </friction>
        <contact>
          <ode>
            <kp>1000000.0</kp>
            <kd>100.0</kd>
            <min_depth>0.001</min_depth>
          </ode>
        </contact>
      </surface>
    </collision>
  </gazebo>
  <!-- Knee joint -->
  <!-- <joint name="RF_KFE" type="revolute">
    <parent link="RF_UPPER_LEG"/>
    <child link="RF_LOWER_LEG"/>
    <origin rpy="0 0 0" xyz="0.19 -0.044 0"/>
    <axis xyz="0 -1 0"/>
    <limit effort="2.7" lower="-3.141592" upper="3.141592" velocity="1000"/>
  </joint> -->
  <!-- Lower leg link -->
  <joint name="RF_ANKLE" type="revolute">
    <origin rpy="3.14159 0 1.5708" xyz="0.19 -0.05 0"/>
    <parent link="RF_UPPER_LEG"/>
    <child link="body_right_F"/>
    <axis xyz="1 0 0"/>
    <limit effort="10" velocity="10" lower="-0.785398" upper="0.785398"/>
  </joint>
  <link name="body_right_F">
    <inertial>
      <origin xyz="-0.0238777 0.00412068 -0.00119624" rpy="0 0 0"/>
      <mass value="0.6"/>
      <inertia ixx="0.000408384" ixy="3.09979e-05" ixz="-6.93353e-06" iyy="0.000303698" iyz="2.90084e-05" izz="0.000335218"/>
    </inertial>
    <!-- Part body_right -->
    <visual>
      <origin xyz="1.06911e-50 -4.41854e-07 3.98827e-51" rpy="-1.5708 5.05322e-16 -3.14159"/>
      <geometry>
        <mesh filename="package://assets/body_right.stl"/>
      </geometry>
      <material name="body_right_material">
        <color rgba="0.647059 0.647059 0.647059 1"/>
      </material>
    </visual>
    <collision>
      <origin xyz="1.06911e-50 -4.41854e-07 3.98827e-51" rpy="-1.5708 5.05322e-16 -3.14159"/>
      <geometry>
        <mesh filename="package://assets/body_right.stl"/>
      </geometry>
    </collision>
  </link>
  <!-- Link wheel -->
  <link name="wheel_1_RIGHT_F">
    <inertial>
      <origin xyz="-1.38585e-17 -2.22698e-18 -0.0225" rpy="0 0 0"/>
      <mass value="0.1"/>
      <inertia ixx="2.26562e-05" ixy="1.25767e-21" ixz="-3.51752e-35" iyy="2.26562e-05" iyz="5.70075e-37" izz="1.15625e-05"/>
    </inertial>
    <!-- Part wheel -->
    <visual>
      <origin xyz="-1.38778e-17 -3.46945e-18 -0.045" rpy="-1.5708 -1.5708 0"/>
      <geometry>
        <mesh filename="package://assets/wheel.stl"/>
      </geometry>
      <material name="wheel_material">
        <color rgba="0.615686 0.811765 0.929412 1"/>
      </material>
    </visual>
    <collision>
      <origin xyz="-1.38778e-17 -3.46945e-18 -0.045" rpy="-1.5708 -1.5708 0"/>
      <geometry>
        <mesh filename="package://assets/wheel.stl"/>
      </geometry>
    </collision>
  </link>
  <!-- Joint from body_right to wheel -->
  <joint name="joint_1_RIGHT_F" type="continuous">
    <origin xyz="2.08167e-17 0.0583795 0.0484062" rpy="-1.5708 0.992087 -1.5708"/>
    <parent link="body_right_F"/>
    <child link="wheel_1_RIGHT_F"/>
    <axis xyz="0 0 1"/>
    <limit effort="10" velocity="10"/>
  </joint>
  <!-- Link wheel_2 -->
  <link name="wheel_2_RIGHT_F">
    <inertial>
      <origin xyz="1.92585e-20 1.24246e-18 -0.0225" rpy="0 0 0"/>
      <mass value="0.1"/>
      <inertia ixx="2.26562e-05" ixy="-1.25767e-21" ixz="-5.70075e-37" iyy="2.26562e-05" iyz="0" izz="1.15625e-05"/>
    </inertial>
    <!-- Part wheel_2 -->
    <visual>
      <origin xyz="0 0 -0.045" rpy="-1.5708 -1.5708 0"/>
      <geometry>
        <mesh filename="package://assets/wheel.stl"/>
      </geometry>
      <material name="wheel_2_material">
        <color rgba="0.615686 0.811765 0.929412 1"/>
      </material>
    </visual>
    <collision>
      <origin xyz="0 0 -0.045" rpy="-1.5708 -1.5708 0"/>
      <geometry>
        <mesh filename="package://assets/wheel.stl"/>
      </geometry>
    </collision>
  </link>
  <!-- Joint from body_right to wheel_2 -->
  <joint name="joint_2_RIGHT_F" type="continuous">
    <origin xyz="0 0.0583795 1.10544e-16" rpy="-1.5708 0.967866 -1.5708"/>
    <parent link="body_right_F"/>
    <child link="wheel_2_RIGHT_F"/>
    <axis xyz="0 0 1"/>
    <limit effort="10" velocity="10"/>
  </joint>
  <!-- Link wheel_3 -->
  <link name="wheel_3_RIGHT_F">
    <inertial>
      <origin xyz="1.75398e-18 1.24246e-18 -0.0225" rpy="0 0 0"/>
      <mass value="0.1"/>
      <inertia ixx="2.26562e-05" ixy="2.51535e-21" ixz="-1.61624e-35" iyy="2.26562e-05" iyz="9.50639e-36" izz="1.15625e-05"/>
    </inertial>
    <!-- Part wheel_3 -->
    <visual>
      <origin xyz="1.73472e-18 0 -0.045" rpy="-1.5708 -1.5708 0"/>
      <geometry>
        <mesh filename="package://assets/wheel.stl"/>
      </geometry>
      <material name="wheel_3_material">
        <color rgba="0.615686 0.811765 0.929412 1"/>
      </material>
    </visual>
    <collision>
      <origin xyz="1.73472e-18 0 -0.045" rpy="-1.5708 -1.5708 0"/>
      <geometry>
        <mesh filename="package://assets/wheel.stl"/>
      </geometry>
    </collision>
  </link>
  <!-- Joint from body_right to wheel_3 -->
  <joint name="joint_3_RIGHT_F" type="continuous">
    <origin xyz="-2.08167e-17 0.0583795 -0.0510312" rpy="-1.5708 0.967866 -1.5708"/>
    <parent link="body_right_F"/>
    <child link="wheel_3_RIGHT_F"/>
    <axis xyz="0 0 1"/>
    <limit effort="10" velocity="10"/>
  </joint>
  <!-- Link wheel_4 -->
  <link name="wheel_4_RIGHT_F">
    <inertial>
      <origin xyz="1.92585e-20 1.51202e-17 -0.0225" rpy="0 0 0"/>
      <mass value="0.1"/>
      <inertia ixx="2.26562e-05" ixy="-1.25767e-21" ixz="0" iyy="2.26562e-05" iyz="0" izz="1.15625e-05"/>
    </inertial>
    <!-- Part wheel_4 -->
    <visual>
      <origin xyz="0 1.38778e-17 -0.045" rpy="-1.5708 -1.5708 0"/>
      <geometry>
        <mesh filename="package://assets/wheel.stl"/>
      </geometry>
      <material name="wheel_4_material">
        <color rgba="0.615686 0.811765 0.929412 1"/>
      </material>
    </visual>
    <collision>
      <origin xyz="0 1.38778e-17 -0.045" rpy="-1.5708 -1.5708 0"/>
      <geometry>
        <mesh filename="package://assets/wheel.stl"/>
      </geometry>
    </collision>
  </link>
  <!-- Joint from body_right to wheel_4 -->
  <joint name="joint_4_RIGHT_F" type="continuous">
    <origin xyz="-3.46945e-17 0.0417374 -0.0766777" rpy="-1.5708 0.992087 -1.5708"/>
    <parent link="body_right_F"/>
    <child link="wheel_4_RIGHT_F"/>
    <axis xyz="0 0 1"/>
    <limit effort="10" velocity="10"/>
  </joint>











  <!-- Joint to fix the leg to the base -->
  <joint name="RH_HAA" type="fixed">
    <parent link="base_link"/>
    <child link="RH_SHOULDER"/>
    <origin rpy="0 0 0" xyz="-0.045 -0.081 0"/>
  </joint>
  <!-- Shoulder link -->
  <link name="RH_SHOULDER">
    <visual>
      <material name="white"/>
      <origin rpy="0 0 0" xyz="0 0 0"/>
      <geometry>
        <mesh filename="package://assets/Module_right_hind.stl"/>
      </geometry>
    </visual>
    <collision>
      <origin rpy="0 0 0" xyz="-0.0945 0 0"/>
      <geometry>
        <!-- <mesh filename="${mulinex_module_right_hind}" /> -->
        <box size="0.269 0.057 0.060"/>
      </geometry>
    </collision>
    <inertial>
      <mass value="0.47669673"/>
      <origin rpy="0 0 0" xyz="-7.2487360e-02 -3.1582591e-02 -2.4812434e-03"/>
      <inertia ixx="2.1574269e-04" ixy="-3.3437484e-05" ixz="2.4284668e-06" iyy="3.0607390e-03" iyz="-2.0388977e-06" izz="3.0504273e-03"/>
    </inertial>
  </link>
  <gazebo reference="RH_SHOULDER">
    <material>Gazebo/White</material>
    <collision>
      <surface>
        <friction>
          <ode>
            <mu>1</mu>
            <mu2>1</mu2>
            <slip1>0</slip1>
            <slip2>0</slip2>
          </ode>
        </friction>
        <contact>
          <ode>
            <kp>1000000.0</kp>
            <kd>100.0</kd>
            <min_depth>0.001</min_depth>
          </ode>
        </contact>
      </surface>
    </collision>
  </gazebo>
  <!-- Hip joint -->
  <joint name="RH_HFE" type="revolute">
    <parent link="RH_SHOULDER"/>
    <child link="RH_UPPER_LEG"/>
    <origin rpy="0 0 0" xyz="-0.19 -0.044 0"/>
    <axis xyz="0 -1 0"/>
    <limit effort="2.7" lower="-3.141592" upper="3.141592" velocity="1000"/>
    <!-- <dynamics damping="0.7" friction="100.0" /> -->
  </joint>
  <!-- Upper leg link -->
  <link name="RH_UPPER_LEG">
    <visual>
      <material name="white"/>
      <origin rpy="0 0 0" xyz="0 0 0"/>
      <geometry>
        <mesh filename="package://assets/Module_right_hind.stl"/>
      </geometry>
    </visual>
    <collision>
      <origin rpy="0 0 0" xyz="-0.0945 -0.015 0"/>
      <geometry>
        <!-- <mesh filename="${mulinex_module_right_hind}" /> -->
        <box size="0.269 0.057 0.060"/>
      </geometry>
    </collision>
    <inertial>
      <mass value="0.47669673"/>
      <origin rpy="0 0 0" xyz="-7.2487360e-02 -3.1582591e-02 -2.4812434e-03"/>
      <inertia ixx="2.1574269e-04" ixy="-3.3437484e-05" ixz="2.4284668e-06" iyy="3.0607390e-03" iyz="-2.0388977e-06" izz="3.0504273e-03"/>
    </inertial>
  </link>
  <gazebo reference="RH_UPPER_LEG">
    <material>Gazebo/White</material>
    <collision>
      <surface>
        <friction>
          <ode>
            <mu>1</mu>
            <mu2>1</mu2>
            <slip1>0</slip1>
            <slip2>0</slip2>
          </ode>
        </friction>
        <contact>
          <ode>
            <kp>1000000.0</kp>
            <kd>100.0</kd>
            <min_depth>0.001</min_depth>
          </ode>
        </contact>
      </surface>
    </collision>
  </gazebo>
  <!-- Knee joint -->
  <!-- <joint name="RH_KFE" type="revolute">
    <parent link="RH_UPPER_LEG"/>
    <child link="RH_LOWER_LEG"/>
    <origin rpy="0 0 0" xyz="-0.19 -0.044 0"/>
    <axis xyz="0 -1 0"/>
    <limit effort="2.7" lower="-3.141592" upper="3.141592" velocity="1000"/>
  </joint> -->
  <!-- Lower leg link -->

  <joint name="RH_ANKLE" type="revolute">
    <origin rpy="0 0 1.5708" xyz="-0.19 -0.05 0"/>
    <parent link="RH_UPPER_LEG"/>
    <child link="body_right_H"/>
    <axis xyz="1 0 0"/>
    <limit effort="10" velocity="10" lower="-0.785398" upper="0.785398"/>
  </joint>
  <link name="body_right_H">
    <inertial>
      <origin xyz="-0.0238777 0.00412068 -0.00119624" rpy="0 0 0"/>
      <mass value="0.6"/>
      <inertia ixx="0.000408384" ixy="3.09979e-05" ixz="-6.93353e-06" iyy="0.000303698" iyz="2.90084e-05" izz="0.000335218"/>
    </inertial>
    <!-- Part body_right -->
    <visual>
      <origin xyz="1.06911e-50 -4.41854e-07 3.98827e-51" rpy="-1.5708 5.05322e-16 -3.14159"/>
      <geometry>
        <mesh filename="package://assets/body_right.stl"/>
      </geometry>
      <material name="body_right_material">
        <color rgba="0.647059 0.647059 0.647059 1"/>
      </material>
    </visual>
    <collision>
      <origin xyz="1.06911e-50 -4.41854e-07 3.98827e-51" rpy="-1.5708 5.05322e-16 -3.14159"/>
      <geometry>
        <mesh filename="package://assets/body_right.stl"/>
      </geometry>
    </collision>
  </link>
  <!-- Link wheel -->
  <link name="wheel_1_RIGHT_H">
    <inertial>
      <origin xyz="-1.38585e-17 -2.22698e-18 -0.0225" rpy="0 0 0"/>
      <mass value="0.1"/>
      <inertia ixx="2.26562e-05" ixy="1.25767e-21" ixz="-3.51752e-35" iyy="2.26562e-05" iyz="5.70075e-37" izz="1.15625e-05"/>
    </inertial>
    <!-- Part wheel -->
    <visual>
      <origin xyz="-1.38778e-17 -3.46945e-18 -0.045" rpy="-1.5708 -1.5708 0"/>
      <geometry>
        <mesh filename="package://assets/wheel.stl"/>
      </geometry>
      <material name="wheel_material">
        <color rgba="0.615686 0.811765 0.929412 1"/>
      </material>
    </visual>
    <collision>
      <origin xyz="-1.38778e-17 -3.46945e-18 -0.045" rpy="-1.5708 -1.5708 0"/>
      <geometry>
        <mesh filename="package://assets/wheel.stl"/>
      </geometry>
    </collision>
  </link>
  <!-- Joint from body_right to wheel -->
  <joint name="joint_1_RIGHT_H" type="continuous">
    <origin xyz="2.08167e-17 0.0583795 0.0484062" rpy="-1.5708 0.992087 -1.5708"/>
    <parent link="body_right_H"/>
    <child link="wheel_1_RIGHT_H"/>
    <axis xyz="0 0 1"/>
    <limit effort="10" velocity="10"/>
  </joint>
  <!-- Link wheel_2 -->
  <link name="wheel_2_RIGHT_H">
    <inertial>
      <origin xyz="1.92585e-20 1.24246e-18 -0.0225" rpy="0 0 0"/>
      <mass value="0.1"/>
      <inertia ixx="2.26562e-05" ixy="-1.25767e-21" ixz="-5.70075e-37" iyy="2.26562e-05" iyz="0" izz="1.15625e-05"/>
    </inertial>
    <!-- Part wheel_2 -->
    <visual>
      <origin xyz="0 0 -0.045" rpy="-1.5708 -1.5708 0"/>
      <geometry>
        <mesh filename="package://assets/wheel.stl"/>
      </geometry>
      <material name="wheel_2_material">
        <color rgba="0.615686 0.811765 0.929412 1"/>
      </material>
    </visual>
    <collision>
      <origin xyz="0 0 -0.045" rpy="-1.5708 -1.5708 0"/>
      <geometry>
        <mesh filename="package://assets/wheel.stl"/>
      </geometry>
    </collision>
  </link>
  <!-- Joint from body_right to wheel_2 -->
  <joint name="joint_2_RIGHT_H" type="continuous">
    <origin xyz="0 0.0583795 1.10544e-16" rpy="-1.5708 0.967866 -1.5708"/>
    <parent link="body_right_H"/>
    <child link="wheel_2_RIGHT_H"/>
    <axis xyz="0 0 1"/>
    <limit effort="10" velocity="10"/>
  </joint>
  <!-- Link wheel_3 -->
  <link name="wheel_3_RIGHT_H">
    <inertial>
      <origin xyz="1.75398e-18 1.24246e-18 -0.0225" rpy="0 0 0"/>
      <mass value="0.1"/>
      <inertia ixx="2.26562e-05" ixy="2.51535e-21" ixz="-1.61624e-35" iyy="2.26562e-05" iyz="9.50639e-36" izz="1.15625e-05"/>
    </inertial>
    <!-- Part wheel_3 -->
    <visual>
      <origin xyz="1.73472e-18 0 -0.045" rpy="-1.5708 -1.5708 0"/>
      <geometry>
        <mesh filename="package://assets/wheel.stl"/>
      </geometry>
      <material name="wheel_3_material">
        <color rgba="0.615686 0.811765 0.929412 1"/>
      </material>
    </visual>
    <collision>
      <origin xyz="1.73472e-18 0 -0.045" rpy="-1.5708 -1.5708 0"/>
      <geometry>
        <mesh filename="package://assets/wheel.stl"/>
      </geometry>
    </collision>
  </link>
  <!-- Joint from body_right to wheel_3 -->
  <joint name="joint_3_RIGHT_H" type="continuous">
    <origin xyz="-2.08167e-17 0.0583795 -0.0510312" rpy="-1.5708 0.967866 -1.5708"/>
    <parent link="body_right_H"/>
    <child link="wheel_3_RIGHT_H"/>
    <axis xyz="0 0 1"/>
    <limit effort="10" velocity="10"/>
  </joint>
  <!-- Link wheel_4 -->
  <link name="wheel_4_RIGHT_H">
    <inertial>
      <origin xyz="1.92585e-20 1.51202e-17 -0.0225" rpy="0 0 0"/>
      <mass value="0.1"/>
      <inertia ixx="2.26562e-05" ixy="-1.25767e-21" ixz="0" iyy="2.26562e-05" iyz="0" izz="1.15625e-05"/>
    </inertial>
    <!-- Part wheel_4 -->
    <visual>
      <origin xyz="0 1.38778e-17 -0.045" rpy="-1.5708 -1.5708 0"/>
      <geometry>
        <mesh filename="package://assets/wheel.stl"/>
      </geometry>
      <material name="wheel_4_material">
        <color rgba="0.615686 0.811765 0.929412 1"/>
      </material>
    </visual>
    <collision>
      <origin xyz="0 1.38778e-17 -0.045" rpy="-1.5708 -1.5708 0"/>
      <geometry>
        <mesh filename="package://assets/wheel.stl"/>
      </geometry>
    </collision>
  </link>
  <!-- Joint from body_right to wheel_4 -->
  <joint name="joint_4_RIGHT_H" type="continuous">
    <origin xyz="-3.46945e-17 0.0417374 -0.0766777" rpy="-1.5708 0.992087 -1.5708"/>
    <parent link="body_right_H"/>
    <child link="wheel_4_RIGHT_H"/>
    <axis xyz="0 0 1"/>
    <limit effort="10" velocity="10"/>
  </joint>
  







  <gazebo reference="base_link">
    <material>Gazebo/White</material>
  </gazebo>
  <!-- <gazebo>
            <plugin filename="libgazebo_ros2_control.so" name="gazebo_ros2_control">
                <parameters>$(find mulinex_gazebo)/config/mulinex_gazebo_sim_jnt_PD_IMU.yaml</parameters>
            </plugin>
        </gazebo> -->
  <ros2_control name="GazeboSystem" type="system">
    <hardware>
      <plugin>gazebo_ros2_control/GazeboSystem</plugin>
    </hardware>
    <joint name="LH_HAA">
      <command_interface name="effort"/>
      <state_interface name="position">
        <param name="initial_value">0.0</param>
      </state_interface>
      <state_interface name="velocity">
        <param name="initial_value">0.0</param>
      </state_interface>
      <state_interface name="effort"/>
    </joint>
    <joint name="LH_HFE">
      <command_interface name="effort"/>
      <state_interface name="position">
        <param name="initial_value">0.0</param>
      </state_interface>
      <state_interface name="velocity">
        <param name="initial_value">0.0</param>
      </state_interface>
      <state_interface name="effort"/>
    </joint>
    <joint name="LH_KFE">
      <command_interface name="effort"/>
      <state_interface name="position">
        <param name="initial_value">0.0</param>
      </state_interface>
      <state_interface name="velocity">
        <param name="initial_value">0.0</param>
      </state_interface>
      <state_interface name="effort"/>
    </joint>
    <joint name="LF_HAA">
      <command_interface name="effort"/>
      <state_interface name="position">
        <param name="initial_value">0.0</param>
      </state_interface>
      <state_interface name="velocity">
        <param name="initial_value">0.0</param>
      </state_interface>
      <state_interface name="effort"/>
    </joint>
    <joint name="LF_HFE">
      <command_interface name="effort"/>
      <state_interface name="position">
        <param name="initial_value">0.0</param>
      </state_interface>
      <state_interface name="velocity">
        <param name="initial_value">0.0</param>
      </state_interface>
      <state_interface name="effort"/>
    </joint>
    <joint name="LF_KFE">
      <command_interface name="effort"/>
      <state_interface name="position">
        <param name="initial_value">0.0</param>
      </state_interface>
      <state_interface name="velocity">
        <param name="initial_value">0.0</param>
      </state_interface>
      <state_interface name="effort"/>
    </joint>
    <joint name="RH_HAA">
      <command_interface name="effort"/>
      <state_interface name="position">
        <param name="initial_value">0.0</param>
      </state_interface>
      <state_interface name="velocity">
        <param name="initial_value">0.0</param>
      </state_interface>
      <state_interface name="effort"/>
    </joint>
    <joint name="RH_HFE">
      <command_interface name="effort"/>
      <state_interface name="position">
        <param name="initial_value">0.0</param>
      </state_interface>
      <state_interface name="velocity">
        <param name="initial_value">0.0</param>
      </state_interface>
      <state_interface name="effort"/>
    </joint>
    <joint name="RH_KFE">
      <command_interface name="effort"/>
      <state_interface name="position">
        <param name="initial_value">0.0</param>
      </state_interface>
      <state_interface name="velocity">
        <param name="initial_value">0.0</param>
      </state_interface>
      <state_interface name="effort"/>
    </joint>
    <joint name="RF_HAA">
      <command_interface name="effort"/>
      <state_interface name="position">
        <param name="initial_value">0.0</param>
      </state_interface>
      <state_interface name="velocity">
        <param name="initial_value">0.0</param>
      </state_interface>
      <state_interface name="effort"/>
    </joint>
    <joint name="RF_HFE">
      <command_interface name="effort"/>
      <state_interface name="position">
        <param name="initial_value">0.0</param>
      </state_interface>
      <state_interface name="velocity">
        <param name="initial_value">0.0</param>
      </state_interface>
      <state_interface name="effort"/>
    </joint>
    <joint name="RF_KFE">
      <command_interface name="effort"/>
      <state_interface name="position">
        <param name="initial_value">0.0</param>
      </state_interface>
      <state_interface name="velocity">
        <param name="initial_value">0.0</param>
      </state_interface>
      <state_interface name="effort"/>
    </joint>
  </ros2_control>
  <gazebo reference="base_link">
    <sensor name="br_imu" type="imu">
      <always_on>true</always_on>
      <update_rate>100</update_rate>
      <imu>
        <angular_velocity>
          <x>
            <noise type="gaussian">
              <mean>0.0</mean>
              <stddev>2e-4</stddev>
            </noise>
          </x>
          <y>
            <noise type="gaussian">
              <mean>0.0</mean>
              <stddev>2e-4</stddev>
            </noise>
          </y>
          <z>
            <noise type="gaussian">
              <mean>0.0</mean>
              <stddev>2e-4</stddev>
            </noise>
          </z>
        </angular_velocity>
        <linear_acceleration>
          <x>
            <noise type="gaussian">
              <mean>0.0</mean>
              <stddev>1.7e-2</stddev>
            </noise>
          </x>
          <y>
            <noise type="gaussian">
              <mean>0.0</mean>
              <stddev>1.7e-2</stddev>
            </noise>
          </y>
          <z>
            <noise type="gaussian">
              <mean>0.0</mean>
              <stddev>1.7e-2</stddev>
            </noise>
          </z>
        </linear_acceleration>
      </imu>
      <plugin filename="libgazebo_ros_imu_sensor.so" name="bytes_imu">
        <ros>
          <namespace>imu</namespace>
          <remapping>~/out:=data</remapping>
        </ros>
        <initial_orientation_as_reference>false</initial_orientation_as_reference>
      </plugin>
    </sensor>
  </gazebo>
</robot>
